Workbook

Sheet 1202
B1: ◈ KK저장소 복합단가 운영표 - 신도시저장소
B5: 이 월 재 고 | G5: [단위:리터/원]
B7: 유종 | D7: 탱크용량 | E7: 재고수량 | F7: 재고율 | G7: 단가
C8: G | D8: 0 | E8: 0 | F8: 0 | G8: 0
C9: K | D9: 200000 | E9: 27252 | F9: 0.13626 | G9: 1061.6455
C10: D | D10: 400000 | E10: 74710 | F10: 0.186775 | G10: 1506.3924
B13: 출고내역(K) | G13: [단위:리터/원] | J13: 출고내역(LD) | O13: [단위:리터/원]
B14: 유종 | C14: 일반매출(사내이관 포함) | J14: 유종 | K14: 일반매출(사내이관 포함)
C15: 거래처명 | D15: 수량 | E15: 출고단가 | F15: 재고단가 | G15: 단가차액 | H15: 이익 | K15: 거래처명 | L15: 수량 | M15: 출고단가 | N15: 재고단가 | O15: 단가차액 | P15: 이익
B16: 실내 등유 | D16: 1000 | F16: 1061.6455 | G16: -1061.6455 | H16: -1061645.5 | J16: 경유
B23: 소 계 | D23: 1000 | H23: -1061645.5 | J23: 소 계 | L23: 0 | P23: 0
B26: 마 감 재 고 | G26: [단위:리터/원] | J26: 입 고 내 역 | O26: [단위:리터/원]
B27: 유종 | C27: 수량 | E27: 단가 | G27: 환산금액 | J27: 유종 | K27: 수량 | M27: 사입단가 | O27: 환산금액
B28: G | C28: 0 | E28: 0 | G28: 0 | J28: G | K28: 0 | M28: 0 | O28: 0
B29: K | C29: 26252 | E29: 1061.6455 | G29: 27870317 | J29: K | O29: 0
B30: D | C30: 74710 | E30: 1506.3924 | G30: 1.1254257e+08 | J30: D | O30: 0
B33: 복 합 단 가
B34: 유종 | C34: 수량 | E34: 금액 | G34: 복 합 단 가
B35: G | C35: 0 | E35: 0 | G35: 0
B36: K | C36: 26252 | E36: 27870317 | G36: 1061.6455
B37: D | C37: 74710 | E37: 1.1254257e+08 | G37: 1506.3924
B39: 재 고 현 황 | O39: [단위:리터/원]
C40: 전일 | F40: 금일 | N40: 복합단가 | O40: 증감
C41: 재고 | F41: 입고 | H41: 출고 | K41: 마 감 재 고 | M41: 재고율
B42: 휘발유
B43: 등 유 | C43: 27252 | F43: 0 | H43: 1000 | K43: 26252 | M43: 0.13126 | N43: 1061.6455
B44: 경 유 | C44: 74710 | F44: 0 | H44: 0 | K44: 74710 | M44: 0.186775 | N44: 1506.3924
G45: 복합단가의 재고수량과 단가는 보관물량 제외니 참고해주세요!

Sheet 1204
B1: ◈ KK저장소 복합단가 운영표 - 신도시저장소
B5: 이 월 재 고 | G5: [단위:리터/원]
B7: 유종 | D7: 탱크용량 | E7: 재고수량 | F7: 재고율 | G7: 단가
C8: G | D8: 0 | E8: 0 | F8: 0 | G8: 0
C9: K | D9: 200000 | E9: =SUM('1202'!$K$43:$L$43) -> 26252 | F9: =SUM(E9)/D9 -> 0.13126 | G9: =SUM('1202'!$N$43) -> 1061.6455
C10: D | D10: 400000 | E10: =SUM('1202'!$K$44:$L$44) -> 74710 | F10: =SUM(E10)/D10 -> 0.186775 | G10: =SUM('1202'!$N$44) -> 1506.3924
B13: 출고내역(K) | G13: [단위:리터/원] | J13: 출고내역(LD) | O13: [단위:리터/원]
B14: 유종 | C14: 일반매출(사내이관 포함) | J14: 유종 | K14: 일반매출(사내이관 포함)
C15: 거래처명 | D15: 수량 | E15: 출고단가 | F15: 재고단가 | G15: 단가차액 | H15: 이익 | K15: 거래처명 | L15: 수량 | M15: 출고단가 | N15: 재고단가 | O15: 단가차액 | P15: 이익
B16: 실내 등유 | D16: 1000 | F16: =IF(D16="","",(SUM($G$9))) -> 1061.6455 | G16: =IF(D16="","",(SUM(E16)-F16)) -> -1061.6455 | H16: =IF(D16="","",(D16*G16)) -> -1061645.5 | J16: 경유 | N16: =IF(L16="","",($G$10)) | O16: =IF(L16="","",(SUM(M16)-N16)) | P16: =IF(L16="","",(L16*O16))
F17: =IF(D17="","",(SUM($G$9))) | G17: =IF(D17="","",(SUM(E17)-F17)) | H17: =IF(D17="","",(D17*G17)) | N17: =IF(L17="","",($G$10)) | O17: =IF(L17="","",(SUM(M17)-N17)) | P17: =IF(L17="","",(L17*O17))
F18: =IF(D18="","",(SUM($G$9))) | G18: =IF(D18="","",(SUM(E18)-F18)) | H18: =IF(D18="","",(D18*G18)) | N18: =IF(L18="","",($G$10)) | O18: =IF(L18="","",(SUM(M18)-N18)) | P18: =IF(L18="","",(L18*O18))
F19: =IF(D19="","",(SUM($G$9))) | G19: =IF(D19="","",(SUM(E19)-F19)) | H19: =IF(D19="","",(D19*G19)) | N19: =IF(L19="","",($G$10)) | O19: =IF(L19="","",(SUM(M19)-N19)) | P19: =IF(L19="","",(L19*O19))
F20: =IF(D20="","",(SUM($G$9))) | G20: =IF(D20="","",(SUM(E20)-F20)) | H20: =IF(D20="","",(D20*G20)) | N20: =IF(L20="","",($G$10)) | O20: =IF(L20="","",(SUM(M20)-N20)) | P20: =IF(L20="","",(L20*O20))
F21: =IF(D21="","",(SUM($G$9))) | G21: =IF(D21="","",(SUM(E21)-F21)) | H21: =IF(D21="","",(D21*G21)) | N21: =IF(L21="","",($G$10)) | O21: =IF(L21="","",(SUM(M21)-N21)) | P21: =IF(L21="","",(L21*O21))
F22: =IF(D22="","",(SUM($G$9))) | G22: =IF(D22="","",(SUM(E22)-F22)) | H22: =IF(D22="","",(D22*G22)) | N22: =IF(L22="","",($G$10)) | O22: =IF(L22="","",(SUM(M22)-N22)) | P22: =IF(L22="","",(L22*O22))
B23: 소 계 | D23: =SUM(D16:D22) -> 1000 | H23: =SUM(H16:H22) -> -1061645.5 | J23: 소 계 | L23: =SUM(L16:L22) -> 0 | P23: =SUM(P16:P22) -> 0
B26: 마 감 재 고 | G26: [단위:리터/원] | J26: 입 고 내 역 | O26: [단위:리터/원]
B27: 유종 | C27: 수량 | E27: 단가 | G27: 환산금액 | J27: 유종 | K27: 수량 | M27: 사입단가 | O27: 환산금액
B28: G | C28: 0 | E28: 0 | G28: 0 | J28: G | K28: 0 | M28: 0 | O28: 0
B29: K | C29: =$E$9-$D$23 -> 25252 | E29: =$G$9 -> 1061.6455 | G29: =C29*E29 -> 26808671 | J29: K | O29: =K29*M29 -> 0
B30: D | C30: =$E$10-$L$23 -> 74710 | E30: =$G$10 -> 1506.3924 | G30: =C30*E30 -> 1.1254257e+08 | J30: D | O30: =K30*M30 -> 0
B33: 복 합 단 가
B34: 유종 | C34: 수량 | E34: 금액 | G34: 복 합 단 가
B35: G | C35: 0 | E35: 0 | G35: 0
B36: K | C36: =$C$29+$K$29 -> 25252 | E36: =$G$29+$O$29 -> 26808671 | G36: =E36/C36 -> 1061.6455
B37: D | C37: =$C$30+$K$30 -> 74710 | E37: =$G$30+$O$30 -> 1.1254257e+08 | G37: =E37/C37 -> 1506.3924
B39: 재 고 현 황 | O39: [단위:리터/원]
C40: 전일 | F40: 금일 | N40: 복합단가 | O40: 증감
C41: 재고 | F41: 입고 | H41: 출고 | K41: 마 감 재 고 | M41: 재고율
B42: 휘발유
B43: 등 유 | C43: =SUM($E$9) -> 26252 | F43: =$K$29 -> 0 | H43: =$D$23 -> 1000 | K43: =$C$43-$H$43+$F$43+$O$43 -> 25252 | M43: =SUM($K$43)/$D$9 -> 0.12626 | N43: =$G$36 -> 1061.6455
B44: 경 유 | C44: =SUM($E$10) -> 74710 | F44: =$K$30 -> 0 | H44: =$L$23 -> 0 | K44: =$C$44-$H$44+$F$44+$O$44 -> 74710 | M44: =SUM($K$44)/D10 -> 0.186775 | N44: =$G$37 -> 1506.3924
G45: 복합단가의 재고수량과 단가는 보관물량 제외니 참고해주세요!

Sheet 1205
B1: ◈ KK저장소 복합단가 운영표 - 신도시저장소
B5: 이 월 재 고 | G5: [단위:리터/원]
B7: 유종 | D7: 탱크용량 | E7: 재고수량 | F7: 재고율 | G7: 단가
C8: G | D8: 0 | E8: 0 | F8: 0 | G8: 0
C9: K | D9: 200000 | E9: =SUM('1204'!$K$43:$L$43) -> 25252 | F9: =SUM(E9)/D9 -> 0.12626 | G9: =SUM('1204'!$N$43) -> 1061.6455
C10: D | D10: 400000 | E10: =SUM('1204'!$K$44:$L$44) -> 74710 | F10: =SUM(E10)/D10 -> 0.186775 | G10: =SUM('1204'!$N$44) -> 1506.3924
B13: 출고내역(K) | G13: [단위:리터/원] | J13: 출고내역(LD) | O13: [단위:리터/원]
B14: 유종 | C14: 일반매출(사내이관 포함) | J14: 유종 | K14: 일반매출(사내이관 포함)
C15: 거래처명 | D15: 수량 | E15: 출고단가 | F15: 재고단가 | G15: 단가차액 | H15: 이익 | K15: 거래처명 | L15: 수량 | M15: 출고단가 | N15: 재고단가 | O15: 단가차액 | P15: 이익
B16: 실내 등유 | F16: =IF(D16="","",(SUM($G$9))) | G16: =IF(D16="","",(SUM(E16)-F16)) | H16: =IF(D16="","",(D16*G16)) | J16: 경유 | L16: 15000 | N16: =IF(L16="","",($G$10)) -> 1506.3924 | O16: =IF(L16="","",(SUM(M16)-N16)) -> -1506.3924 | P16: =IF(L16="","",(L16*O16)) -> -22595886
F17: =IF(D17="","",(SUM($G$9))) | G17: =IF(D17="","",(SUM(E17)-F17)) | H17: =IF(D17="","",(D17*G17)) | L17: 2930 | N17: =IF(L17="","",($G$10)) -> 1506.3924 | O17: =IF(L17="","",(SUM(M17)-N17)) -> -1506.3924 | P17: =IF(L17="","",(L17*O17)) -> -4413729.7
F18: =IF(D18="","",(SUM($G$9))) | G18: =IF(D18="","",(SUM(E18)-F18)) | H18: =IF(D18="","",(D18*G18)) | N18: =IF(L18="","",($G$10)) | O18: =IF(L18="","",(SUM(M18)-N18)) | P18: =IF(L18="","",(L18*O18))
F19: =IF(D19="","",(SUM($G$9))) | G19: =IF(D19="","",(SUM(E19)-F19)) | H19: =IF(D19="","",(D19*G19)) | N19: =IF(L19="","",($G$10)) | O19: =IF(L19="","",(SUM(M19)-N19)) | P19: =IF(L19="","",(L19*O19))
F20: =IF(D20="","",(SUM($G$9))) | G20: =IF(D20="","",(SUM(E20)-F20)) | H20: =IF(D20="","",(D20*G20)) | N20: =IF(L20="","",($G$10)) | O20: =IF(L20="","",(SUM(M20)-N20)) | P20: =IF(L20="","",(L20*O20))
F21: =IF(D21="","",(SUM($G$9))) | G21: =IF(D21="","",(SUM(E21)-F21)) | H21: =IF(D21="","",(D21*G21)) | N21: =IF(L21="","",($G$10)) | O21: =IF(L21="","",(SUM(M21)-N21)) | P21: =IF(L21="","",(L21*O21))
F22: =IF(D22="","",(SUM($G$9))) | G22: =IF(D22="","",(SUM(E22)-F22)) | H22: =IF(D22="","",(D22*G22)) | N22: =IF(L22="","",($G$10)) | O22: =IF(L22="","",(SUM(M22)-N22)) | P22: =IF(L22="","",(L22*O22))
B23: 소 계 | D23: =SUM(D16:D22) -> 0 | H23: =SUM(H16:H22) -> 0 | J23: 소 계 | L23: =SUM(L16:L22) -> 17930 | P23: =SUM(P16:P22) -> -27009615
B26: 마 감 재 고 | G26: [단위:리터/원] | J26: 입 고 내 역 | O26: [단위:리터/원]
B27: 유종 | C27: 수량 | E27: 단가 | G27: 환산금액 | J27: 유종 | K27: 수량 | M27: 사입단가 | O27: 환산금액
B28: G | C28: 0 | E28: 0 | G28: 0 | J28: G | K28: 0 | M28: 0 | O28: 0
B29: K | C29: =$E$9-$D$23 -> 25252 | E29: =$G$9 -> 1061.6455 | G29: =C29*E29 -> 26808671 | J29: K | O29: =K29*M29 -> 0
B30: D | C30: =$E$10-$L$23 -> 56780 | E30: =$G$10 -> 1506.3924 | G30: =C30*E30 -> 85532959 | J30: D | O30: =K30*M30 -> 0
B33: 복 합 단 가
B34: 유종 | C34: 수량 | E34: 금액 | G34: 복 합 단 가
B35: G | C35: 0 | E35: 0 | G35: 0
B36: K | C36: =$C$29+$K$29 -> 25252 | E36: =$G$29+$O$29 -> 26808671 | G36: =E36/C36 -> 1061.6455
B37: D | C37: =$C$30+$K$30 -> 56780 | E37: =$G$30+$O$30 -> 85532959 | G37: =E37/C37 -> 1506.3924
B39: 재 고 현 황 | O39: [단위:리터/원]
C40: 전일 | F40: 금일 | N40: 복합단가 | O40: 증감
C41: 재고 | F41: 입고 | H41: 출고 | K41: 마 감 재 고 | M41: 재고율
B42: 휘발유
B43: 등 유 | C43: =SUM($E$9) -> 25252 | F43: =$K$29 -> 0 | H43: =$D$23 -> 0 | K43: =$C$43-$H$43+$F$43+$O$43 -> 25252 | M43: =SUM($K$43)/$D$9 -> 0.12626 | N43: =$G$36 -> 1061.6455
B44: 경 유 | C44: =SUM($E$10) -> 74710 | F44: =$K$30 -> 0 | H44: =$L$23 -> 17930 | K44: =$C$44-$H$44+$F$44+$O$44 -> 56780 | M44: =SUM($K$44)/D10 -> 0.14195 | N44: =$G$37 -> 1506.3924
G45: 복합단가의 재고수량과 단가는 보관물량 제외니 참고해주세요!

Sheet 1208
B1: ◈ KK저장소 복합단가 운영표 - 신도시저장소
B5: 이 월 재 고 | G5: [단위:리터/원]
B7: 유종 | D7: 탱크용량 | E7: 재고수량 | F7: 재고율 | G7: 단가
C8: G | D8: 0 | E8: 0 | F8: 0 | G8: 0
C9: K | D9: 200000 | E9: =SUM('1205'!$K$43:$L$43) -> 25252 | F9: =SUM(E9)/D9 -> 0.12626 | G9: =SUM('1205'!$N$43) -> 1061.6455
C10: D | D10: 400000 | E10: =SUM('1205'!$K$44:$L$44) -> 56780 | F10: =SUM(E10)/D10 -> 0.14195 | G10: =SUM('1205'!$N$44) -> 1506.3924
B13: 출고내역(K) | G13: [단위:리터/원] | J13: 출고내역(LD) | O13: [단위:리터/원]
B14: 유종 | C14: 일반매출(사내이관 포함) | J14: 유종 | K14: 일반매출(사내이관 포함)
C15: 거래처명 | D15: 수량 | E15: 출고단가 | F15: 재고단가 | G15: 단가차액 | H15: 이익 | K15: 거래처명 | L15: 수량 | M15: 출고단가 | N15: 재고단가 | O15: 단가차액 | P15: 이익
B16: 실내 등유 | F16: =IF(D16="","",(SUM($G$9))) | G16: =IF(D16="","",(SUM(E16)-F16)) | H16: =IF(D16="","",(D16*G16)) | J16: 경유 | L16: 2840 | N16: =IF(L16="","",($G$10)) -> 1506.3924 | O16: =IF(L16="","",(SUM(M16)-N16)) -> -1506.3924 | P16: =IF(L16="","",(L16*O16)) -> -4278154.4
F17: =IF(D17="","",(SUM($G$9))) | G17: =IF(D17="","",(SUM(E17)-F17)) | H17: =IF(D17="","",(D17*G17)) | N17: =IF(L17="","",($G$10)) | O17: =IF(L17="","",(SUM(M17)-N17)) | P17: =IF(L17="","",(L17*O17))
F18: =IF(D18="","",(SUM($G$9))) | G18: =IF(D18="","",(SUM(E18)-F18)) | H18: =IF(D18="","",(D18*G18)) | N18: =IF(L18="","",($G$10)) | O18: =IF(L18="","",(SUM(M18)-N18)) | P18: =IF(L18="","",(L18*O18))
F19: =IF(D19="","",(SUM($G$9))) | G19: =IF(D19="","",(SUM(E19)-F19)) | H19: =IF(D19="","",(D19*G19)) | N19: =IF(L19="","",($G$10)) | O19: =IF(L19="","",(SUM(M19)-N19)) | P19: =IF(L19="","",(L19*O19))
F20: =IF(D20="","",(SUM($G$9))) | G20: =IF(D20="","",(SUM(E20)-F20)) | H20: =IF(D20="","",(D20*G20)) | N20: =IF(L20="","",($G$10)) | O20: =IF(L20="","",(SUM(M20)-N20)) | P20: =IF(L20="","",(L20*O20))
F21: =IF(D21="","",(SUM($G$9))) | G21: =IF(D21="","",(SUM(E21)-F21)) | H21: =IF(D21="","",(D21*G21)) | N21: =IF(L21="","",($G$10)) | O21: =IF(L21="","",(SUM(M21)-N21)) | P21: =IF(L21="","",(L21*O21))
F22: =IF(D22="","",(SUM($G$9))) | G22: =IF(D22="","",(SUM(E22)-F22)) | H22: =IF(D22="","",(D22*G22)) | N22: =IF(L22="","",($G$10)) | O22: =IF(L22="","",(SUM(M22)-N22)) | P22: =IF(L22="","",(L22*O22))
B23: 소 계 | D23: =SUM(D16:D22) -> 0 | H23: =SUM(H16:H22) -> 0 | J23: 소 계 | L23: =SUM(L16:L22) -> 2840 | P23: =SUM(P16:P22) -> -4278154.4
B26: 마 감 재 고 | G26: [단위:리터/원] | J26: 입 고 내 역 | O26: [단위:리터/원]
B27: 유종 | C27: 수량 | E27: 단가 | G27: 환산금액 | J27: 유종 | K27: 수량 | M27: 사입단가 | O27: 환산금액
B28: G | C28: 0 | E28: 0 | G28: 0 | J28: G | K28: 0 | M28: 0 | O28: 0
B29: K | C29: =$E$9-$D$23 -> 25252 | E29: =$G$9 -> 1061.6455 | G29: =C29*E29 -> 26808671 | J29: K | O29: =K29*M29 -> 0
B30: D | C30: =$E$10-$L$23 -> 53940 | E30: =$G$10 -> 1506.3924 | G30: =C30*E30 -> 81254805 | J30: D | O30: =K30*M30 -> 0
B33: 복 합 단 가
B34: 유종 | C34: 수량 | E34: 금액 | G34: 복 합 단 가
B35: G | C35: 0 | E35: 0 | G35: 0
B36: K | C36: =$C$29+$K$29 -> 25252 | E36: =$G$29+$O$29 -> 26808671 | G36: =E36/C36 -> 1061.6455
B37: D | C37: =$C$30+$K$30 -> 53940 | E37: =$G$30+$O$30 -> 81254805 | G37: =E37/C37 -> 1506.3924
B39: 재 고 현 황 | O39: [단위:리터/원]
C40: 전일 | F40: 금일 | N40: 복합단가 | O40: 증감
C41: 재고 | F41: 입고 | H41: 출고 | K41: 마 감 재 고 | M41: 재고율
B42: 휘발유
B43: 등 유 | C43: =SUM($E$9) -> 25252 | F43: =$K$29 -> 0 | H43: =$D$23 -> 0 | K43: =$C$43-$H$43+$F$43+$O$43 -> 25252 | M43: =SUM($K$43)/$D$9 -> 0.12626 | N43: =$G$36 -> 1061.6455
B44: 경 유 | C44: =SUM($E$10) -> 56780 | F44: =$K$30 -> 0 | H44: =$L$23 -> 2840 | K44: =$C$44-$H$44+$F$44+$O$44 -> 53940 | M44: =SUM($K$44)/D10 -> 0.13485 | N44: =$G$37 -> 1506.3924
G45: 복합단가의 재고수량과 단가는 보관물량 제외니 참고해주세요!

Sheet 1209
B1: ◈ KK저장소 복합단가 운영표 - 신도시저장소
B5: 이 월 재 고 | G5: [단위:리터/원]
B7: 유종 | D7: 탱크용량 | E7: 재고수량 | F7: 재고율 | G7: 단가
C8: G | D8: 0 | E8: 0 | F8: 0 | G8: 0
C9: K | D9: 200000 | E9: =SUM('1208'!$K$43:$L$43) -> 25252 | F9: =SUM(E9)/D9 -> 0.12626 | G9: =SUM('1208'!$N$43) -> 1061.6455
C10: D | D10: 400000 | E10: =SUM('1208'!$K$44:$L$44) -> 53940 | F10: =SUM(E10)/D10 -> 0.13485 | G10: =SUM('1208'!$N$44) -> 1506.3924
B13: 출고내역(K) | G13: [단위:리터/원] | J13: 출고내역(LD) | O13: [단위:리터/원]
B14: 유종 | C14: 일반매출(사내이관 포함) | J14: 유종 | K14: 일반매출(사내이관 포함)
C15: 거래처명 | D15: 수량 | E15: 출고단가 | F15: 재고단가 | G15: 단가차액 | H15: 이익 | K15: 거래처명 | L15: 수량 | M15: 출고단가 | N15: 재고단가 | O15: 단가차액 | P15: 이익
B16: 실내 등유 | F16: =IF(D16="","",(SUM($G$9))) | G16: =IF(D16="","",(SUM(E16)-F16)) | H16: =IF(D16="","",(D16*G16)) | J16: 경유 | L16: 8000 | N16: =IF(L16="","",($G$10)) -> 1506.3924 | O16: =IF(L16="","",(SUM(M16)-N16)) -> -1506.3924 | P16: =IF(L16="","",(L16*O16)) -> -12051139
F17: =IF(D17="","",(SUM($G$9))) | G17: =IF(D17="","",(SUM(E17)-F17)) | H17: =IF(D17="","",(D17*G17)) | N17: =IF(L17="","",($G$10)) | O17: =IF(L17="","",(SUM(M17)-N17)) | P17: =IF(L17="","",(L17*O17))
F18: =IF(D18="","",(SUM($G$9))) | G18: =IF(D18="","",(SUM(E18)-F18)) | H18: =IF(D18="","",(D18*G18)) | N18: =IF(L18="","",($G$10)) | O18: =IF(L18="","",(SUM(M18)-N18)) | P18: =IF(L18="","",(L18*O18))
F19: =IF(D19="","",(SUM($G$9))) | G19: =IF(D19="","",(SUM(E19)-F19)) | H19: =IF(D19="","",(D19*G19)) | N19: =IF(L19="","",($G$10)) | O19: =IF(L19="","",(SUM(M19)-N19)) | P19: =IF(L19="","",(L19*O19))
F20: =IF(D20="","",(SUM($G$9))) | G20: =IF(D20="","",(SUM(E20)-F20)) | H20: =IF(D20="","",(D20*G20)) | N20: =IF(L20="","",($G$10)) | O20: =IF(L20="","",(SUM(M20)-N20)) | P20: =IF(L20="","",(L20*O20))
F21: =IF(D21="","",(SUM($G$9))) | G21: =IF(D21="","",(SUM(E21)-F21)) | H21: =IF(D21="","",(D21*G21)) | N21: =IF(L21="","",($G$10)) | O21: =IF(L21="","",(SUM(M21)-N21)) | P21: =IF(L21="","",(L21*O21))
F22: =IF(D22="","",(SUM($G$9))) | G22: =IF(D22="","",(SUM(E22)-F22)) | H22: =IF(D22="","",(D22*G22)) | N22: =IF(L22="","",($G$10)) | O22: =IF(L22="","",(SUM(M22)-N22)) | P22: =IF(L22="","",(L22*O22))
B23: 소 계 | D23: =SUM(D16:D22) -> 0 | H23: =SUM(H16:H22) -> 0 | J23: 소 계 | L23: =SUM(L16:L22) -> 8000 | P23: =SUM(P16:P22) -> -12051139
B26: 마 감 재 고 | G26: [단위:리터/원] | J26: 입 고 내 역 | O26: [단위:리터/원]
B27: 유종 | C27: 수량 | E27: 단가 | G27: 환산금액 | J27: 유종 | K27: 수량 | M27: 사입단가 | O27: 환산금액
B28: G | C28: 0 | E28: 0 | G28: 0 | J28: G | K28: 0 | M28: 0 | O28: 0
B29: K | C29: =$E$9-$D$23 -> 25252 | E29: =$G$9 -> 1061.6455 | G29: =C29*E29 -> 26808671 | J29: K | O29: =K29*M29 -> 0
B30: D | C30: =$E$10-$L$23 -> 45940 | E30: =$G$10 -> 1506.3924 | G30: =C30*E30 -> 69203666 | J30: D | O30: =K30*M30 -> 0
B33: 복 합 단 가
B34: 유종 | C34: 수량 | E34: 금액 | G34: 복 합 단 가
B35: G | C35: 0 | E35: 0 | G35: 0
B36: K | C36: =$C$29+$K$29 -> 25252 | E36: =$G$29+$O$29 -> 26808671 | G36: =E36/C36 -> 1061.6455
B37: D | C37: =$C$30+$K$30 -> 45940 | E37: =$G$30+$O$30 -> 69203666 | G37: =E37/C37 -> 1506.3924
B39: 재 고 현 황 | O39: [단위:리터/원]
C40: 전일 | F40: 금일 | N40: 복합단가 | O40: 증감
C41: 재고 | F41: 입고 | H41: 출고 | K41: 마 감 재 고 | M41: 재고율
B42: 휘발유
B43: 등 유 | C43: =SUM($E$9) -> 25252 | F43: =$K$29 -> 0 | H43: =$D$23 -> 0 | K43: =$C$43-$H$43+$F$43+$O$43 -> 25252 | M43: =SUM($K$43)/$D$9 -> 0.12626 | N43: =$G$36 -> 1061.6455
B44: 경 유 | C44: =SUM($E$10) -> 53940 | F44: =$K$30 -> 0 | H44: =$L$23 -> 8000 | K44: =$C$44-$H$44+$F$44+$O$44 -> 45940 | M44: =SUM($K$44)/D10 -> 0.11485 | N44: =$G$37 -> 1506.3924
G45: 복합단가의 재고수량과 단가는 보관물량 제외니 참고해주세요!

Sheet 1210
B1: ◈ KK저장소 복합단가 운영표 - 신도시저장소
B5: 이 월 재 고 | G5: [단위:리터/원]
B7: 유종 | D7: 탱크용량 | E7: 재고수량 | F7: 재고율 | G7: 단가
C8: G | D8: 0 | E8: 0 | F8: 0 | G8: 0
C9: K | D9: 200000 | E9: =SUM('1209'!$K$43:$L$43) -> 25252 | F9: =SUM(E9)/D9 -> 0.12626 | G9: =SUM('1209'!$N$43) -> 1061.6455
C10: D | D10: 400000 | E10: =SUM('1209'!$K$44:$L$44) -> 45940 | F10: =SUM(E10)/D10 -> 0.11485 | G10: =SUM('1209'!$N$44) -> 1506.3924
B13: 출고내역(K) | G13: [단위:리터/원] | J13: 출고내역(LD) | O13: [단위:리터/원]
B14: 유종 | C14: 일반매출(사내이관 포함) | J14: 유종 | K14: 일반매출(사내이관 포함)
C15: 거래처명 | D15: 수량 | E15: 출고단가 | F15: 재고단가 | G15: 단가차액 | H15: 이익 | K15: 거래처명 | L15: 수량 | M15: 출고단가 | N15: 재고단가 | O15: 단가차액 | P15: 이익
B16: 실내 등유 | F16: =IF(D16="","",(SUM($G$9))) | G16: =IF(D16="","",(SUM(E16)-F16)) | H16: =IF(D16="","",(D16*G16)) | J16: 경유 | N16: =IF(L16="","",($G$10)) | O16: =IF(L16="","",(SUM(M16)-N16)) | P16: =IF(L16="","",(L16*O16))
F17: =IF(D17="","",(SUM($G$9))) | G17: =IF(D17="","",(SUM(E17)-F17)) | H17: =IF(D17="","",(D17*G17)) | N17: =IF(L17="","",($G$10)) | O17: =IF(L17="","",(SUM(M17)-N17)) | P17: =IF(L17="","",(L17*O17))
F18: =IF(D18="","",(SUM($G$9))) | G18: =IF(D18="","",(SUM(E18)-F18)) | H18: =IF(D18="","",(D18*G18)) | N18: =IF(L18="","",($G$10)) | O18: =IF(L18="","",(SUM(M18)-N18)) | P18: =IF(L18="","",(L18*O18))
F19: =IF(D19="","",(SUM($G$9))) | G19: =IF(D19="","",(SUM(E19)-F19)) | H19: =IF(D19="","",(D19*G19)) | N19: =IF(L19="","",($G$10)) | O19: =IF(L19="","",(SUM(M19)-N19)) | P19: =IF(L19="","",(L19*O19))
F20: =IF(D20="","",(SUM($G$9))) | G20: =IF(D20="","",(SUM(E20)-F20)) | H20: =IF(D20="","",(D20*G20)) | N20: =IF(L20="","",($G$10)) | O20: =IF(L20="","",(SUM(M20)-N20)) | P20: =IF(L20="","",(L20*O20))
F21: =IF(D21="","",(SUM($G$9))) | G21: =IF(D21="","",(SUM(E21)-F21)) | H21: =IF(D21="","",(D21*G21)) | N21: =IF(L21="","",($G$10)) | O21: =IF(L21="","",(SUM(M21)-N21)) | P21: =IF(L21="","",(L21*O21))
F22: =IF(D22="","",(SUM($G$9))) | G22: =IF(D22="","",(SUM(E22)-F22)) | H22: =IF(D22="","",(D22*G22)) | N22: =IF(L22="","",($G$10)) | O22: =IF(L22="","",(SUM(M22)-N22)) | P22: =IF(L22="","",(L22*O22))
B23: 소 계 | D23: =SUM(D16:D22) -> 0 | H23: =SUM(H16:H22) -> 0 | J23: 소 계 | L23: =SUM(L16:L22) -> 0 | P23: =SUM(P16:P22) -> 0
B26: 마 감 재 고 | G26: [단위:리터/원] | J26: 입 고 내 역 | O26: [단위:리터/원]
B27: 유종 | C27: 수량 | E27: 단가 | G27: 환산금액 | J27: 유종 | K27: 수량 | M27: 사입단가 | O27: 환산금액
B28: G | C28: 0 | E28: 0 | G28: 0 | J28: G | K28: 0 | M28: 0 | O28: 0
B29: K | C29: =$E$9-$D$23 -> 25252 | E29: =$G$9 -> 1061.6455 | G29: =C29*E29 -> 26808671 | J29: K | O29: =K29*M29 -> 0
B30: D | C30: =$E$10-$L$23 -> 45940 | E30: =$G$10 -> 1506.3924 | G30: =C30*E30 -> 69203666 | J30: D | K30: 64000 | M30: 1468.1 | O30: =K30*M30 -> 93958400
B33: 복 합 단 가
B34: 유종 | C34: 수량 | E34: 금액 | G34: 복 합 단 가
B35: G | C35: 0 | E35: 0 | G35: 0
B36: K | C36: =$C$29+$K$29 -> 25252 | E36: =$G$29+$O$29 -> 26808671 | G36: =E36/C36 -> 1061.6455
B37: D | C37: =$C$30+$K$30 -> 109940 | E37: =$G$30+$O$30 -> 1.6316207e+08 | G37: =E37/C37 -> 1484.101
B39: 재 고 현 황 | O39: [단위:리터/원]
C40: 전일 | F40: 금일 | N40: 복합단가 | O40: 증감
C41: 재고 | F41: 입고 | H41: 출고 | K41: 마 감 재 고 | M41: 재고율
B42: 휘발유
B43: 등 유 | C43: =SUM($E$9) -> 25252 | F43: =$K$29 -> 0 | H43: =$D$23 -> 0 | K43: =$C$43-$H$43+$F$43+$O$43 -> 25252 | M43: =SUM($K$43)/$D$9 -> 0.12626 | N43: =$G$36 -> 1061.6455
B44: 경 유 | C44: =SUM($E$10) -> 45940 | F44: =$K$30 -> 64000 | H44: =$L$23 -> 0 | K44: =$C$44-$H$44+$F$44+$O$44 -> 109940 | M44: =SUM($K$44)/D10 -> 0.27485 | N44: =$G$37 -> 1484.101
G45: 복합단가의 재고수량과 단가는 보관물량 제외니 참고해주세요!

Sheet 1211
B1: ◈ KK저장소 복합단가 운영표 - 신도시저장소
B5: 이 월 재 고 | G5: [단위:리터/원]
B7: 유종 | D7: 탱크용량 | E7: 재고수량 | F7: 재고율 | G7: 단가
C8: G | D8: 0 | E8: 0 | F8: 0 | G8: 0
C9: K | D9: 200000 | E9: =SUM('1210'!$K$43:$L$43) -> 25252 | F9: =SUM(E9)/D9 -> 0.12626 | G9: =SUM('1210'!$N$43) -> 1061.6455
C10: D | D10: 400000 | E10: =SUM('1210'!$K$44:$L$44) -> 109940 | F10: =SUM(E10)/D10 -> 0.27485 | G10: =SUM('1210'!$N$44) -> 1484.101
B13: 출고내역(K) | G13: [단위:리터/원] | J13: 출고내역(LD) | O13: [단위:리터/원]
B14: 유종 | C14: 일반매출(사내이관 포함) | J14: 유종 | K14: 일반매출(사내이관 포함)
C15: 거래처명 | D15: 수량 | E15: 출고단가 | F15: 재고단가 | G15: 단가차액 | H15: 이익 | K15: 거래처명 | L15: 수량 | M15: 출고단가 | N15: 재고단가 | O15: 단가차액 | P15: 이익
B16: 실내 등유 | F16: =IF(D16="","",(SUM($G$9))) | G16: =IF(D16="","",(SUM(E16)-F16)) | H16: =IF(D16="","",(D16*G16)) | J16: 경유 | N16: =IF(L16="","",($G$10)) | O16: =IF(L16="","",(SUM(M16)-N16)) | P16: =IF(L16="","",(L16*O16))
F17: =IF(D17="","",(SUM($G$9))) | G17: =IF(D17="","",(SUM(E17)-F17)) | H17: =IF(D17="","",(D17*G17)) | N17: =IF(L17="","",($G$10)) | O17: =IF(L17="","",(SUM(M17)-N17)) | P17: =IF(L17="","",(L17*O17))
F18: =IF(D18="","",(SUM($G$9))) | G18: =IF(D18="","",(SUM(E18)-F18)) | H18: =IF(D18="","",(D18*G18)) | N18: =IF(L18="","",($G$10)) | O18: =IF(L18="","",(SUM(M18)-N18)) | P18: =IF(L18="","",(L18*O18))
F19: =IF(D19="","",(SUM($G$9))) | G19: =IF(D19="","",(SUM(E19)-F19)) | H19: =IF(D19="","",(D19*G19)) | N19: =IF(L19="","",($G$10)) | O19: =IF(L19="","",(SUM(M19)-N19)) | P19: =IF(L19="","",(L19*O19))
F20: =IF(D20="","",(SUM($G$9))) | G20: =IF(D20="","",(SUM(E20)-F20)) | H20: =IF(D20="","",(D20*G20)) | N20: =IF(L20="","",($G$10)) | O20: =IF(L20="","",(SUM(M20)-N20)) | P20: =IF(L20="","",(L20*O20))
F21: =IF(D21="","",(SUM($G$9))) | G21: =IF(D21="","",(SUM(E21)-F21)) | H21: =IF(D21="","",(D21*G21)) | N21: =IF(L21="","",($G$10)) | O21: =IF(L21="","",(SUM(M21)-N21)) | P21: =IF(L21="","",(L21*O21))
F22: =IF(D22="","",(SUM($G$9))) | G22: =IF(D22="","",(SUM(E22)-F22)) | H22: =IF(D22="","",(D22*G22)) | N22: =IF(L22="","",($G$10)) | O22: =IF(L22="","",(SUM(M22)-N22)) | P22: =IF(L22="","",(L22*O22))
B23: 소 계 | D23: =SUM(D16:D22) -> 0 | H23: =SUM(H16:H22) -> 0 | J23: 소 계 | L23: =SUM(L16:L22) -> 0 | P23: =SUM(P16:P22) -> 0
B26: 마 감 재 고 | G26: [단위:리터/원] | J26: 입 고 내 역 | O26: [단위:리터/원]
B27: 유종 | C27: 수량 | E27: 단가 | G27: 환산금액 | J27: 유종 | K27: 수량 | M27: 사입단가 | O27: 환산금액
B28: G | C28: 0 | E28: 0 | G28: 0 | J28: G | K28: 0 | M28: 0 | O28: 0
B29: K | C29: =$E$9-$D$23 -> 25252 | E29: =$G$9 -> 1061.6455 | G29: =C29*E29 -> 26808671 | J29: K | O29: =K29*M29 -> 0
B30: D | C30: =$E$10-$L$23 -> 109940 | E30: =$G$10 -> 1484.101 | G30: =C30*E30 -> 1.6316207e+08 | J30: D | K30: 32000 | M30: 1453.1 | O30: =K30*M30 -> 46499200
B33: 복 합 단 가
B34: 유종 | C34: 수량 | E34: 금액 | G34: 복 합 단 가
B35: G | C35: 0 | E35: 0 | G35: 0
B36: K | C36: =$C$29+$K$29 -> 25252 | E36: =$G$29+$O$29 -> 26808671 | G36: =E36/C36 -> 1061.6455
B37: D | C37: =$C$30+$K$30 -> 141940 | E37: =$G$30+$O$30 -> 2.0966127e+08 | G37: =E37/C37 -> 1477.1119
B39: 재 고 현 황 | O39: [단위:리터/원]
C40: 전일 | F40: 금일 | N40: 복합단가 | O40: 증감
C41: 재고 | F41: 입고 | H41: 출고 | K41: 마 감 재 고 | M41: 재고율
B42: 휘발유
B43: 등 유 | C43: =SUM($E$9) -> 25252 | F43: =$K$29 -> 0 | H43: =$D$23 -> 0 | K43: =$C$43-$H$43+$F$43+$O$43 -> 25252 | M43: =SUM($K$43)/$D$9 -> 0.12626 | N43: =$G$36 -> 1061.6455
B44: 경 유 | C44: =SUM($E$10) -> 109940 | F44: =$K$30 -> 32000 | H44: =$L$23 -> 0 | K44: =$C$44-$H$44+$F$44+$O$44 -> 141940 | M44: =SUM($K$44)/D10 -> 0.35485 | N44: =$G$37 -> 1477.1119
G45: 복합단가의 재고수량과 단가는 보관물량 제외니 참고해주세요!

Sheet 1212
B1: ◈ KK저장소 복합단가 운영표 - 신도시저장소
B5: 이 월 재 고 | G5: [단위:리터/원]
B7: 유종 | D7: 탱크용량 | E7: 재고수량 | F7: 재고율 | G7: 단가
C8: G | D8: 0 | E8: 0 | F8: 0 | G8: 0
C9: K | D9: 200000 | E9: =SUM('1211'!$K$43:$L$43) -> 25252 | F9: =SUM(E9)/D9 -> 0.12626 | G9: =SUM('1211'!$N$43) -> 1061.6455
C10: D | D10: 400000 | E10: =SUM('1211'!$K$44:$L$44) -> 141940 | F10: =SUM(E10)/D10 -> 0.35485 | G10: =SUM('1211'!$N$44) -> 1477.1119
B13: 출고내역(K) | G13: [단위:리터/원] | J13: 출고내역(LD) | O13: [단위:리터/원]
B14: 유종 | C14: 일반매출(사내이관 포함) | J14: 유종 | K14: 일반매출(사내이관 포함)
C15: 거래처명 | D15: 수량 | E15: 출고단가 | F15: 재고단가 | G15: 단가차액 | H15: 이익 | K15: 거래처명 | L15: 수량 | M15: 출고단가 | N15: 재고단가 | O15: 단가차액 | P15: 이익
B16: 실내 등유 | F16: =IF(D16="","",(SUM($G$9))) | G16: =IF(D16="","",(SUM(E16)-F16)) | H16: =IF(D16="","",(D16*G16)) | J16: 경유 | N16: =IF(L16="","",($G$10)) | O16: =IF(L16="","",(SUM(M16)-N16)) | P16: =IF(L16="","",(L16*O16))
F17: =IF(D17="","",(SUM($G$9))) | G17: =IF(D17="","",(SUM(E17)-F17)) | H17: =IF(D17="","",(D17*G17)) | N17: =IF(L17="","",($G$10)) | O17: =IF(L17="","",(SUM(M17)-N17)) | P17: =IF(L17="","",(L17*O17))
F18: =IF(D18="","",(SUM($G$9))) | G18: =IF(D18="","",(SUM(E18)-F18)) | H18: =IF(D18="","",(D18*G18)) | N18: =IF(L18="","",($G$10)) | O18: =IF(L18="","",(SUM(M18)-N18)) | P18: =IF(L18="","",(L18*O18))
F19: =IF(D19="","",(SUM($G$9))) | G19: =IF(D19="","",(SUM(E19)-F19)) | H19: =IF(D19="","",(D19*G19)) | N19: =IF(L19="","",($G$10)) | O19: =IF(L19="","",(SUM(M19)-N19)) | P19: =IF(L19="","",(L19*O19))
F20: =IF(D20="","",(SUM($G$9))) | G20: =IF(D20="","",(SUM(E20)-F20)) | H20: =IF(D20="","",(D20*G20)) | N20: =IF(L20="","",($G$10)) | O20: =IF(L20="","",(SUM(M20)-N20)) | P20: =IF(L20="","",(L20*O20))
F21: =IF(D21="","",(SUM($G$9))) | G21: =IF(D21="","",(SUM(E21)-F21)) | H21: =IF(D21="","",(D21*G21)) | N21: =IF(L21="","",($G$10)) | O21: =IF(L21="","",(SUM(M21)-N21)) | P21: =IF(L21="","",(L21*O21))
F22: =IF(D22="","",(SUM($G$9))) | G22: =IF(D22="","",(SUM(E22)-F22)) | H22: =IF(D22="","",(D22*G22)) | N22: =IF(L22="","",($G$10)) | O22: =IF(L22="","",(SUM(M22)-N22)) | P22: =IF(L22="","",(L22*O22))
B23: 소 계 | D23: =SUM(D16:D22) -> 0 | H23: =SUM(H16:H22) -> 0 | J23: 소 계 | L23: =SUM(L16:L22) -> 0 | P23: =SUM(P16:P22) -> 0
B26: 마 감 재 고 | G26: [단위:리터/원] | J26: 입 고 내 역 | O26: [단위:리터/원]
B27: 유종 | C27: 수량 | E27: 단가 | G27: 환산금액 | J27: 유종 | K27: 수량 | M27: 사입단가 | O27: 환산금액
B28: G | C28: 0 | E28: 0 | G28: 0 | J28: G | K28: 0 | M28: 0 | O28: 0
B29: K | C29: =$E$9-$D$23 -> 25252 | E29: =$G$9 -> 1061.6455 | G29: =C29*E29 -> 26808671 | J29: K | O29: =K29*M29 -> 0
B30: D | C30: =$E$10-$L$23 -> 141940 | E30: =$G$10 -> 1477.1119 | G30: =C30*E30 -> 2.0966127e+08 | J30: D | K30: 32000 | M30: 1453.1 | O30: =K30*M30 -> 46499200
B33: 복 합 단 가
B34: 유종 | C34: 수량 | E34: 금액 | G34: 복 합 단 가
B35: G | C35: 0 | E35: 0 | G35: 0
B36: K | C36: =$C$29+$K$29 -> 25252 | E36: =$G$29+$O$29 -> 26808671 | G36: =E36/C36 -> 1061.6455
B37: D | C37: =$C$30+$K$30 -> 173940 | E37: =$G$30+$O$30 -> 2.5616047e+08 | G37: =E37/C37 -> 1472.6944
B39: 재 고 현 황 | O39: [단위:리터/원]
C40: 전일 | F40: 금일 | N40: 복합단가 | O40: 증감
C41: 재고 | F41: 입고 | H41: 출고 | K41: 마 감 재 고 | M41: 재고율
B42: 휘발유
B43: 등 유 | C43: =SUM($E$9) -> 25252 | F43: =$K$29 -> 0 | H43: =$D$23 -> 0 | K43: =$C$43-$H$43+$F$43+$O$43 -> 25252 | M43: =SUM($K$43)/$D$9 -> 0.12626 | N43: =$G$36 -> 1061.6455
B44: 경 유 | C44: =SUM($E$10) -> 141940 | F44: =$K$30 -> 32000 | H44: =$L$23 -> 0 | K44: =$C$44-$H$44+$F$44+$O$44 -> 173940 | M44: =SUM($K$44)/D10 -> 0.43485 | N44: =$G$37 -> 1472.6944
G45: 복합단가의 재고수량과 단가는 보관물량 제외니 참고해주세요!

Sheet 1216
B1: ◈ KK저장소 복합단가 운영표 - 신도시저장소
B5: 이 월 재 고 | G5: [단위:리터/원]
B7: 유종 | D7: 탱크용량 | E7: 재고수량 | F7: 재고율 | G7: 단가
C8: G | D8: 0 | E8: 0 | F8: 0 | G8: 0
C9: K | D9: 200000 | E9: =SUM('1212'!$K$43:$L$43) -> 25252 | F9: =SUM(E9)/D9 -> 0.12626 | G9: =SUM('1212'!$N$43) -> 1061.6455
C10: D | D10: 400000 | E10: =SUM('1212'!$K$44:$L$44) -> 173940 | F10: =SUM(E10)/D10 -> 0.43485 | G10: =SUM('1212'!$N$44) -> 1472.6944
B13: 출고내역(K) | G13: [단위:리터/원] | J13: 출고내역(LD) | O13: [단위:리터/원]
B14: 유종 | C14: 일반매출(사내이관 포함) | J14: 유종 | K14: 일반매출(사내이관 포함)
C15: 거래처명 | D15: 수량 | E15: 출고단가 | F15: 재고단가 | G15: 단가차액 | H15: 이익 | K15: 거래처명 | L15: 수량 | M15: 출고단가 | N15: 재고단가 | O15: 단가차액 | P15: 이익
B16: 실내 등유 | F16: =IF(D16="","",(SUM($G$9))) | G16: =IF(D16="","",(SUM(E16)-F16)) | H16: =IF(D16="","",(D16*G16)) | J16: 경유 | L16: 2850 | N16: =IF(L16="","",($G$10)) -> 1472.6944 | O16: =IF(L16="","",(SUM(M16)-N16)) -> -1472.6944 | P16: =IF(L16="","",(L16*O16)) -> -4197179.1
F17: =IF(D17="","",(SUM($G$9))) | G17: =IF(D17="","",(SUM(E17)-F17)) | H17: =IF(D17="","",(D17*G17)) | N17: =IF(L17="","",($G$10)) | O17: =IF(L17="","",(SUM(M17)-N17)) | P17: =IF(L17="","",(L17*O17))
F18: =IF(D18="","",(SUM($G$9))) | G18: =IF(D18="","",(SUM(E18)-F18)) | H18: =IF(D18="","",(D18*G18)) | N18: =IF(L18="","",($G$10)) | O18: =IF(L18="","",(SUM(M18)-N18)) | P18: =IF(L18="","",(L18*O18))
F19: =IF(D19="","",(SUM($G$9))) | G19: =IF(D19="","",(SUM(E19)-F19)) | H19: =IF(D19="","",(D19*G19)) | N19: =IF(L19="","",($G$10)) | O19: =IF(L19="","",(SUM(M19)-N19)) | P19: =IF(L19="","",(L19*O19))
F20: =IF(D20="","",(SUM($G$9))) | G20: =IF(D20="","",(SUM(E20)-F20)) | H20: =IF(D20="","",(D20*G20)) | N20: =IF(L20="","",($G$10)) | O20: =IF(L20="","",(SUM(M20)-N20)) | P20: =IF(L20="","",(L20*O20))
F21: =IF(D21="","",(SUM($G$9))) | G21: =IF(D21="","",(SUM(E21)-F21)) | H21: =IF(D21="","",(D21*G21)) | N21: =IF(L21="","",($G$10)) | O21: =IF(L21="","",(SUM(M21)-N21)) | P21: =IF(L21="","",(L21*O21))
F22: =IF(D22="","",(SUM($G$9))) | G22: =IF(D22="","",(SUM(E22)-F22)) | H22: =IF(D22="","",(D22*G22)) | N22: =IF(L22="","",($G$10)) | O22: =IF(L22="","",(SUM(M22)-N22)) | P22: =IF(L22="","",(L22*O22))
B23: 소 계 | D23: =SUM(D16:D22) -> 0 | H23: =SUM(H16:H22) -> 0 | J23: 소 계 | L23: =SUM(L16:L22) -> 2850 | P23: =SUM(P16:P22) -> -4197179.1
B26: 마 감 재 고 | G26: [단위:리터/원] | J26: 입 고 내 역 | O26: [단위:리터/원]
B27: 유종 | C27: 수량 | E27: 단가 | G27: 환산금액 | J27: 유종 | K27: 수량 | M27: 사입단가 | O27: 환산금액
B28: G | C28: 0 | E28: 0 | G28: 0 | J28: G | K28: 0 | M28: 0 | O28: 0
B29: K | C29: =$E$9-$D$23 -> 25252 | E29: =$G$9 -> 1061.6455 | G29: =C29*E29 -> 26808671 | J29: K | O29: =K29*M29 -> 0
B30: D | C30: =$E$10-$L$23 -> 171090 | E30: =$G$10 -> 1472.6944 | G30: =C30*E30 -> 2.5196329e+08 | J30: D | O30: =K30*M30 -> 0
B33: 복 합 단 가
B34: 유종 | C34: 수량 | E34: 금액 | G34: 복 합 단 가
B35: G | C35: 0 | E35: 0 | G35: 0
B36: K | C36: =$C$29+$K$29 -> 25252 | E36: =$G$29+$O$29 -> 26808671 | G36: =E36/C36 -> 1061.6455
B37: D | C37: =$C$30+$K$30 -> 171090 | E37: =$G$30+$O$30 -> 2.5196329e+08 | G37: =E37/C37 -> 1472.6944
B39: 재 고 현 황 | O39: [단위:리터/원]
C40: 전일 | F40: 금일 | N40: 복합단가 | O40: 증감
C41: 재고 | F41: 입고 | H41: 출고 | K41: 마 감 재 고 | M41: 재고율
B42: 휘발유
B43: 등 유 | C43: =SUM($E$9) -> 25252 | F43: =$K$29 -> 0 | H43: =$D$23 -> 0 | K43: =$C$43-$H$43+$F$43+$O$43 -> 25252 | M43: =SUM($K$43)/$D$9 -> 0.12626 | N43: =$G$36 -> 1061.6455
B44: 경 유 | C44: =SUM($E$10) -> 173940 | F44: =$K$30 -> 0 | H44: =$L$23 -> 2850 | K44: =$C$44-$H$44+$F$44+$O$44 -> 171090 | M44: =SUM($K$44)/D10 -> 0.427725 | N44: =$G$37 -> 1472.6944
G45: 복합단가의 재고수량과 단가는 보관물량 제외니 참고해주세요!

Sheet 1217
B1: ◈ KK저장소 복합단가 운영표 - 신도시저장소
B5: 이 월 재 고 | G5: [단위:리터/원]
B7: 유종 | D7: 탱크용량 | E7: 재고수량 | F7: 재고율 | G7: 단가
C8: G | D8: 0 | E8: 0 | F8: 0 | G8: 0
C9: K | D9: 200000 | E9: =SUM('1216'!$K$43:$L$43) -> 25252 | F9: =SUM(E9)/D9 -> 0.12626 | G9: =SUM('1216'!$N$43) -> 1061.6455
C10: D | D10: 400000 | E10: =SUM('1216'!$K$44:$L$44) -> 171090 | F10: =SUM(E10)/D10 -> 0.427725 | G10: =SUM('1216'!$N$44) -> 1472.6944
B13: 출고내역(K) | G13: [단위:리터/원] | J13: 출고내역(LD) | O13: [단위:리터/원]
B14: 유종 | C14: 일반매출(사내이관 포함) | J14: 유종 | K14: 일반매출(사내이관 포함)
C15: 거래처명 | D15: 수량 | E15: 출고단가 | F15: 재고단가 | G15: 단가차액 | H15: 이익 | K15: 거래처명 | L15: 수량 | M15: 출고단가 | N15: 재고단가 | O15: 단가차액 | P15: 이익
B16: 실내 등유 | F16: =IF(D16="","",(SUM($G$9))) | G16: =IF(D16="","",(SUM(E16)-F16)) | H16: =IF(D16="","",(D16*G16)) | J16: 경유 | L16: 3000 | N16: =IF(L16="","",($G$10)) -> 1472.6944 | O16: =IF(L16="","",(SUM(M16)-N16)) -> -1472.6944 | P16: =IF(L16="","",(L16*O16)) -> -4418083.2
F17: =IF(D17="","",(SUM($G$9))) | G17: =IF(D17="","",(SUM(E17)-F17)) | H17: =IF(D17="","",(D17*G17)) | N17: =IF(L17="","",($G$10)) | O17: =IF(L17="","",(SUM(M17)-N17)) | P17: =IF(L17="","",(L17*O17))
F18: =IF(D18="","",(SUM($G$9))) | G18: =IF(D18="","",(SUM(E18)-F18)) | H18: =IF(D18="","",(D18*G18)) | N18: =IF(L18="","",($G$10)) | O18: =IF(L18="","",(SUM(M18)-N18)) | P18: =IF(L18="","",(L18*O18))
F19: =IF(D19="","",(SUM($G$9))) | G19: =IF(D19="","",(SUM(E19)-F19)) | H19: =IF(D19="","",(D19*G19)) | N19: =IF(L19="","",($G$10)) | O19: =IF(L19="","",(SUM(M19)-N19)) | P19: =IF(L19="","",(L19*O19))
F20: =IF(D20="","",(SUM($G$9))) | G20: =IF(D20="","",(SUM(E20)-F20)) | H20: =IF(D20="","",(D20*G20)) | N20: =IF(L20="","",($G$10)) | O20: =IF(L20="","",(SUM(M20)-N20)) | P20: =IF(L20="","",(L20*O20))
F21: =IF(D21="","",(SUM($G$9))) | G21: =IF(D21="","",(SUM(E21)-F21)) | H21: =IF(D21="","",(D21*G21)) | N21: =IF(L21="","",($G$10)) | O21: =IF(L21="","",(SUM(M21)-N21)) | P21: =IF(L21="","",(L21*O21))
F22: =IF(D22="","",(SUM($G$9))) | G22: =IF(D22="","",(SUM(E22)-F22)) | H22: =IF(D22="","",(D22*G22)) | N22: =IF(L22="","",($G$10)) | O22: =IF(L22="","",(SUM(M22)-N22)) | P22: =IF(L22="","",(L22*O22))
B23: 소 계 | D23: =SUM(D16:D22) -> 0 | H23: =SUM(H16:H22) -> 0 | J23: 소 계 | L23: =SUM(L16:L22) -> 3000 | P23: =SUM(P16:P22) -> -4418083.2
B26: 마 감 재 고 | G26: [단위:리터/원] | J26: 입 고 내 역 | O26: [단위:리터/원]
B27: 유종 | C27: 수량 | E27: 단가 | G27: 환산금액 | J27: 유종 | K27: 수량 | M27: 사입단가 | O27: 환산금액
B28: G | C28: 0 | E28: 0 | G28: 0 | J28: G | K28: 0 | M28: 0 | O28: 0
B29: K | C29: =$E$9-$D$23 -> 25252 | E29: =$G$9 -> 1061.6455 | G29: =C29*E29 -> 26808671 | J29: K | O29: =K29*M29 -> 0
B30: D | C30: =$E$10-$L$23 -> 168090 | E30: =$G$10 -> 1472.6944 | G30: =C30*E30 -> 2.475452e+08 | J30: D | O30: =K30*M30 -> 0
B33: 복 합 단 가
B34: 유종 | C34: 수량 | E34: 금액 | G34: 복 합 단 가
B35: G | C35: 0 | E35: 0 | G35: 0
B36: K | C36: =$C$29+$K$29 -> 25252 | E36: =$G$29+$O$29 -> 26808671 | G36: =E36/C36 -> 1061.6455
B37: D | C37: =$C$30+$K$30 -> 168090 | E37: =$G$30+$O$30 -> 2.475452e+08 | G37: =E37/C37 -> 1472.6944
B39: 재 고 현 황 | O39: [단위:리터/원]
C40: 전일 | F40: 금일 | N40: 복합단가 | O40: 증감
C41: 재고 | F41: 입고 | H41: 출고 | K41: 마 감 재 고 | M41: 재고율
B42: 휘발유
B43: 등 유 | C43: =SUM($E$9) -> 25252 | F43: =$K$29 -> 0 | H43: =$D$23 -> 0 | K43: =$C$43-$H$43+$F$43+$O$43 -> 25252 | M43: =SUM($K$43)/$D$9 -> 0.12626 | N43: =$G$36 -> 1061.6455
B44: 경 유 | C44: =SUM($E$10) -> 171090 | F44: =$K$30 -> 0 | H44: =$L$23 -> 3000 | K44: =$C$44-$H$44+$F$44+$O$44 -> 168090 | M44: =SUM($K$44)/D10 -> 0.420225 | N44: =$G$37 -> 1472.6944
G45: 복합단가의 재고수량과 단가는 보관물량 제외니 참고해주세요!

Sheet 1219
B1: ◈ KK저장소 복합단가 운영표 - 신도시저장소
B5: 이 월 재 고 | G5: [단위:리터/원]
B7: 유종 | D7: 탱크용량 | E7: 재고수량 | F7: 재고율 | G7: 단가
C8: G | D8: 0 | E8: 0 | F8: 0 | G8: 0
C9: K | D9: 200000 | E9: =SUM('1217'!$K$43:$L$43) -> 25252 | F9: =SUM(E9)/D9 -> 0.12626 | G9: =SUM('1217'!$N$43) -> 1061.6455
C10: D | D10: 400000 | E10: =SUM('1217'!$K$44:$L$44) -> 168090 | F10: =SUM(E10)/D10 -> 0.420225 | G10: =SUM('1217'!$N$44) -> 1472.6944
B13: 출고내역(K) | G13: [단위:리터/원] | J13: 출고내역(LD) | O13: [단위:리터/원]
B14: 유종 | C14: 일반매출(사내이관 포함) | J14: 유종 | K14: 일반매출(사내이관 포함)
C15: 거래처명 | D15: 수량 | E15: 출고단가 | F15: 재고단가 | G15: 단가차액 | H15: 이익 | K15: 거래처명 | L15: 수량 | M15: 출고단가 | N15: 재고단가 | O15: 단가차액 | P15: 이익
B16: 실내 등유 | F16: =IF(D16="","",(SUM($G$9))) | G16: =IF(D16="","",(SUM(E16)-F16)) | H16: =IF(D16="","",(D16*G16)) | J16: 경유 | K16: 고아농협 | L16: 2700 | N16: =IF(L16="","",($G$10)) -> 1472.6944 | O16: =IF(L16="","",(SUM(M16)-N16)) -> -1472.6944 | P16: =IF(L16="","",(L16*O16)) -> -3976274.9
F17: =IF(D17="","",(SUM($G$9))) | G17: =IF(D17="","",(SUM(E17)-F17)) | H17: =IF(D17="","",(D17*G17)) | N17: =IF(L17="","",($G$10)) | O17: =IF(L17="","",(SUM(M17)-N17)) | P17: =IF(L17="","",(L17*O17))
F18: =IF(D18="","",(SUM($G$9))) | G18: =IF(D18="","",(SUM(E18)-F18)) | H18: =IF(D18="","",(D18*G18)) | N18: =IF(L18="","",($G$10)) | O18: =IF(L18="","",(SUM(M18)-N18)) | P18: =IF(L18="","",(L18*O18))
F19: =IF(D19="","",(SUM($G$9))) | G19: =IF(D19="","",(SUM(E19)-F19)) | H19: =IF(D19="","",(D19*G19)) | N19: =IF(L19="","",($G$10)) | O19: =IF(L19="","",(SUM(M19)-N19)) | P19: =IF(L19="","",(L19*O19))
F20: =IF(D20="","",(SUM($G$9))) | G20: =IF(D20="","",(SUM(E20)-F20)) | H20: =IF(D20="","",(D20*G20)) | N20: =IF(L20="","",($G$10)) | O20: =IF(L20="","",(SUM(M20)-N20)) | P20: =IF(L20="","",(L20*O20))
F21: =IF(D21="","",(SUM($G$9))) | G21: =IF(D21="","",(SUM(E21)-F21)) | H21: =IF(D21="","",(D21*G21)) | N21: =IF(L21="","",($G$10)) | O21: =IF(L21="","",(SUM(M21)-N21)) | P21: =IF(L21="","",(L21*O21))
F22: =IF(D22="","",(SUM($G$9))) | G22: =IF(D22="","",(SUM(E22)-F22)) | H22: =IF(D22="","",(D22*G22)) | N22: =IF(L22="","",($G$10)) | O22: =IF(L22="","",(SUM(M22)-N22)) | P22: =IF(L22="","",(L22*O22))
B23: 소 계 | D23: =SUM(D16:D22) -> 0 | H23: =SUM(H16:H22) -> 0 | J23: 소 계 | L23: =SUM(L16:L22) -> 2700 | P23: =SUM(P16:P22) -> -3976274.9
B26: 마 감 재 고 | G26: [단위:리터/원] | J26: 입 고 내 역 | O26: [단위:리터/원]
B27: 유종 | C27: 수량 | E27: 단가 | G27: 환산금액 | J27: 유종 | K27: 수량 | M27: 사입단가 | O27: 환산금액
B28: G | C28: 0 | E28: 0 | G28: 0 | J28: G | K28: 0 | M28: 0 | O28: 0
B29: K | C29: =$E$9-$D$23 -> 25252 | E29: =$G$9 -> 1061.6455 | G29: =C29*E29 -> 26808671 | J29: K | O29: =K29*M29 -> 0
B30: D | C30: =$E$10-$L$23 -> 165390 | E30: =$G$10 -> 1472.6944 | G30: =C30*E30 -> 2.4356893e+08 | J30: D | O30: =K30*M30 -> 0
B33: 복 합 단 가
B34: 유종 | C34: 수량 | E34: 금액 | G34: 복 합 단 가
B35: G | C35: 0 | E35: 0 | G35: 0
B36: K | C36: =$C$29+$K$29 -> 25252 | E36: =$G$29+$O$29 -> 26808671 | G36: =E36/C36 -> 1061.6455
B37: D | C37: =$C$30+$K$30 -> 165390 | E37: =$G$30+$O$30 -> 2.4356893e+08 | G37: =E37/C37 -> 1472.6944
B39: 재 고 현 황 | O39: [단위:리터/원]
C40: 전일 | F40: 금일 | N40: 복합단가 | O40: 증감
C41: 재고 | F41: 입고 | H41: 출고 | K41: 마 감 재 고 | M41: 재고율
B42: 휘발유
B43: 등 유 | C43: =SUM($E$9) -> 25252 | F43: =$K$29 -> 0 | H43: =$D$23 -> 0 | K43: =$C$43-$H$43+$F$43+$O$43 -> 24174 | M43: =SUM($K$43)/$D$9 -> 0.12087 | N43: =$G$36 -> 1061.6455 | O43: -1078
B44: 경 유 | C44: =SUM($E$10) -> 168090 | F44: =$K$30 -> 0 | H44: =$L$23 -> 2700 | K44: =$C$44-$H$44+$F$44+$O$44 -> 162794 | M44: =SUM($K$44)/D10 -> 0.406985 | N44: =$G$37 -> 1472.6944 | O44: -2596
G45: 복합단가의 재고수량과 단가는 보관물량 제외니 참고해주세요!

Sheet 1224
B1: ◈ KK저장소 복합단가 운영표 - 신도시저장소
B5: 이 월 재 고 | G5: [단위:리터/원]
B7: 유종 | D7: 탱크용량 | E7: 재고수량 | F7: 재고율 | G7: 단가
C8: G | D8: 0 | E8: 0 | F8: 0 | G8: 0
C9: K | D9: 200000 | E9: =SUM('1219'!$K$43:$L$43) -> 24174 | F9: =SUM(E9)/D9 -> 0.12087 | G9: =SUM('1219'!$N$43) -> 1061.6455
C10: D | D10: 400000 | E10: =SUM('1219'!$K$44:$L$44) -> 162794 | F10: =SUM(E10)/D10 -> 0.406985 | G10: =SUM('1219'!$N$44) -> 1472.6944
B13: 출고내역(K) | G13: [단위:리터/원] | J13: 출고내역(LD) | O13: [단위:리터/원]
B14: 유종 | C14: 일반매출(사내이관 포함) | J14: 유종 | K14: 일반매출(사내이관 포함)
C15: 거래처명 | D15: 수량 | E15: 출고단가 | F15: 재고단가 | G15: 단가차액 | H15: 이익 | K15: 거래처명 | L15: 수량 | M15: 출고단가 | N15: 재고단가 | O15: 단가차액 | P15: 이익
B16: 실내 등유 | F16: =IF(D16="","",(SUM($G$9))) | G16: =IF(D16="","",(SUM(E16)-F16)) | H16: =IF(D16="","",(D16*G16)) | J16: 경유 | K16: 경천 | L16: 32000 | N16: =IF(L16="","",($G$10)) -> 1472.6944 | O16: =IF(L16="","",(SUM(M16)-N16)) -> -1472.6944 | P16: =IF(L16="","",(L16*O16)) -> -47126221
F17: =IF(D17="","",(SUM($G$9))) | G17: =IF(D17="","",(SUM(E17)-F17)) | H17: =IF(D17="","",(D17*G17)) | K17: 고아농협 | L17: 2330 | N17: =IF(L17="","",($G$10)) -> 1472.6944 | O17: =IF(L17="","",(SUM(M17)-N17)) -> -1472.6944 | P17: =IF(L17="","",(L17*O17)) -> -3431378
F18: =IF(D18="","",(SUM($G$9))) | G18: =IF(D18="","",(SUM(E18)-F18)) | H18: =IF(D18="","",(D18*G18)) | N18: =IF(L18="","",($G$10)) | O18: =IF(L18="","",(SUM(M18)-N18)) | P18: =IF(L18="","",(L18*O18))
F19: =IF(D19="","",(SUM($G$9))) | G19: =IF(D19="","",(SUM(E19)-F19)) | H19: =IF(D19="","",(D19*G19)) | N19: =IF(L19="","",($G$10)) | O19: =IF(L19="","",(SUM(M19)-N19)) | P19: =IF(L19="","",(L19*O19))
F20: =IF(D20="","",(SUM($G$9))) | G20: =IF(D20="","",(SUM(E20)-F20)) | H20: =IF(D20="","",(D20*G20)) | N20: =IF(L20="","",($G$10)) | O20: =IF(L20="","",(SUM(M20)-N20)) | P20: =IF(L20="","",(L20*O20))
F21: =IF(D21="","",(SUM($G$9))) | G21: =IF(D21="","",(SUM(E21)-F21)) | H21: =IF(D21="","",(D21*G21)) | N21: =IF(L21="","",($G$10)) | O21: =IF(L21="","",(SUM(M21)-N21)) | P21: =IF(L21="","",(L21*O21))
F22: =IF(D22="","",(SUM($G$9))) | G22: =IF(D22="","",(SUM(E22)-F22)) | H22: =IF(D22="","",(D22*G22)) | N22: =IF(L22="","",($G$10)) | O22: =IF(L22="","",(SUM(M22)-N22)) | P22: =IF(L22="","",(L22*O22))
B23: 소 계 | D23: =SUM(D16:D22) -> 0 | H23: =SUM(H16:H22) -> 0 | J23: 소 계 | L23: =SUM(L16:L22) -> 34330 | P23: =SUM(P16:P22) -> -50557599
B26: 마 감 재 고 | G26: [단위:리터/원] | J26: 입 고 내 역 | O26: [단위:리터/원]
B27: 유종 | C27: 수량 | E27: 단가 | G27: 환산금액 | J27: 유종 | K27: 수량 | M27: 사입단가 | O27: 환산금액
B28: G | C28: 0 | E28: 0 | G28: 0 | J28: G | K28: 0 | M28: 0 | O28: 0
B29: K | C29: =$E$9-$D$23 -> 24174 | E29: =$G$9 -> 1061.6455 | G29: =C29*E29 -> 25664218 | J29: K | O29: =K29*M29 -> 0
B30: D | C30: =$E$10-$L$23 -> 128464 | E30: =$G$10 -> 1472.6944 | G30: =C30*E30 -> 1.8918821e+08 | J30: D | O30: =K30*M30 -> 0
B33: 복 합 단 가
B34: 유종 | C34: 수량 | E34: 금액 | G34: 복 합 단 가
B35: G | C35: 0 | E35: 0 | G35: 0
B36: K | C36: =$C$29+$K$29 -> 24174 | E36: =$G$29+$O$29 -> 25664218 | G36: =E36/C36 -> 1061.6455
B37: D | C37: =$C$30+$K$30 -> 128464 | E37: =$G$30+$O$30 -> 1.8918821e+08 | G37: =E37/C37 -> 1472.6944
B39: 재 고 현 황 | O39: [단위:리터/원]
C40: 전일 | F40: 금일 | N40: 복합단가 | O40: 증감
C41: 재고 | F41: 입고 | H41: 출고 | K41: 마 감 재 고 | M41: 재고율
B42: 휘발유
B43: 등 유 | C43: =SUM($E$9) -> 24174 | F43: =$K$29 -> 0 | H43: =$D$23 -> 0 | K43: =$C$43-$H$43+$F$43+$O$43 -> 24174 | M43: =SUM($K$43)/$D$9 -> 0.12087 | N43: =$G$36 -> 1061.6455
B44: 경 유 | C44: =SUM($E$10) -> 162794 | F44: =$K$30 -> 0 | H44: =$L$23 -> 34330 | K44: =$C$44-$H$44+$F$44+$O$44 -> 128464 | M44: =SUM($K$44)/D10 -> 0.32116 | N44: =$G$37 -> 1472.6944
G45: 복합단가의 재고수량과 단가는 보관물량 제외니 참고해주세요!

Sheet 1228
B1: ◈ KK저장소 복합단가 운영표 - 신도시저장소
B5: 이 월 재 고 | G5: [단위:리터/원]
B7: 유종 | D7: 탱크용량 | E7: 재고수량 | F7: 재고율 | G7: 단가
C8: G | D8: 0 | E8: 0 | F8: 0 | G8: 0
C9: K | D9: 200000 | E9: =SUM('1224'!$K$43:$L$43) -> 24174 | F9: =SUM(E9)/D9 -> 0.12087 | G9: =SUM('1224'!$N$43) -> 1061.6455
C10: D | D10: 400000 | E10: =SUM('1224'!$K$44:$L$44) -> 128464 | F10: =SUM(E10)/D10 -> 0.32116 | G10: =SUM('1224'!$N$44) -> 1472.6944
B13: 출고내역(K) | G13: [단위:리터/원] | J13: 출고내역(LD) | O13: [단위:리터/원]
B14: 유종 | C14: 일반매출(사내이관 포함) | J14: 유종 | K14: 일반매출(사내이관 포함)
C15: 거래처명 | D15: 수량 | E15: 출고단가 | F15: 재고단가 | G15: 단가차액 | H15: 이익 | K15: 거래처명 | L15: 수량 | M15: 출고단가 | N15: 재고단가 | O15: 단가차액 | P15: 이익
B16: 실내 등유 | F16: =IF(D16="","",(SUM($G$9))) | G16: =IF(D16="","",(SUM(E16)-F16)) | H16: =IF(D16="","",(D16*G16)) | J16: 경유 | N16: =IF(L16="","",($G$10)) | O16: =IF(L16="","",(SUM(M16)-N16)) | P16: =IF(L16="","",(L16*O16))
F17: =IF(D17="","",(SUM($G$9))) | G17: =IF(D17="","",(SUM(E17)-F17)) | H17: =IF(D17="","",(D17*G17)) | N17: =IF(L17="","",($G$10)) | O17: =IF(L17="","",(SUM(M17)-N17)) | P17: =IF(L17="","",(L17*O17))
F18: =IF(D18="","",(SUM($G$9))) | G18: =IF(D18="","",(SUM(E18)-F18)) | H18: =IF(D18="","",(D18*G18)) | N18: =IF(L18="","",($G$10)) | O18: =IF(L18="","",(SUM(M18)-N18)) | P18: =IF(L18="","",(L18*O18))
F19: =IF(D19="","",(SUM($G$9))) | G19: =IF(D19="","",(SUM(E19)-F19)) | H19: =IF(D19="","",(D19*G19)) | N19: =IF(L19="","",($G$10)) | O19: =IF(L19="","",(SUM(M19)-N19)) | P19: =IF(L19="","",(L19*O19))
F20: =IF(D20="","",(SUM($G$9))) | G20: =IF(D20="","",(SUM(E20)-F20)) | H20: =IF(D20="","",(D20*G20)) | N20: =IF(L20="","",($G$10)) | O20: =IF(L20="","",(SUM(M20)-N20)) | P20: =IF(L20="","",(L20*O20))
F21: =IF(D21="","",(SUM($G$9))) | G21: =IF(D21="","",(SUM(E21)-F21)) | H21: =IF(D21="","",(D21*G21)) | N21: =IF(L21="","",($G$10)) | O21: =IF(L21="","",(SUM(M21)-N21)) | P21: =IF(L21="","",(L21*O21))
F22: =IF(D22="","",(SUM($G$9))) | G22: =IF(D22="","",(SUM(E22)-F22)) | H22: =IF(D22="","",(D22*G22)) | N22: =IF(L22="","",($G$10)) | O22: =IF(L22="","",(SUM(M22)-N22)) | P22: =IF(L22="","",(L22*O22))
B23: 소 계 | D23: =SUM(D16:D22) -> 0 | H23: =SUM(H16:H22) -> 0 | J23: 소 계 | L23: =SUM(L16:L22) -> 0 | P23: =SUM(P16:P22) -> 0
B26: 마 감 재 고 | G26: [단위:리터/원] | J26: 입 고 내 역 | O26: [단위:리터/원]
B27: 유종 | C27: 수량 | E27: 단가 | G27: 환산금액 | J27: 유종 | K27: 수량 | M27: 사입단가 | O27: 환산금액
B28: G | C28: 0 | E28: 0 | G28: 0 | J28: G | K28: 0 | M28: 0 | O28: 0
B29: K | C29: =$E$9-$D$23 -> 24174 | E29: =$G$9 -> 1061.6455 | G29: =C29*E29 -> 25664218 | J29: K | K29: 32000 | M29: 999.5 | O29: =K29*M29 -> 31984000
B30: D | C30: =$E$10-$L$23 -> 128464 | E30: =$G$10 -> 1472.6944 | G30: =C30*E30 -> 1.8918821e+08 | J30: D | K30: 88000 | M30: 1453.1 | O30: =K30*M30 -> 1.278728e+08
B33: 복 합 단 가
B34: 유종 | C34: 수량 | E34: 금액 | G34: 복 합 단 가
B35: G | C35: 0 | E35: 0 | G35: 0
B36: K | C36: =$C$29+$K$29 -> 56174 | E36: =$G$29+$O$29 -> 57648218 | G36: =E36/C36 -> 1026.2438
B37: D | C37: =$C$30+$K$30 -> 216464 | E37: =$G$30+$O$30 -> 3.1706101e+08 | G37: =E37/C37 -> 1464.7286
B39: 재 고 현 황 | O39: [단위:리터/원]
C40: 전일 | F40: 금일 | N40: 복합단가 | O40: 증감
C41: 재고 | F41: 입고 | H41: 출고 | K41: 마 감 재 고 | M41: 재고율
B42: 휘발유
B43: 등 유 | C43: =SUM($E$9) -> 24174 | F43: =$K$29 -> 32000 | H43: =$D$23 -> 0 | K43: =$C$43-$H$43+$F$43+$O$43 -> 56174 | M43: =SUM($K$43)/$D$9 -> 0.28087 | N43: =$G$36 -> 1026.2438
B44: 경 유 | C44: =SUM($E$10) -> 128464 | F44: =$K$30 -> 88000 | H44: =$L$23 -> 0 | K44: =$C$44-$H$44+$F$44+$O$44 -> 216464 | M44: =SUM($K$44)/D10 -> 0.54116 | N44: =$G$37 -> 1464.7286
G45: 복합단가의 재고수량과 단가는 보관물량 제외니 참고해주세요!

Sheet 1230
B1: ◈ KK저장소 복합단가 운영표 - 신도시저장소
B5: 이 월 재 고 | G5: [단위:리터/원]
B7: 유종 | D7: 탱크용량 | E7: 재고수량 | F7: 재고율 | G7: 단가
C8: G | D8: 0 | E8: 0 | F8: 0 | G8: 0
C9: K | D9: 200000 | E9: =SUM('1228'!$K$43:$L$43) -> 56174 | F9: =SUM(E9)/D9 -> 0.28087 | G9: =SUM('1228'!$N$43) -> 1026.2438
C10: D | D10: 400000 | E10: =SUM('1228'!$K$44:$L$44) -> 216464 | F10: =SUM(E10)/D10 -> 0.54116 | G10: =SUM('1228'!$N$44) -> 1464.7286
B13: 출고내역(K) | G13: [단위:리터/원] | J13: 출고내역(LD) | O13: [단위:리터/원]
B14: 유종 | C14: 일반매출(사내이관 포함) | J14: 유종 | K14: 일반매출(사내이관 포함)
C15: 거래처명 | D15: 수량 | E15: 출고단가 | F15: 재고단가 | G15: 단가차액 | H15: 이익 | K15: 거래처명 | L15: 수량 | M15: 출고단가 | N15: 재고단가 | O15: 단가차액 | P15: 이익
B16: 실내 등유 | F16: =IF(D16="","",(SUM($G$9))) | G16: =IF(D16="","",(SUM(E16)-F16)) | H16: =IF(D16="","",(D16*G16)) | J16: 경유 | K16: 고아농협 | L16: 3000 | N16: =IF(L16="","",($G$10)) -> 1464.7286 | O16: =IF(L16="","",(SUM(M16)-N16)) -> -1464.7286 | P16: =IF(L16="","",(L16*O16)) -> -4394185.8
F17: =IF(D17="","",(SUM($G$9))) | G17: =IF(D17="","",(SUM(E17)-F17)) | H17: =IF(D17="","",(D17*G17)) | N17: =IF(L17="","",($G$10)) | O17: =IF(L17="","",(SUM(M17)-N17)) | P17: =IF(L17="","",(L17*O17))
F18: =IF(D18="","",(SUM($G$9))) | G18: =IF(D18="","",(SUM(E18)-F18)) | H18: =IF(D18="","",(D18*G18)) | N18: =IF(L18="","",($G$10)) | O18: =IF(L18="","",(SUM(M18)-N18)) | P18: =IF(L18="","",(L18*O18))
F19: =IF(D19="","",(SUM($G$9))) | G19: =IF(D19="","",(SUM(E19)-F19)) | H19: =IF(D19="","",(D19*G19)) | N19: =IF(L19="","",($G$10)) | O19: =IF(L19="","",(SUM(M19)-N19)) | P19: =IF(L19="","",(L19*O19))
F20: =IF(D20="","",(SUM($G$9))) | G20: =IF(D20="","",(SUM(E20)-F20)) | H20: =IF(D20="","",(D20*G20)) | N20: =IF(L20="","",($G$10)) | O20: =IF(L20="","",(SUM(M20)-N20)) | P20: =IF(L20="","",(L20*O20))
F21: =IF(D21="","",(SUM($G$9))) | G21: =IF(D21="","",(SUM(E21)-F21)) | H21: =IF(D21="","",(D21*G21)) | N21: =IF(L21="","",($G$10)) | O21: =IF(L21="","",(SUM(M21)-N21)) | P21: =IF(L21="","",(L21*O21))
F22: =IF(D22="","",(SUM($G$9))) | G22: =IF(D22="","",(SUM(E22)-F22)) | H22: =IF(D22="","",(D22*G22)) | N22: =IF(L22="","",($G$10)) | O22: =IF(L22="","",(SUM(M22)-N22)) | P22: =IF(L22="","",(L22*O22))
B23: 소 계 | D23: =SUM(D16:D22) -> 0 | H23: =SUM(H16:H22) -> 0 | J23: 소 계 | L23: =SUM(L16:L22) -> 3000 | P23: =SUM(P16:P22) -> -4394185.8
B26: 마 감 재 고 | G26: [단위:리터/원] | J26: 입 고 내 역 | O26: [단위:리터/원]
B27: 유종 | C27: 수량 | E27: 단가 | G27: 환산금액 | J27: 유종 | K27: 수량 | M27: 사입단가 | O27: 환산금액
B28: G | C28: 0 | E28: 0 | G28: 0 | J28: G | K28: 0 | M28: 0 | O28: 0
B29: K | C29: =$E$9-$D$23 -> 56174 | E29: =$G$9 -> 1026.2438 | G29: =C29*E29 -> 57648218 | J29: K | O29: =K29*M29 -> 0
B30: D | C30: =$E$10-$L$23 -> 213464 | E30: =$G$10 -> 1464.7286 | G30: =C30*E30 -> 3.1266683e+08 | J30: D | O30: =K30*M30 -> 0
B33: 복 합 단 가
B34: 유종 | C34: 수량 | E34: 금액 | G34: 복 합 단 가
B35: G | C35: 0 | E35: 0 | G35: 0
B36: K | C36: =$C$29+$K$29 -> 56174 | E36: =$G$29+$O$29 -> 57648218 | G36: =E36/C36 -> 1026.2438
B37: D | C37: =$C$30+$K$30 -> 213464 | E37: =$G$30+$O$30 -> 3.1266683e+08 | G37: =E37/C37 -> 1464.7286
B39: 재 고 현 황 | O39: [단위:리터/원]
C40: 전일 | F40: 금일 | N40: 복합단가 | O40: 증감
C41: 재고 | F41: 입고 | H41: 출고 | K41: 마 감 재 고 | M41: 재고율
B42: 휘발유
B43: 등 유 | C43: =SUM($E$9) -> 56174 | F43: =$K$29 -> 0 | H43: =$D$23 -> 0 | K43: =$C$43-$H$43+$F$43+$O$43 -> 56174 | M43: =SUM($K$43)/$D$9 -> 0.28087 | N43: =$G$36 -> 1026.2438
B44: 경 유 | C44: =SUM($E$10) -> 216464 | F44: =$K$30 -> 0 | H44: =$L$23 -> 3000 | K44: =$C$44-$H$44+$F$44+$O$44 -> 213464 | M44: =SUM($K$44)/D10 -> 0.53366 | N44: =$G$37 -> 1464.7286
G45: 복합단가의 재고수량과 단가는 보관물량 제외니 참고해주세요!

Sheet 0105
B1: ◈ KK저장소 복합단가 운영표 - 신도시저장소
B5: 이 월 재 고 | G5: [단위:리터/원]
B7: 유종 | D7: 탱크용량 | E7: 재고수량 | F7: 재고율 | G7: 단가
C8: G | D8: 0 | E8: 0 | F8: 0 | G8: 0
C9: K | D9: 200000 | E9: =SUM('1230'!$K$43:$L$43) -> 56174 | F9: =SUM(E9)/D9 -> 0.28087 | G9: =SUM('1230'!$N$43) -> 1026.2438
C10: D | D10: 400000 | E10: =SUM('1230'!$K$44:$L$44) -> 213464 | F10: =SUM(E10)/D10 -> 0.53366 | G10: =SUM('1230'!$N$44) -> 1464.7286
B13: 출고내역(K) | G13: [단위:리터/원] | J13: 출고내역(LD) | O13: [단위:리터/원]
B14: 유종 | C14: 일반매출(사내이관 포함) | J14: 유종 | K14: 일반매출(사내이관 포함)
C15: 거래처명 | D15: 수량 | E15: 출고단가 | F15: 재고단가 | G15: 단가차액 | H15: 이익 | K15: 거래처명 | L15: 수량 | M15: 출고단가 | N15: 재고단가 | O15: 단가차액 | P15: 이익
B16: 실내 등유 | C16: 일호셀프 | D16: 28000 | F16: =IF(D16="","",(SUM($G$9))) -> 1026.2438 | G16: =IF(D16="","",(SUM(E16)-F16)) -> -1026.2438 | H16: =IF(D16="","",(D16*G16)) -> -28734826 | J16: 경유 | K16: 성서고속 | L16: 24000 | N16: =IF(L16="","",($G$10)) -> 1464.7286 | O16: =IF(L16="","",(SUM(M16)-N16)) -> -1464.7286 | P16: =IF(L16="","",(L16*O16)) -> -35153487
C17: 성서고속 | D17: 4000 | F17: =IF(D17="","",(SUM($G$9))) -> 1026.2438 | G17: =IF(D17="","",(SUM(E17)-F17)) -> -1026.2438 | H17: =IF(D17="","",(D17*G17)) -> -4104975.1 | N17: =IF(L17="","",($G$10)) | O17: =IF(L17="","",(SUM(M17)-N17)) | P17: =IF(L17="","",(L17*O17))
F18: =IF(D18="","",(SUM($G$9))) | G18: =IF(D18="","",(SUM(E18)-F18)) | H18: =IF(D18="","",(D18*G18)) | N18: =IF(L18="","",($G$10)) | O18: =IF(L18="","",(SUM(M18)-N18)) | P18: =IF(L18="","",(L18*O18))
F19: =IF(D19="","",(SUM($G$9))) | G19: =IF(D19="","",(SUM(E19)-F19)) | H19: =IF(D19="","",(D19*G19)) | N19: =IF(L19="","",($G$10)) | O19: =IF(L19="","",(SUM(M19)-N19)) | P19: =IF(L19="","",(L19*O19))
F20: =IF(D20="","",(SUM($G$9))) | G20: =IF(D20="","",(SUM(E20)-F20)) | H20: =IF(D20="","",(D20*G20)) | N20: =IF(L20="","",($G$10)) | O20: =IF(L20="","",(SUM(M20)-N20)) | P20: =IF(L20="","",(L20*O20))
F21: =IF(D21="","",(SUM($G$9))) | G21: =IF(D21="","",(SUM(E21)-F21)) | H21: =IF(D21="","",(D21*G21)) | N21: =IF(L21="","",($G$10)) | O21: =IF(L21="","",(SUM(M21)-N21)) | P21: =IF(L21="","",(L21*O21))
F22: =IF(D22="","",(SUM($G$9))) | G22: =IF(D22="","",(SUM(E22)-F22)) | H22: =IF(D22="","",(D22*G22)) | N22: =IF(L22="","",($G$10)) | O22: =IF(L22="","",(SUM(M22)-N22)) | P22: =IF(L22="","",(L22*O22))
B23: 소 계 | D23: =SUM(D16:D22) -> 32000 | H23: =SUM(H16:H22) -> -32839801 | J23: 소 계 | L23: =SUM(L16:L22) -> 24000 | P23: =SUM(P16:P22) -> -35153487
B26: 마 감 재 고 | G26: [단위:리터/원] | J26: 입 고 내 역 | O26: [단위:리터/원]
B27: 유종 | C27: 수량 | E27: 단가 | G27: 환산금액 | J27: 유종 | K27: 수량 | M27: 사입단가 | O27: 환산금액
B28: G | C28: 0 | E28: 0 | G28: 0 | J28: G | K28: 0 | M28: 0 | O28: 0
B29: K | C29: =$E$9-$D$23 -> 24174 | E29: =$G$9 -> 1026.2438 | G29: =C29*E29 -> 24808417 | J29: K | O29: =K29*M29 -> 0
B30: D | C30: =$E$10-$L$23 -> 189464 | E30: =$G$10 -> 1464.7286 | G30: =C30*E30 -> 2.7751334e+08 | J30: D | O30: =K30*M30 -> 0
B33: 복 합 단 가
B34: 유종 | C34: 수량 | E34: 금액 | G34: 복 합 단 가
B35: G | C35: 0 | E35: 0 | G35: 0
B36: K | C36: =$C$29+$K$29 -> 24174 | E36: =$G$29+$O$29-K36 -> 24384044 | G36: =E36/C36 -> 1008.6888 | K36: 424372.88 | L36: <<11월, 12월 경질유 인센
B37: D | C37: =$C$30+$K$30 -> 189464 | E37: =$G$30+$O$30 -> 2.7751334e+08 | G37: =E37/C37 -> 1464.7286
B39: 재 고 현 황 | O39: [단위:리터/원]
C40: 전일 | F40: 금일 | N40: 복합단가 | O40: 증감
C41: 재고 | F41: 입고 | H41: 출고 | K41: 마 감 재 고 | M41: 재고율
B42: 휘발유
B43: 등 유 | C43: =SUM($E$9) -> 56174 | F43: =$K$29 -> 0 | H43: =$D$23 -> 32000 | K43: =$C$43-$H$43+$F$43+$O$43 -> 24174 | M43: =SUM($K$43)/$D$9 -> 0.12087 | N43: =$G$36 -> 1008.6888
B44: 경 유 | C44: =SUM($E$10) -> 213464 | F44: =$K$30 -> 0 | H44: =$L$23 -> 24000 | K44: =$C$44-$H$44+$F$44+$O$44 -> 189464 | M44: =SUM($K$44)/D10 -> 0.47366 | N44: =$G$37 -> 1464.7286
G45: 복합단가의 재고수량과 단가는 보관물량 제외니 참고해주세요!

Sheet 0113
B1: ◈ KK저장소 복합단가 운영표 - 신도시저장소
B5: 이 월 재 고 | G5: [단위:리터/원]
B7: 유종 | D7: 탱크용량 | E7: 재고수량 | F7: 재고율 | G7: 단가
C8: G | D8: 0 | E8: 0 | F8: 0 | G8: 0
C9: K | D9: 200000 | E9: =SUM('0105'!$K$43:$L$43) -> 24174 | F9: =SUM(E9)/D9 -> 0.12087 | G9: =SUM('0105'!$N$43) -> 1008.6888
C10: D | D10: 400000 | E10: =SUM('0105'!$K$44:$L$44) -> 189464 | F10: =SUM(E10)/D10 -> 0.47366 | G10: =SUM('0105'!$N$44) -> 1464.7286
B13: 출고내역(K) | G13: [단위:리터/원] | J13: 출고내역(LD) | O13: [단위:리터/원]
B14: 유종 | C14: 일반매출(사내이관 포함) | J14: 유종 | K14: 일반매출(사내이관 포함)
C15: 거래처명 | D15: 수량 | E15: 출고단가 | F15: 재고단가 | G15: 단가차액 | H15: 이익 | K15: 거래처명 | L15: 수량 | M15: 출고단가 | N15: 재고단가 | O15: 단가차액 | P15: 이익
B16: 실내 등유 | C16: 고아농협 | D16: 2400 | F16: =IF(D16="","",(SUM($G$9))) -> 1008.6888 | G16: =IF(D16="","",(SUM(E16)-F16)) -> -1008.6888 | H16: =IF(D16="","",(D16*G16)) -> -2420853.2 | J16: 경유 | N16: =IF(L16="","",($G$10)) | O16: =IF(L16="","",(SUM(M16)-N16)) | P16: =IF(L16="","",(L16*O16))
F17: =IF(D17="","",(SUM($G$9))) | G17: =IF(D17="","",(SUM(E17)-F17)) | H17: =IF(D17="","",(D17*G17)) | N17: =IF(L17="","",($G$10)) | O17: =IF(L17="","",(SUM(M17)-N17)) | P17: =IF(L17="","",(L17*O17))
F18: =IF(D18="","",(SUM($G$9))) | G18: =IF(D18="","",(SUM(E18)-F18)) | H18: =IF(D18="","",(D18*G18)) | N18: =IF(L18="","",($G$10)) | O18: =IF(L18="","",(SUM(M18)-N18)) | P18: =IF(L18="","",(L18*O18))
F19: =IF(D19="","",(SUM($G$9))) | G19: =IF(D19="","",(SUM(E19)-F19)) | H19: =IF(D19="","",(D19*G19)) | N19: =IF(L19="","",($G$10)) | O19: =IF(L19="","",(SUM(M19)-N19)) | P19: =IF(L19="","",(L19*O19))
F20: =IF(D20="","",(SUM($G$9))) | G20: =IF(D20="","",(SUM(E20)-F20)) | H20: =IF(D20="","",(D20*G20)) | N20: =IF(L20="","",($G$10)) | O20: =IF(L20="","",(SUM(M20)-N20)) | P20: =IF(L20="","",(L20*O20))
F21: =IF(D21="","",(SUM($G$9))) | G21: =IF(D21="","",(SUM(E21)-F21)) | H21: =IF(D21="","",(D21*G21)) | N21: =IF(L21="","",($G$10)) | O21: =IF(L21="","",(SUM(M21)-N21)) | P21: =IF(L21="","",(L21*O21))
F22: =IF(D22="","",(SUM($G$9))) | G22: =IF(D22="","",(SUM(E22)-F22)) | H22: =IF(D22="","",(D22*G22)) | N22: =IF(L22="","",($G$10)) | O22: =IF(L22="","",(SUM(M22)-N22)) | P22: =IF(L22="","",(L22*O22))
B23: 소 계 | D23: =SUM(D16:D22) -> 2400 | H23: =SUM(H16:H22) -> -2420853.2 | J23: 소 계 | L23: =SUM(L16:L22) -> 0 | P23: =SUM(P16:P22) -> 0
B26: 마 감 재 고 | G26: [단위:리터/원] | J26: 입 고 내 역 | O26: [단위:리터/원]
B27: 유종 | C27: 수량 | E27: 단가 | G27: 환산금액 | J27: 유종 | K27: 수량 | M27: 사입단가 | O27: 환산금액
B28: G | C28: 0 | E28: 0 | G28: 0 | J28: G | K28: 0 | M28: 0 | O28: 0
B29: K | C29: =$E$9-$D$23 -> 21774 | E29: =$G$9 -> 1008.6888 | G29: =C29*E29 -> 21963191 | J29: K | O29: =K29*M29 -> 0
B30: D | C30: =$E$10-$L$23 -> 189464 | E30: =$G$10 -> 1464.7286 | G30: =C30*E30 -> 2.7751334e+08 | J30: D | O30: =K30*M30 -> 0
B33: 복 합 단 가
B34: 유종 | C34: 수량 | E34: 금액 | G34: 복 합 단 가
B35: G | C35: 0 | E35: 0 | G35: 0
B36: K | C36: =$C$29+$K$29 -> 21774 | E36: =$G$29+$O$29 -> 21963191 | G36: =E36/C36 -> 1008.6888
B37: D | C37: =$C$30+$K$30 -> 189464 | E37: =$G$30+$O$30 -> 2.7751334e+08 | G37: =E37/C37 -> 1464.7286
B39: 재 고 현 황 | O39: [단위:리터/원]
C40: 전일 | F40: 금일 | N40: 복합단가 | O40: 증감
C41: 재고 | F41: 입고 | H41: 출고 | K41: 마 감 재 고 | M41: 재고율
B42: 휘발유
B43: 등 유 | C43: =SUM($E$9) -> 24174 | F43: =$K$29 -> 0 | H43: =$D$23 -> 2400 | K43: =$C$43-$H$43+$F$43+$O$43 -> 21774 | M43: =SUM($K$43)/$D$9 -> 0.10887 | N43: =$G$36 -> 1008.6888
B44: 경 유 | C44: =SUM($E$10) -> 189464 | F44: =$K$30 -> 0 | H44: =$L$23 -> 0 | K44: =$C$44-$H$44+$F$44+$O$44 -> 189464 | M44: =SUM($K$44)/D10 -> 0.47366 | N44: =$G$37 -> 1464.7286
G45: 복합단가의 재고수량과 단가는 보관물량 제외니 참고해주세요!

Sheet 0114
B1: ◈ KK저장소 복합단가 운영표 - 신도시저장소
B5: 이 월 재 고 | G5: [단위:리터/원]
B7: 유종 | D7: 탱크용량 | E7: 재고수량 | F7: 재고율 | G7: 단가
C8: G | D8: 0 | E8: 0 | F8: 0 | G8: 0
C9: K | D9: 200000 | E9: =SUM('0113'!$K$43:$L$43) -> 21774 | F9: =SUM(E9)/D9 -> 0.10887 | G9: =SUM('0113'!$N$43) -> 1008.6888
C10: D | D10: 400000 | E10: =SUM('0113'!$K$44:$L$44) -> 189464 | F10: =SUM(E10)/D10 -> 0.47366 | G10: =SUM('0113'!$N$44) -> 1464.7286
B13: 출고내역(K) | G13: [단위:리터/원] | J13: 출고내역(LD) | O13: [단위:리터/원]
B14: 유종 | C14: 일반매출(사내이관 포함) | J14: 유종 | K14: 일반매출(사내이관 포함)
C15: 거래처명 | D15: 수량 | E15: 출고단가 | F15: 재고단가 | G15: 단가차액 | H15: 이익 | K15: 거래처명 | L15: 수량 | M15: 출고단가 | N15: 재고단가 | O15: 단가차액 | P15: 이익
B16: 실내 등유 | C16: 고아농협 | D16: 5000 | F16: =IF(D16="","",(SUM($G$9))) -> 1008.6888 | G16: =IF(D16="","",(SUM(E16)-F16)) -> -1008.6888 | H16: =IF(D16="","",(D16*G16)) -> -5043444.2 | J16: 경유 | N16: =IF(L16="","",($G$10)) | O16: =IF(L16="","",(SUM(M16)-N16)) | P16: =IF(L16="","",(L16*O16))
F17: =IF(D17="","",(SUM($G$9))) | G17: =IF(D17="","",(SUM(E17)-F17)) | H17: =IF(D17="","",(D17*G17)) | N17: =IF(L17="","",($G$10)) | O17: =IF(L17="","",(SUM(M17)-N17)) | P17: =IF(L17="","",(L17*O17))
F18: =IF(D18="","",(SUM($G$9))) | G18: =IF(D18="","",(SUM(E18)-F18)) | H18: =IF(D18="","",(D18*G18)) | N18: =IF(L18="","",($G$10)) | O18: =IF(L18="","",(SUM(M18)-N18)) | P18: =IF(L18="","",(L18*O18))
F19: =IF(D19="","",(SUM($G$9))) | G19: =IF(D19="","",(SUM(E19)-F19)) | H19: =IF(D19="","",(D19*G19)) | N19: =IF(L19="","",($G$10)) | O19: =IF(L19="","",(SUM(M19)-N19)) | P19: =IF(L19="","",(L19*O19))
F20: =IF(D20="","",(SUM($G$9))) | G20: =IF(D20="","",(SUM(E20)-F20)) | H20: =IF(D20="","",(D20*G20)) | N20: =IF(L20="","",($G$10)) | O20: =IF(L20="","",(SUM(M20)-N20)) | P20: =IF(L20="","",(L20*O20))
F21: =IF(D21="","",(SUM($G$9))) | G21: =IF(D21="","",(SUM(E21)-F21)) | H21: =IF(D21="","",(D21*G21)) | N21: =IF(L21="","",($G$10)) | O21: =IF(L21="","",(SUM(M21)-N21)) | P21: =IF(L21="","",(L21*O21))
F22: =IF(D22="","",(SUM($G$9))) | G22: =IF(D22="","",(SUM(E22)-F22)) | H22: =IF(D22="","",(D22*G22)) | N22: =IF(L22="","",($G$10)) | O22: =IF(L22="","",(SUM(M22)-N22)) | P22: =IF(L22="","",(L22*O22))
B23: 소 계 | D23: =SUM(D16:D22) -> 5000 | H23: =SUM(H16:H22) -> -5043444.2 | J23: 소 계 | L23: =SUM(L16:L22) -> 0 | P23: =SUM(P16:P22) -> 0
B26: 마 감 재 고 | G26: [단위:리터/원] | J26: 입 고 내 역 | O26: [단위:리터/원]
B27: 유종 | C27: 수량 | E27: 단가 | G27: 환산금액 | J27: 유종 | K27: 수량 | M27: 사입단가 | O27: 환산금액
B28: G | C28: 0 | E28: 0 | G28: 0 | J28: G | K28: 0 | M28: 0 | O28: 0
B29: K | C29: =$E$9-$D$23 -> 16774 | E29: =$G$9 -> 1008.6888 | G29: =C29*E29 -> 16919747 | J29: K | O29: =K29*M29 -> 0
B30: D | C30: =$E$10-$L$23 -> 189464 | E30: =$G$10 -> 1464.7286 | G30: =C30*E30 -> 2.7751334e+08 | J30: D | O30: =K30*M30 -> 0
B33: 복 합 단 가
B34: 유종 | C34: 수량 | E34: 금액 | G34: 복 합 단 가
B35: G | C35: 0 | E35: 0 | G35: 0
B36: K | C36: =$C$29+$K$29 -> 16774 | E36: =$G$29+$O$29 -> 16919747 | G36: =E36/C36 -> 1008.6888
B37: D | C37: =$C$30+$K$30 -> 189464 | E37: =$G$30+$O$30 -> 2.7751334e+08 | G37: =E37/C37 -> 1464.7286
B39: 재 고 현 황 | O39: [단위:리터/원]
C40: 전일 | F40: 금일 | N40: 복합단가 | O40: 증감
C41: 재고 | F41: 입고 | H41: 출고 | K41: 마 감 재 고 | M41: 재고율
B42: 휘발유
B43: 등 유 | C43: =SUM($E$9) -> 21774 | F43: =$K$29 -> 0 | H43: =$D$23 -> 5000 | K43: =$C$43-$H$43+$F$43+$O$43 -> 16774 | M43: =SUM($K$43)/$D$9 -> 0.08387 | N43: =$G$36 -> 1008.6888
B44: 경 유 | C44: =SUM($E$10) -> 189464 | F44: =$K$30 -> 0 | H44: =$L$23 -> 0 | K44: =$C$44-$H$44+$F$44+$O$44 -> 189464 | M44: =SUM($K$44)/D10 -> 0.47366 | N44: =$G$37 -> 1464.7286
G45: 복합단가의 재고수량과 단가는 보관물량 제외니 참고해주세요!

Sheet 0115
B1: ◈ KK저장소 복합단가 운영표 - 신도시저장소
B5: 이 월 재 고 | G5: [단위:리터/원]
B7: 유종 | D7: 탱크용량 | E7: 재고수량 | F7: 재고율 | G7: 단가
C8: G | D8: 0 | E8: 0 | F8: 0 | G8: 0
C9: K | D9: 200000 | E9: =SUM('0114'!$K$43:$L$43) -> 16774 | F9: =SUM(E9)/D9 -> 0.08387 | G9: =SUM('0114'!$N$43) -> 1008.6888
C10: D | D10: 400000 | E10: =SUM('0114'!$K$44:$L$44) -> 189464 | F10: =SUM(E10)/D10 -> 0.47366 | G10: =SUM('0114'!$N$44) -> 1464.7286
B13: 출고내역(K) | G13: [단위:리터/원] | J13: 출고내역(LD) | O13: [단위:리터/원]
B14: 유종 | C14: 일반매출(사내이관 포함) | J14: 유종 | K14: 일반매출(사내이관 포함)
C15: 거래처명 | D15: 수량 | E15: 출고단가 | F15: 재고단가 | G15: 단가차액 | H15: 이익 | K15: 거래처명 | L15: 수량 | M15: 출고단가 | N15: 재고단가 | O15: 단가차액 | P15: 이익
B16: 실내 등유 | F16: =IF(D16="","",(SUM($G$9))) | G16: =IF(D16="","",(SUM(E16)-F16)) | H16: =IF(D16="","",(D16*G16)) | J16: 경유 | N16: =IF(L16="","",($G$10)) | O16: =IF(L16="","",(SUM(M16)-N16)) | P16: =IF(L16="","",(L16*O16))
