Workbook

Sheet 1203
B1: ◈ KK저장소 복합단가 운영표 - 침산저장소
B5: 이 월 재 고 | G5: [단위:리터/원]
B7: 유종 | D7: 탱크용량 | E7: 재고수량 | F7: 재고율 | G7: 단가
C8: G | D8: 0 | E8: 0 | F8: 0 | G8: 0
C9: K | D9: 0 | E9: 0 | G9: #DIV/0!
C10: D | D10: 800000 | E10: 135149 | G10: 1457.9272
B13: 출고내역(K) | G13: [단위:리터/원] | J13: 출고내역(LD) | O13: [단위:리터/원]
B14: 유종 | C14: 일반매출(사내이관 포함) | J14: 유종 | K14: 일반매출(사내이관 포함)
C15: 거래처명 | D15: 수량 | E15: 출고단가 | F15: 재고단가 | G15: 단가차액 | H15: 이익 | K15: 거래처명 | L15: 수량 | M15: 출고단가 | N15: 재고단가 | O15: 단가차액 | P15: 이익
B16: 실내 등유 | J16: 경유 | L16: 8000 | N16: 1457.9272 | O16: -1457.9272 | P16: -11663418
B23: 소 계 | D23: 0 | H23: 0 | J23: 소 계 | L23: 8000 | P23: -11663418
B26: 마 감 재 고 | G26: [단위:리터/원] | J26: 입 고 내 역 | O26: [단위:리터/원]
B27: 유종 | C27: 수량 | E27: 단가 | G27: 환산금액 | J27: 유종 | K27: 수량 | M27: 사입단가 | O27: 환산금액
B28: G | C28: 0 | E28: 0 | G28: 0 | J28: G | K28: 0 | M28: 0 | O28: 0
B29: K | C29: 0 | E29: #DIV/0! | G29: #DIV/0! | J29: K | O29: 0
B30: D | C30: 127149 | E30: 1457.9272 | G30: 1.8537399e+08 | J30: D | O30: 0
B33: 복 합 단 가
B34: 유종 | C34: 수량 | E34: 금액 | G34: 복 합 단 가
B35: G | C35: 0 | E35: 0 | G35: 0 | R35: 별도 보관물량(국세청 제외)
B36: K | C36: 0 | E36: #DIV/0! | G36: #DIV/0!
B37: D | C37: 127149 | E37: 1.8537399e+08 | G37: 1457.9272
B39: 재 고 현 황 | O39: [단위:리터/원]
C40: 전일 | F40: 금일 | N40: 복합단가 | O40: 증감
C41: 재고 | F41: 입고 | H41: 출고 | K41: 마 감 재 고 | M41: 재고율
B42: 휘발유
B43: 등 유 | C43: 0 | F43: 0 | H43: 0 | K43: 0 | M43: #DIV/0! | N43: #DIV/0!
B44: 경 유 | C44: 135149 | F44: 0 | H44: 8000 | K44: 126264 | M44: 0.15783 | N44: 1457.9272 | O44: -885
G45: 복합단가의 재고수량과 단가는 보관물량 제외니 참고해주세요!

Sheet 1211
B1: ◈ KK저장소 복합단가 운영표 - 침산저장소
B5: 이 월 재 고 | G5: [단위:리터/원]
B7: 유종 | D7: 탱크용량 | E7: 재고수량 | F7: 재고율 | G7: 단가
C8: G | D8: 0 | E8: 0 | F8: 0 | G8: 0
C9: K | D9: 0 | E9: =SUM(#REF!) -> #REF! | G9: =SUM(#REF!) -> #REF!
C10: D | D10: 800000 | E10: =SUM('1203'!K44:L44) -> 126264 | G10: =SUM('1203'!N44) -> 1457.9272
B13: 출고내역(K) | G13: [단위:리터/원] | J13: 출고내역(LD) | O13: [단위:리터/원]
B14: 유종 | C14: 일반매출(사내이관 포함) | J14: 유종 | K14: 일반매출(사내이관 포함)
C15: 거래처명 | D15: 수량 | E15: 출고단가 | F15: 재고단가 | G15: 단가차액 | H15: 이익 | K15: 거래처명 | L15: 수량 | M15: 출고단가 | N15: 재고단가 | O15: 단가차액 | P15: 이익
B16: 실내 등유 | F16: =IF(D16="","",(SUM($G$9))) | G16: =IF(D16="","",(SUM(E16)-F16)) | H16: =IF(D16="","",(D16*G16)) | J16: 경유 | N16: =IF(L16="","",($G$10)) | O16: =IF(L16="","",(SUM(M16)-N16)) | P16: =IF(L16="","",(L16*O16))
F17: =IF(D17="","",(SUM($G$9))) | G17: =IF(D17="","",(SUM(E17)-F17)) | H17: =IF(D17="","",(D17*G17)) | N17: =IF(L17="","",($G$10)) | O17: =IF(L17="","",(SUM(M17)-N17)) | P17: =IF(L17="","",(L17*O17))
F18: =IF(D18="","",(SUM($G$9))) | G18: =IF(D18="","",(SUM(E18)-F18)) | H18: =IF(D18="","",(D18*G18)) | N18: =IF(L18="","",($G$10)) | O18: =IF(L18="","",(SUM(M18)-N18)) | P18: =IF(L18="","",(L18*O18))
F19: =IF(D19="","",(SUM($G$9))) | G19: =IF(D19="","",(SUM(E19)-F19)) | H19: =IF(D19="","",(D19*G19)) | N19: =IF(L19="","",($G$10)) | O19: =IF(L19="","",(SUM(M19)-N19)) | P19: =IF(L19="","",(L19*O19))
F20: =IF(D20="","",(SUM($G$9))) | G20: =IF(D20="","",(SUM(E20)-F20)) | H20: =IF(D20="","",(D20*G20)) | N20: =IF(L20="","",($G$10)) | O20: =IF(L20="","",(SUM(M20)-N20)) | P20: =IF(L20="","",(L20*O20))
F21: =IF(D21="","",(SUM($G$9))) | G21: =IF(D21="","",(SUM(E21)-F21)) | H21: =IF(D21="","",(D21*G21)) | N21: =IF(L21="","",($G$10)) | O21: =IF(L21="","",(SUM(M21)-N21)) | P21: =IF(L21="","",(L21*O21))
F22: =IF(D22="","",(SUM($G$9))) | G22: =IF(D22="","",(SUM(E22)-F22)) | H22: =IF(D22="","",(D22*G22)) | N22: =IF(L22="","",($G$10)) | O22: =IF(L22="","",(SUM(M22)-N22)) | P22: =IF(L22="","",(L22*O22))
B23: 소 계 | D23: =SUM(D16:D22) -> 0 | H23: =SUM(H16:H22) -> 0 | J23: 소 계 | L23: =SUM(L16:L22) -> 0 | P23: =SUM(P16:P22) -> 0
B26: 마 감 재 고 | G26: [단위:리터/원] | J26: 입 고 내 역 | O26: [단위:리터/원]
B27: 유종 | C27: 수량 | E27: 단가 | G27: 환산금액 | J27: 유종 | K27: 수량 | M27: 사입단가 | O27: 환산금액
B28: G | C28: 0 | E28: 0 | G28: 0 | J28: G | K28: 0 | M28: 0 | O28: 0
B29: K | C29: =$E$9-$D$23 -> #REF! | E29: =$G$9 -> #REF! | G29: =C29*E29 -> #REF! | J29: K | O29: =K29*M29 -> 0
B30: D | C30: =$E$10-$L$23 -> 126264 | E30: =$G$10 -> 1457.9272 | G30: =C30*E30 -> 1.8408372e+08 | J30: D | K30: 60000 | M30: 1453.1 | O30: =K30*M30 -> 87186000
B33: 복 합 단 가
B34: 유종 | C34: 수량 | E34: 금액 | G34: 복 합 단 가
B35: G | C35: 0 | E35: 0 | G35: 0 | R35: 별도 보관물량(국세청 제외)
B36: K | C36: =$C$29+$K$29 -> #REF! | E36: =$G$29+$O$29 -> #REF! | G36: =E36/C36 -> #REF!
B37: D | C37: =$C$30+$K$30 -> 186264 | E37: =$G$30+$O$30-K37 -> 2.7126972e+08 | G37: =E37/C37 -> 1456.3722
B39: 재 고 현 황 | O39: [단위:리터/원]
C40: 전일 | F40: 금일 | N40: 복합단가 | O40: 증감
C41: 재고 | F41: 입고 | H41: 출고 | K41: 마 감 재 고 | M41: 재고율
B42: 휘발유
B43: 등 유 | C43: =SUM($E$9) -> #REF! | F43: =$K$29 -> 0 | H43: =$D$23 -> 0 | K43: =$C$43-$H$43+$F$43+$O$43 -> #REF! | M43: =SUM($K$43)/$D$9 -> #REF! | N43: =$G$36 -> #REF!
B44: 경 유 | C44: =SUM($E$10) -> 126264 | F44: =$K$30 -> 60000 | H44: =$L$23 -> 0 | K44: =$C$44-$H$44+$F$44+$O$44 -> 186264 | M44: =SUM($K$44)/D10 -> 0.23283 | N44: =$G$37 -> 1456.3722
G45: 복합단가의 재고수량과 단가는 보관물량 제외니 참고해주세요!

Sheet 1212
B1: ◈ KK저장소 복합단가 운영표 - 침산저장소
B5: 이 월 재 고 | G5: [단위:리터/원]
B7: 유종 | D7: 탱크용량 | E7: 재고수량 | F7: 재고율 | G7: 단가
C8: G | D8: 0 | E8: 0 | F8: 0 | G8: 0
C9: K | D9: 0 | E9: =SUM(#REF!) -> #REF! | G9: =SUM(#REF!) -> #REF!
C10: D | D10: 800000 | E10: =SUM('1211'!K44:L44) -> 186264 | G10: =SUM('1211'!N44) -> 1456.3722
B13: 출고내역(K) | G13: [단위:리터/원] | J13: 출고내역(LD) | O13: [단위:리터/원]
B14: 유종 | C14: 일반매출(사내이관 포함) | J14: 유종 | K14: 일반매출(사내이관 포함)
C15: 거래처명 | D15: 수량 | E15: 출고단가 | F15: 재고단가 | G15: 단가차액 | H15: 이익 | K15: 거래처명 | L15: 수량 | M15: 출고단가 | N15: 재고단가 | O15: 단가차액 | P15: 이익
B16: 실내 등유 | F16: =IF(D16="","",(SUM($G$9))) | G16: =IF(D16="","",(SUM(E16)-F16)) | H16: =IF(D16="","",(D16*G16)) | J16: 경유 | L16: 3000 | N16: =IF(L16="","",($G$10)) -> 1456.3722 | O16: =IF(L16="","",(SUM(M16)-N16)) -> -1456.3722 | P16: =IF(L16="","",(L16*O16)) -> -4369116.7
F17: =IF(D17="","",(SUM($G$9))) | G17: =IF(D17="","",(SUM(E17)-F17)) | H17: =IF(D17="","",(D17*G17)) | N17: =IF(L17="","",($G$10)) | O17: =IF(L17="","",(SUM(M17)-N17)) | P17: =IF(L17="","",(L17*O17))
F18: =IF(D18="","",(SUM($G$9))) | G18: =IF(D18="","",(SUM(E18)-F18)) | H18: =IF(D18="","",(D18*G18)) | N18: =IF(L18="","",($G$10)) | O18: =IF(L18="","",(SUM(M18)-N18)) | P18: =IF(L18="","",(L18*O18))
F19: =IF(D19="","",(SUM($G$9))) | G19: =IF(D19="","",(SUM(E19)-F19)) | H19: =IF(D19="","",(D19*G19)) | N19: =IF(L19="","",($G$10)) | O19: =IF(L19="","",(SUM(M19)-N19)) | P19: =IF(L19="","",(L19*O19))
F20: =IF(D20="","",(SUM($G$9))) | G20: =IF(D20="","",(SUM(E20)-F20)) | H20: =IF(D20="","",(D20*G20)) | N20: =IF(L20="","",($G$10)) | O20: =IF(L20="","",(SUM(M20)-N20)) | P20: =IF(L20="","",(L20*O20))
F21: =IF(D21="","",(SUM($G$9))) | G21: =IF(D21="","",(SUM(E21)-F21)) | H21: =IF(D21="","",(D21*G21)) | N21: =IF(L21="","",($G$10)) | O21: =IF(L21="","",(SUM(M21)-N21)) | P21: =IF(L21="","",(L21*O21))
F22: =IF(D22="","",(SUM($G$9))) | G22: =IF(D22="","",(SUM(E22)-F22)) | H22: =IF(D22="","",(D22*G22)) | N22: =IF(L22="","",($G$10)) | O22: =IF(L22="","",(SUM(M22)-N22)) | P22: =IF(L22="","",(L22*O22))
B23: 소 계 | D23: =SUM(D16:D22) -> 0 | H23: =SUM(H16:H22) -> 0 | J23: 소 계 | L23: =SUM(L16:L22) -> 3000 | P23: =SUM(P16:P22) -> -4369116.7
B26: 마 감 재 고 | G26: [단위:리터/원] | J26: 입 고 내 역 | O26: [단위:리터/원]
B27: 유종 | C27: 수량 | E27: 단가 | G27: 환산금액 | J27: 유종 | K27: 수량 | M27: 사입단가 | O27: 환산금액
B28: G | C28: 0 | E28: 0 | G28: 0 | J28: G | K28: 0 | M28: 0 | O28: 0
B29: K | C29: =$E$9-$D$23 -> #REF! | E29: =$G$9 -> #REF! | G29: =C29*E29 -> #REF! | J29: K | O29: =K29*M29 -> 0
B30: D | C30: =$E$10-$L$23 -> 183264 | E30: =$G$10 -> 1456.3722 | G30: =C30*E30 -> 2.669006e+08 | J30: D | O30: =K30*M30 -> 0
B33: 복 합 단 가
B34: 유종 | C34: 수량 | E34: 금액 | G34: 복 합 단 가
B35: G | C35: 0 | E35: 0 | G35: 0 | R35: 별도 보관물량(국세청 제외)
B36: K | C36: =$C$29+$K$29 -> #REF! | E36: =$G$29+$O$29 -> #REF! | G36: =E36/C36 -> #REF!
B37: D | C37: =$C$30+$K$30 -> 183264 | E37: =$G$30+$O$30-K37 -> 2.669006e+08 | G37: =E37/C37 -> 1456.3722
B39: 재 고 현 황 | O39: [단위:리터/원]
C40: 전일 | F40: 금일 | N40: 복합단가 | O40: 증감
C41: 재고 | F41: 입고 | H41: 출고 | K41: 마 감 재 고 | M41: 재고율
B42: 휘발유
B43: 등 유 | C43: =SUM($E$9) -> #REF! | F43: =$K$29 -> 0 | H43: =$D$23 -> 0 | K43: =$C$43-$H$43+$F$43+$O$43 -> #REF! | M43: =SUM($K$43)/$D$9 -> #REF! | N43: =$G$36 -> #REF!
B44: 경 유 | C44: =SUM($E$10) -> 186264 | F44: =$K$30 -> 0 | H44: =$L$23 -> 3000 | K44: =$C$44-$H$44+$F$44+$O$44 -> 183264 | M44: =SUM($K$44)/D10 -> 0.22908 | N44: =$G$37 -> 1456.3722
G45: 복합단가의 재고수량과 단가는 보관물량 제외니 참고해주세요!

Sheet 1215
B1: ◈ KK저장소 복합단가 운영표 - 침산저장소
B5: 이 월 재 고 | G5: [단위:리터/원]
B7: 유종 | D7: 탱크용량 | E7: 재고수량 | F7: 재고율 | G7: 단가
C8: G | D8: 0 | E8: 0 | F8: 0 | G8: 0
C9: K | D9: 0 | E9: =SUM(#REF!) -> #REF! | G9: =SUM(#REF!) -> #REF!
C10: D | D10: 800000 | E10: =SUM('1212'!K44:L44) -> 183264 | G10: =SUM('1212'!N44) -> 1456.3722
B13: 출고내역(K) | G13: [단위:리터/원] | J13: 출고내역(LD) | O13: [단위:리터/원]
B14: 유종 | C14: 일반매출(사내이관 포함) | J14: 유종 | K14: 일반매출(사내이관 포함)
C15: 거래처명 | D15: 수량 | E15: 출고단가 | F15: 재고단가 | G15: 단가차액 | H15: 이익 | K15: 거래처명 | L15: 수량 | M15: 출고단가 | N15: 재고단가 | O15: 단가차액 | P15: 이익
B16: 실내 등유 | F16: =IF(D16="","",(SUM($G$9))) | G16: =IF(D16="","",(SUM(E16)-F16)) | H16: =IF(D16="","",(D16*G16)) | J16: 경유 | L16: 8000 | N16: =IF(L16="","",($G$10)) -> 1456.3722 | O16: =IF(L16="","",(SUM(M16)-N16)) -> -1456.3722 | P16: =IF(L16="","",(L16*O16)) -> -11650978
F17: =IF(D17="","",(SUM($G$9))) | G17: =IF(D17="","",(SUM(E17)-F17)) | H17: =IF(D17="","",(D17*G17)) | N17: =IF(L17="","",($G$10)) | O17: =IF(L17="","",(SUM(M17)-N17)) | P17: =IF(L17="","",(L17*O17))
F18: =IF(D18="","",(SUM($G$9))) | G18: =IF(D18="","",(SUM(E18)-F18)) | H18: =IF(D18="","",(D18*G18)) | N18: =IF(L18="","",($G$10)) | O18: =IF(L18="","",(SUM(M18)-N18)) | P18: =IF(L18="","",(L18*O18))
F19: =IF(D19="","",(SUM($G$9))) | G19: =IF(D19="","",(SUM(E19)-F19)) | H19: =IF(D19="","",(D19*G19)) | N19: =IF(L19="","",($G$10)) | O19: =IF(L19="","",(SUM(M19)-N19)) | P19: =IF(L19="","",(L19*O19))
F20: =IF(D20="","",(SUM($G$9))) | G20: =IF(D20="","",(SUM(E20)-F20)) | H20: =IF(D20="","",(D20*G20)) | N20: =IF(L20="","",($G$10)) | O20: =IF(L20="","",(SUM(M20)-N20)) | P20: =IF(L20="","",(L20*O20))
F21: =IF(D21="","",(SUM($G$9))) | G21: =IF(D21="","",(SUM(E21)-F21)) | H21: =IF(D21="","",(D21*G21)) | N21: =IF(L21="","",($G$10)) | O21: =IF(L21="","",(SUM(M21)-N21)) | P21: =IF(L21="","",(L21*O21))
F22: =IF(D22="","",(SUM($G$9))) | G22: =IF(D22="","",(SUM(E22)-F22)) | H22: =IF(D22="","",(D22*G22)) | N22: =IF(L22="","",($G$10)) | O22: =IF(L22="","",(SUM(M22)-N22)) | P22: =IF(L22="","",(L22*O22))
B23: 소 계 | D23: =SUM(D16:D22) -> 0 | H23: =SUM(H16:H22) -> 0 | J23: 소 계 | L23: =SUM(L16:L22) -> 8000 | P23: =SUM(P16:P22) -> -11650978
B26: 마 감 재 고 | G26: [단위:리터/원] | J26: 입 고 내 역 | O26: [단위:리터/원]
B27: 유종 | C27: 수량 | E27: 단가 | G27: 환산금액 | J27: 유종 | K27: 수량 | M27: 사입단가 | O27: 환산금액
B28: G | C28: 0 | E28: 0 | G28: 0 | J28: G | K28: 0 | M28: 0 | O28: 0
B29: K | C29: =$E$9-$D$23 -> #REF! | E29: =$G$9 -> #REF! | G29: =C29*E29 -> #REF! | J29: K | O29: =K29*M29 -> 0
B30: D | C30: =$E$10-$L$23 -> 175264 | E30: =$G$10 -> 1456.3722 | G30: =C30*E30 -> 2.5524963e+08 | J30: D | O30: =K30*M30 -> 0
B33: 복 합 단 가
B34: 유종 | C34: 수량 | E34: 금액 | G34: 복 합 단 가
B35: G | C35: 0 | E35: 0 | G35: 0 | R35: 별도 보관물량(국세청 제외)
B36: K | C36: =$C$29+$K$29 -> #REF! | E36: =$G$29+$O$29 -> #REF! | G36: =E36/C36 -> #REF!
B37: D | C37: =$C$30+$K$30 -> 175264 | E37: =$G$30+$O$30-K37 -> 2.5524963e+08 | G37: =E37/C37 -> 1456.3722
B39: 재 고 현 황 | O39: [단위:리터/원]
C40: 전일 | F40: 금일 | N40: 복합단가 | O40: 증감
C41: 재고 | F41: 입고 | H41: 출고 | K41: 마 감 재 고 | M41: 재고율
B42: 휘발유
B43: 등 유 | C43: =SUM($E$9) -> #REF! | F43: =$K$29 -> 0 | H43: =$D$23 -> 0 | K43: =$C$43-$H$43+$F$43+$O$43 -> #REF! | M43: =SUM($K$43)/$D$9 -> #REF! | N43: =$G$36 -> #REF!
B44: 경 유 | C44: =SUM($E$10) -> 183264 | F44: =$K$30 -> 0 | H44: =$L$23 -> 8000 | K44: =$C$44-$H$44+$F$44+$O$44 -> 175264 | M44: =SUM($K$44)/D10 -> 0.21908 | N44: =$G$37 -> 1456.3722
G45: 복합단가의 재고수량과 단가는 보관물량 제외니 참고해주세요!

Sheet 1222
B1: ◈ KK저장소 복합단가 운영표 - 침산저장소
B5: 이 월 재 고 | G5: [단위:리터/원]
B7: 유종 | D7: 탱크용량 | E7: 재고수량 | F7: 재고율 | G7: 단가
C8: G | D8: 0 | E8: 0 | F8: 0 | G8: 0
C9: K | D9: 0 | E9: =SUM(#REF!) -> #REF! | G9: =SUM(#REF!) -> #REF!
C10: D | D10: 800000 | E10: =SUM('1215'!K44:L44) -> 175264 | G10: =SUM('1215'!N44) -> 1456.3722
B13: 출고내역(K) | G13: [단위:리터/원] | J13: 출고내역(LD) | O13: [단위:리터/원]
B14: 유종 | C14: 일반매출(사내이관 포함) | J14: 유종 | K14: 일반매출(사내이관 포함)
C15: 거래처명 | D15: 수량 | E15: 출고단가 | F15: 재고단가 | G15: 단가차액 | H15: 이익 | K15: 거래처명 | L15: 수량 | M15: 출고단가 | N15: 재고단가 | O15: 단가차액 | P15: 이익
B16: 실내 등유 | F16: =IF(D16="","",(SUM($G$9))) | G16: =IF(D16="","",(SUM(E16)-F16)) | H16: =IF(D16="","",(D16*G16)) | J16: 경유 | K16: 새양개발 | L16: 8000 | N16: =IF(L16="","",($G$10)) -> 1456.3722 | O16: =IF(L16="","",(SUM(M16)-N16)) -> -1456.3722 | P16: =IF(L16="","",(L16*O16)) -> -11650978
F17: =IF(D17="","",(SUM($G$9))) | G17: =IF(D17="","",(SUM(E17)-F17)) | H17: =IF(D17="","",(D17*G17)) | N17: =IF(L17="","",($G$10)) | O17: =IF(L17="","",(SUM(M17)-N17)) | P17: =IF(L17="","",(L17*O17))
F18: =IF(D18="","",(SUM($G$9))) | G18: =IF(D18="","",(SUM(E18)-F18)) | H18: =IF(D18="","",(D18*G18)) | N18: =IF(L18="","",($G$10)) | O18: =IF(L18="","",(SUM(M18)-N18)) | P18: =IF(L18="","",(L18*O18))
F19: =IF(D19="","",(SUM($G$9))) | G19: =IF(D19="","",(SUM(E19)-F19)) | H19: =IF(D19="","",(D19*G19)) | N19: =IF(L19="","",($G$10)) | O19: =IF(L19="","",(SUM(M19)-N19)) | P19: =IF(L19="","",(L19*O19))
F20: =IF(D20="","",(SUM($G$9))) | G20: =IF(D20="","",(SUM(E20)-F20)) | H20: =IF(D20="","",(D20*G20)) | N20: =IF(L20="","",($G$10)) | O20: =IF(L20="","",(SUM(M20)-N20)) | P20: =IF(L20="","",(L20*O20))
F21: =IF(D21="","",(SUM($G$9))) | G21: =IF(D21="","",(SUM(E21)-F21)) | H21: =IF(D21="","",(D21*G21)) | N21: =IF(L21="","",($G$10)) | O21: =IF(L21="","",(SUM(M21)-N21)) | P21: =IF(L21="","",(L21*O21))
F22: =IF(D22="","",(SUM($G$9))) | G22: =IF(D22="","",(SUM(E22)-F22)) | H22: =IF(D22="","",(D22*G22)) | N22: =IF(L22="","",($G$10)) | O22: =IF(L22="","",(SUM(M22)-N22)) | P22: =IF(L22="","",(L22*O22))
B23: 소 계 | D23: =SUM(D16:D22) -> 0 | H23: =SUM(H16:H22) -> 0 | J23: 소 계 | L23: =SUM(L16:L22) -> 8000 | P23: =SUM(P16:P22) -> -11650978
B26: 마 감 재 고 | G26: [단위:리터/원] | J26: 입 고 내 역 | O26: [단위:리터/원]
B27: 유종 | C27: 수량 | E27: 단가 | G27: 환산금액 | J27: 유종 | K27: 수량 | M27: 사입단가 | O27: 환산금액
B28: G | C28: 0 | E28: 0 | G28: 0 | J28: G | K28: 0 | M28: 0 | O28: 0
B29: K | C29: =$E$9-$D$23 -> #REF! | E29: =$G$9 -> #REF! | G29: =C29*E29 -> #REF! | J29: K | O29: =K29*M29 -> 0
B30: D | C30: =$E$10-$L$23 -> 167264 | E30: =$G$10 -> 1456.3722 | G30: =C30*E30 -> 2.4359865e+08 | J30: D | O30: =K30*M30 -> 0
B33: 복 합 단 가
B34: 유종 | C34: 수량 | E34: 금액 | G34: 복 합 단 가
B35: G | C35: 0 | E35: 0 | G35: 0 | R35: 별도 보관물량(국세청 제외)
B36: K | C36: =$C$29+$K$29 -> #REF! | E36: =$G$29+$O$29 -> #REF! | G36: =E36/C36 -> #REF!
B37: D | C37: =$C$30+$K$30 -> 167264 | E37: =$G$30+$O$30-K37 -> 2.4359865e+08 | G37: =E37/C37 -> 1456.3722
B39: 재 고 현 황 | O39: [단위:리터/원]
C40: 전일 | F40: 금일 | N40: 복합단가 | O40: 증감
C41: 재고 | F41: 입고 | H41: 출고 | K41: 마 감 재 고 | M41: 재고율
B42: 휘발유
B43: 등 유 | C43: =SUM($E$9) -> #REF! | F43: =$K$29 -> 0 | H43: =$D$23 -> 0 | K43: =$C$43-$H$43+$F$43+$O$43 -> #REF! | M43: =SUM($K$43)/$D$9 -> #REF! | N43: =$G$36 -> #REF!
B44: 경 유 | C44: =SUM($E$10) -> 175264 | F44: =$K$30 -> 0 | H44: =$L$23 -> 8000 | K44: =$C$44-$H$44+$F$44+$O$44 -> 167264 | M44: =SUM($K$44)/D10 -> 0.20908 | N44: =$G$37 -> 1456.3722
G45: 복합단가의 재고수량과 단가는 보관물량 제외니 참고해주세요!

Sheet 1224
B1: ◈ KK저장소 복합단가 운영표 - 침산저장소
B5: 이 월 재 고 | G5: [단위:리터/원]
B7: 유종 | D7: 탱크용량 | E7: 재고수량 | F7: 재고율 | G7: 단가
C8: G | D8: 0 | E8: 0 | F8: 0 | G8: 0
C9: K | D9: 0 | E9: =SUM(#REF!) -> #REF! | G9: =SUM(#REF!) -> #REF!
C10: D | D10: 800000 | E10: =SUM('1222'!K44:L44) -> 167264 | G10: =SUM('1222'!N44) -> 1456.3722
B13: 출고내역(K) | G13: [단위:리터/원] | J13: 출고내역(LD) | O13: [단위:리터/원]
B14: 유종 | C14: 일반매출(사내이관 포함) | J14: 유종 | K14: 일반매출(사내이관 포함)
C15: 거래처명 | D15: 수량 | E15: 출고단가 | F15: 재고단가 | G15: 단가차액 | H15: 이익 | K15: 거래처명 | L15: 수량 | M15: 출고단가 | N15: 재고단가 | O15: 단가차액 | P15: 이익
B16: 실내 등유 | F16: =IF(D16="","",(SUM($G$9))) | G16: =IF(D16="","",(SUM(E16)-F16)) | H16: =IF(D16="","",(D16*G16)) | J16: 경유 | N16: =IF(L16="","",($G$10)) | O16: =IF(L16="","",(SUM(M16)-N16)) | P16: =IF(L16="","",(L16*O16))
F17: =IF(D17="","",(SUM($G$9))) | G17: =IF(D17="","",(SUM(E17)-F17)) | H17: =IF(D17="","",(D17*G17)) | N17: =IF(L17="","",($G$10)) | O17: =IF(L17="","",(SUM(M17)-N17)) | P17: =IF(L17="","",(L17*O17))
F18: =IF(D18="","",(SUM($G$9))) | G18: =IF(D18="","",(SUM(E18)-F18)) | H18: =IF(D18="","",(D18*G18)) | N18: =IF(L18="","",($G$10)) | O18: =IF(L18="","",(SUM(M18)-N18)) | P18: =IF(L18="","",(L18*O18))
F19: =IF(D19="","",(SUM($G$9))) | G19: =IF(D19="","",(SUM(E19)-F19)) | H19: =IF(D19="","",(D19*G19)) | N19: =IF(L19="","",($G$10)) | O19: =IF(L19="","",(SUM(M19)-N19)) | P19: =IF(L19="","",(L19*O19))
F20: =IF(D20="","",(SUM($G$9))) | G20: =IF(D20="","",(SUM(E20)-F20)) | H20: =IF(D20="","",(D20*G20)) | N20: =IF(L20="","",($G$10)) | O20: =IF(L20="","",(SUM(M20)-N20)) | P20: =IF(L20="","",(L20*O20))
F21: =IF(D21="","",(SUM($G$9))) | G21: =IF(D21="","",(SUM(E21)-F21)) | H21: =IF(D21="","",(D21*G21)) | N21: =IF(L21="","",($G$10)) | O21: =IF(L21="","",(SUM(M21)-N21)) | P21: =IF(L21="","",(L21*O21))
F22: =IF(D22="","",(SUM($G$9))) | G22: =IF(D22="","",(SUM(E22)-F22)) | H22: =IF(D22="","",(D22*G22)) | N22: =IF(L22="","",($G$10)) | O22: =IF(L22="","",(SUM(M22)-N22)) | P22: =IF(L22="","",(L22*O22))
B23: 소 계 | D23: =SUM(D16:D22) -> 0 | H23: =SUM(H16:H22) -> 0 | J23: 소 계 | L23: =SUM(L16:L22) -> 0 | P23: =SUM(P16:P22) -> 0
B26: 마 감 재 고 | G26: [단위:리터/원] | J26: 입 고 내 역 | O26: [단위:리터/원]
B27: 유종 | C27: 수량 | E27: 단가 | G27: 환산금액 | J27: 유종 | K27: 수량 | M27: 사입단가 | O27: 환산금액
B28: G | C28: 0 | E28: 0 | G28: 0 | J28: G | K28: 0 | M28: 0 | O28: 0
B29: K | C29: =$E$9-$D$23 -> #REF! | E29: =$G$9 -> #REF! | G29: =C29*E29 -> #REF! | J29: K | O29: =K29*M29 -> 0
B30: D | C30: =$E$10-$L$23 -> 167264 | E30: =$G$10 -> 1456.3722 | G30: =C30*E30 -> 2.4359865e+08 | J30: D | O30: =K30*M30 -> 0
B33: 복 합 단 가
B34: 유종 | C34: 수량 | E34: 금액 | G34: 복 합 단 가
B35: G | C35: 0 | E35: 0 | G35: 0 | R35: 별도 보관물량(국세청 제외)
B36: K | C36: =$C$29+$K$29 -> #REF! | E36: =$G$29+$O$29 -> #REF! | G36: =E36/C36 -> #REF! | R36: 46015
B37: D | C37: =$C$30+$K$30 -> 167264 | E37: =$G$30+$O$30-K37 -> 2.4359865e+08 | G37: =E37/C37 -> 1456.3722 | R37: 신광
R38: 28137
B39: 재 고 현 황 | O39: [단위:리터/원] | R39: 1대
C40: 전일 | F40: 금일 | N40: 복합단가 | O40: 증감 | R40: 1452.1
C41: 재고 | F41: 입고 | H41: 출고 | K41: 마 감 재 고 | M41: 재고율
B42: 휘발유
B43: 등 유 | C43: =SUM($E$9) -> #REF! | F43: =$K$29 -> 0 | H43: =$D$23 -> 0 | K43: =$C$43-$H$43+$F$43+$O$43 -> #REF! | M43: =SUM($K$43)/$D$9 -> #REF! | N43: =$G$36 -> #REF!
B44: 경 유 | C44: =SUM($E$10) -> 167264 | F44: =$K$30 -> 0 | H44: =$L$23 -> 0 | K44: =$C$44-$H$44+$F$44+$O$44 -> 167264 | M44: =SUM($K$44)/D10 -> 0.20908 | N44: =$G$37 -> 1456.3722
G45: 복합단가의 재고수량과 단가는 보관물량 제외니 참고해주세요!

Sheet 1226
B1: ◈ KK저장소 복합단가 운영표 - 침산저장소
B5: 이 월 재 고 | G5: [단위:리터/원]
B7: 유종 | D7: 탱크용량 | E7: 재고수량 | F7: 재고율 | G7: 단가
C8: G | D8: 0 | E8: 0 | F8: 0 | G8: 0
C9: K | D9: 0 | E9: =SUM(#REF!) -> #REF! | G9: =SUM(#REF!) -> #REF!
C10: D | D10: 800000 | E10: =SUM('1224'!K44:L44) -> 167264 | G10: =SUM('1224'!N44) -> 1456.3722
B13: 출고내역(K) | G13: [단위:리터/원] | J13: 출고내역(LD) | O13: [단위:리터/원]
B14: 유종 | C14: 일반매출(사내이관 포함) | J14: 유종 | K14: 일반매출(사내이관 포함)
C15: 거래처명 | D15: 수량 | E15: 출고단가 | F15: 재고단가 | G15: 단가차액 | H15: 이익 | K15: 거래처명 | L15: 수량 | M15: 출고단가 | N15: 재고단가 | O15: 단가차액 | P15: 이익
B16: 실내 등유 | F16: =IF(D16="","",(SUM($G$9))) | G16: =IF(D16="","",(SUM(E16)-F16)) | H16: =IF(D16="","",(D16*G16)) | J16: 경유 | N16: =IF(L16="","",($G$10)) | O16: =IF(L16="","",(SUM(M16)-N16)) | P16: =IF(L16="","",(L16*O16))
F17: =IF(D17="","",(SUM($G$9))) | G17: =IF(D17="","",(SUM(E17)-F17)) | H17: =IF(D17="","",(D17*G17)) | N17: =IF(L17="","",($G$10)) | O17: =IF(L17="","",(SUM(M17)-N17)) | P17: =IF(L17="","",(L17*O17))
F18: =IF(D18="","",(SUM($G$9))) | G18: =IF(D18="","",(SUM(E18)-F18)) | H18: =IF(D18="","",(D18*G18)) | N18: =IF(L18="","",($G$10)) | O18: =IF(L18="","",(SUM(M18)-N18)) | P18: =IF(L18="","",(L18*O18))
F19: =IF(D19="","",(SUM($G$9))) | G19: =IF(D19="","",(SUM(E19)-F19)) | H19: =IF(D19="","",(D19*G19)) | N19: =IF(L19="","",($G$10)) | O19: =IF(L19="","",(SUM(M19)-N19)) | P19: =IF(L19="","",(L19*O19))
F20: =IF(D20="","",(SUM($G$9))) | G20: =IF(D20="","",(SUM(E20)-F20)) | H20: =IF(D20="","",(D20*G20)) | N20: =IF(L20="","",($G$10)) | O20: =IF(L20="","",(SUM(M20)-N20)) | P20: =IF(L20="","",(L20*O20))
F21: =IF(D21="","",(SUM($G$9))) | G21: =IF(D21="","",(SUM(E21)-F21)) | H21: =IF(D21="","",(D21*G21)) | N21: =IF(L21="","",($G$10)) | O21: =IF(L21="","",(SUM(M21)-N21)) | P21: =IF(L21="","",(L21*O21))
F22: =IF(D22="","",(SUM($G$9))) | G22: =IF(D22="","",(SUM(E22)-F22)) | H22: =IF(D22="","",(D22*G22)) | N22: =IF(L22="","",($G$10)) | O22: =IF(L22="","",(SUM(M22)-N22)) | P22: =IF(L22="","",(L22*O22))
B23: 소 계 | D23: =SUM(D16:D22) -> 0 | H23: =SUM(H16:H22) -> 0 | J23: 소 계 | L23: =SUM(L16:L22) -> 0 | P23: =SUM(P16:P22) -> 0
B26: 마 감 재 고 | G26: [단위:리터/원] | J26: 입 고 내 역 | O26: [단위:리터/원]
B27: 유종 | C27: 수량 | E27: 단가 | G27: 환산금액 | J27: 유종 | K27: 수량 | M27: 사입단가 | O27: 환산금액
B28: G | C28: 0 | E28: 0 | G28: 0 | J28: G | K28: 0 | M28: 0 | O28: 0
B29: K | C29: =$E$9-$D$23 -> #REF! | E29: =$G$9 -> #REF! | G29: =C29*E29 -> #REF! | J29: K | O29: =K29*M29 -> 0
B30: D | C30: =$E$10-$L$23 -> 167264 | E30: =$G$10 -> 1456.3722 | G30: =C30*E30 -> 2.4359865e+08 | J30: D | K30: 161037 | M30: 1449.1 | O30: =K30*M30 -> 2.3335872e+08
B33: 복 합 단 가
B34: 유종 | C34: 수량 | E34: 금액 | G34: 복 합 단 가
B35: G | C35: 0 | E35: 0 | G35: 0 | R35: 별도 보관물량(국세청 제외)
B36: K | C36: =$C$29+$K$29 -> #REF! | E36: =$G$29+$O$29 -> #REF! | G36: =E36/C36 -> #REF! | R36: 46015 | T36: 46017
B37: D | C37: =$C$30+$K$30 -> 328301 | E37: =$G$30+$O$30-K37 -> 4.7695736e+08 | G37: =E37/C37 -> 1452.8051 | R37: 신광 | T37: 신광
R38: 28137 | T38: 112719
B39: 재 고 현 황 | O39: [단위:리터/원] | R39: 1대 | T39: 4대
C40: 전일 | F40: 금일 | N40: 복합단가 | O40: 증감 | R40: 1452.1 | T40: 1452.1
C41: 재고 | F41: 입고 | H41: 출고 | K41: 마 감 재 고 | M41: 재고율
B42: 휘발유 | T42: =+T38+K30 -> 273756
B43: 등 유 | C43: =SUM($E$9) -> #REF! | F43: =$K$29 -> 0 | H43: =$D$23 -> 0 | K43: =$C$43-$H$43+$F$43+$O$43 -> #REF! | M43: =SUM($K$43)/$D$9 -> #REF! | N43: =$G$36 -> #REF!
B44: 경 유 | C44: =SUM($E$10) -> 167264 | F44: =$K$30 -> 161037 | H44: =$L$23 -> 0 | K44: =$C$44-$H$44+$F$44+$O$44 -> 328301 | M44: =SUM($K$44)/D10 -> 0.41037625 | N44: =$G$37 -> 1452.8051
G45: 복합단가의 재고수량과 단가는 보관물량 제외니 참고해주세요!

Sheet 1229
B1: ◈ KK저장소 복합단가 운영표 - 침산저장소
B5: 이 월 재 고 | G5: [단위:리터/원]
B7: 유종 | D7: 탱크용량 | E7: 재고수량 | F7: 재고율 | G7: 단가
C8: G | D8: 0 | E8: 0 | F8: 0 | G8: 0
C9: K | D9: 0 | E9: =SUM(#REF!) -> #REF! | G9: =SUM(#REF!) -> #REF!
C10: D | D10: 800000 | E10: =SUM('1226'!K44:L44) -> 328301 | G10: =SUM('1226'!N44) -> 1452.8051
B13: 출고내역(K) | G13: [단위:리터/원] | J13: 출고내역(LD) | O13: [단위:리터/원]
B14: 유종 | C14: 일반매출(사내이관 포함) | J14: 유종 | K14: 일반매출(사내이관 포함)
C15: 거래처명 | D15: 수량 | E15: 출고단가 | F15: 재고단가 | G15: 단가차액 | H15: 이익 | K15: 거래처명 | L15: 수량 | M15: 출고단가 | N15: 재고단가 | O15: 단가차액 | P15: 이익
B16: 실내 등유 | F16: =IF(D16="","",(SUM($G$9))) | G16: =IF(D16="","",(SUM(E16)-F16)) | H16: =IF(D16="","",(D16*G16)) | J16: 경유 | N16: =IF(L16="","",($G$10)) | O16: =IF(L16="","",(SUM(M16)-N16)) | P16: =IF(L16="","",(L16*O16))
F17: =IF(D17="","",(SUM($G$9))) | G17: =IF(D17="","",(SUM(E17)-F17)) | H17: =IF(D17="","",(D17*G17)) | N17: =IF(L17="","",($G$10)) | O17: =IF(L17="","",(SUM(M17)-N17)) | P17: =IF(L17="","",(L17*O17))
F18: =IF(D18="","",(SUM($G$9))) | G18: =IF(D18="","",(SUM(E18)-F18)) | H18: =IF(D18="","",(D18*G18)) | N18: =IF(L18="","",($G$10)) | O18: =IF(L18="","",(SUM(M18)-N18)) | P18: =IF(L18="","",(L18*O18))
F19: =IF(D19="","",(SUM($G$9))) | G19: =IF(D19="","",(SUM(E19)-F19)) | H19: =IF(D19="","",(D19*G19)) | N19: =IF(L19="","",($G$10)) | O19: =IF(L19="","",(SUM(M19)-N19)) | P19: =IF(L19="","",(L19*O19))
F20: =IF(D20="","",(SUM($G$9))) | G20: =IF(D20="","",(SUM(E20)-F20)) | H20: =IF(D20="","",(D20*G20)) | N20: =IF(L20="","",($G$10)) | O20: =IF(L20="","",(SUM(M20)-N20)) | P20: =IF(L20="","",(L20*O20))
F21: =IF(D21="","",(SUM($G$9))) | G21: =IF(D21="","",(SUM(E21)-F21)) | H21: =IF(D21="","",(D21*G21)) | N21: =IF(L21="","",($G$10)) | O21: =IF(L21="","",(SUM(M21)-N21)) | P21: =IF(L21="","",(L21*O21))
F22: =IF(D22="","",(SUM($G$9))) | G22: =IF(D22="","",(SUM(E22)-F22)) | H22: =IF(D22="","",(D22*G22)) | N22: =IF(L22="","",($G$10)) | O22: =IF(L22="","",(SUM(M22)-N22)) | P22: =IF(L22="","",(L22*O22))
B23: 소 계 | D23: =SUM(D16:D22) -> 0 | H23: =SUM(H16:H22) -> 0 | J23: 소 계 | L23: =SUM(L16:L22) -> 0 | P23: =SUM(P16:P22) -> 0
B26: 마 감 재 고 | G26: [단위:리터/원] | J26: 입 고 내 역 | O26: [단위:리터/원]
B27: 유종 | C27: 수량 | E27: 단가 | G27: 환산금액 | J27: 유종 | K27: 수량 | M27: 사입단가 | O27: 환산금액
B28: G | C28: 0 | E28: 0 | G28: 0 | J28: G | K28: 0 | M28: 0 | O28: 0
B29: K | C29: =$E$9-$D$23 -> #REF! | E29: =$G$9 -> #REF! | G29: =C29*E29 -> #REF! | J29: K | O29: =K29*M29 -> 0
B30: D | C30: =$E$10-$L$23 -> 328301 | E30: =$G$10 -> 1452.8051 | G30: =C30*E30 -> 4.7695736e+08 | J30: D | K30: 112795 | M30: 1424.3224 | O30: =K30*M30 -> 1.6065644e+08
B33: 복 합 단 가
B34: 유종 | C34: 수량 | E34: 금액 | G34: 복 합 단 가
B35: G | C35: 0 | E35: 0 | G35: 0 | R35: 별도 보관물량(국세청 제외)
B36: K | C36: =$C$29+$K$29 -> #REF! | E36: =$G$29+$O$29 -> #REF! | G36: =E36/C36 -> #REF! | R36: 46015 | T36: 46017
B37: D | C37: =$C$30+$K$30 -> 441096 | E37: =$G$30+$O$30-K37 -> 6.376138e+08 | G37: =E37/C37 -> 1445.5216 | R37: 신광 | T37: 신광
R38: 28137 | T38: 112719
B39: 재 고 현 황 | O39: [단위:리터/원] | R39: 1대 | T39: 4대
C40: 전일 | F40: 금일 | N40: 복합단가 | O40: 증감
C41: 재고 | F41: 입고 | H41: 출고 | K41: 마 감 재 고 | M41: 재고율
B42: 휘발유
B43: 등 유 | C43: =SUM($E$9) -> #REF! | F43: =$K$29 -> 0 | H43: =$D$23 -> 0 | K43: =$C$43-$H$43+$F$43+$O$43 -> #REF! | M43: =SUM($K$43)/$D$9 -> #REF! | N43: =$G$36 -> #REF!
B44: 경 유 | C44: =SUM($E$10) -> 328301 | F44: =$K$30 -> 112795 | H44: =$L$23 -> 0 | K44: =$C$44-$H$44+$F$44+$O$44 -> 441096 | M44: =SUM($K$44)/D10 -> 0.55137 | N44: =$G$37 -> 1445.5216
G45: 복합단가의 재고수량과 단가는 보관물량 제외니 참고해주세요!

Sheet 1231
B1: ◈ KK저장소 복합단가 운영표 - 침산저장소
B5: 이 월 재 고 | G5: [단위:리터/원]
B7: 유종 | D7: 탱크용량 | E7: 재고수량 | F7: 재고율 | G7: 단가
C8: G | D8: 0 | E8: 0 | F8: 0 | G8: 0
C9: K | D9: 0 | E9: =SUM(#REF!) -> #REF! | G9: =SUM(#REF!) -> #REF!
C10: D | D10: 800000 | E10: =SUM('1229'!K44:L44) -> 441096 | G10: =SUM('1229'!N44) -> 1445.5216
B13: 출고내역(K) | G13: [단위:리터/원] | J13: 출고내역(LD) | O13: [단위:리터/원]
B14: 유종 | C14: 일반매출(사내이관 포함) | J14: 유종 | K14: 일반매출(사내이관 포함)
C15: 거래처명 | D15: 수량 | E15: 출고단가 | F15: 재고단가 | G15: 단가차액 | H15: 이익 | K15: 거래처명 | L15: 수량 | M15: 출고단가 | N15: 재고단가 | O15: 단가차액 | P15: 이익
B16: 실내 등유 | F16: =IF(D16="","",(SUM($G$9))) | G16: =IF(D16="","",(SUM(E16)-F16)) | H16: =IF(D16="","",(D16*G16)) | J16: 경유 | K16: 성서고속 | L16: 28000 | N16: =IF(L16="","",($G$10)) -> 1445.5216 | O16: =IF(L16="","",(SUM(M16)-N16)) -> -1445.5216 | P16: =IF(L16="","",(L16*O16)) -> -40474605
F17: =IF(D17="","",(SUM($G$9))) | G17: =IF(D17="","",(SUM(E17)-F17)) | H17: =IF(D17="","",(D17*G17)) | K17: 보관출고증감 | L17: 1054 | N17: =IF(L17="","",($G$10)) -> 1445.5216 | O17: =IF(L17="","",(SUM(M17)-N17)) -> -1445.5216 | P17: =IF(L17="","",(L17*O17)) -> -1523579.8
F18: =IF(D18="","",(SUM($G$9))) | G18: =IF(D18="","",(SUM(E18)-F18)) | H18: =IF(D18="","",(D18*G18)) | N18: =IF(L18="","",($G$10)) | O18: =IF(L18="","",(SUM(M18)-N18)) | P18: =IF(L18="","",(L18*O18))
F19: =IF(D19="","",(SUM($G$9))) | G19: =IF(D19="","",(SUM(E19)-F19)) | H19: =IF(D19="","",(D19*G19)) | N19: =IF(L19="","",($G$10)) | O19: =IF(L19="","",(SUM(M19)-N19)) | P19: =IF(L19="","",(L19*O19))
F20: =IF(D20="","",(SUM($G$9))) | G20: =IF(D20="","",(SUM(E20)-F20)) | H20: =IF(D20="","",(D20*G20)) | N20: =IF(L20="","",($G$10)) | O20: =IF(L20="","",(SUM(M20)-N20)) | P20: =IF(L20="","",(L20*O20))
F21: =IF(D21="","",(SUM($G$9))) | G21: =IF(D21="","",(SUM(E21)-F21)) | H21: =IF(D21="","",(D21*G21)) | N21: =IF(L21="","",($G$10)) | O21: =IF(L21="","",(SUM(M21)-N21)) | P21: =IF(L21="","",(L21*O21))
F22: =IF(D22="","",(SUM($G$9))) | G22: =IF(D22="","",(SUM(E22)-F22)) | H22: =IF(D22="","",(D22*G22)) | N22: =IF(L22="","",($G$10)) | O22: =IF(L22="","",(SUM(M22)-N22)) | P22: =IF(L22="","",(L22*O22))
B23: 소 계 | D23: =SUM(D16:D22) -> 0 | H23: =SUM(H16:H22) -> 0 | J23: 소 계 | L23: =SUM(L16:L22) -> 29054 | P23: =SUM(P16:P22) -> -41998185
B26: 마 감 재 고 | G26: [단위:리터/원] | J26: 입 고 내 역 | O26: [단위:리터/원]
B27: 유종 | C27: 수량 | E27: 단가 | G27: 환산금액 | J27: 유종 | K27: 수량 | M27: 사입단가 | O27: 환산금액
B28: G | C28: 0 | E28: 0 | G28: 0 | J28: G | K28: 0 | M28: 0 | O28: 0
B29: K | C29: =$E$9-$D$23 -> #REF! | E29: =$G$9 -> #REF! | G29: =C29*E29 -> #REF! | J29: K | O29: =K29*M29 -> 0
B30: D | C30: =$E$10-$L$23 -> 412042 | E30: =$G$10 -> 1445.5216 | G30: =C30*E30 -> 5.9561562e+08 | J30: D | O30: =K30*M30 -> 0
B33: 복 합 단 가
B34: 유종 | C34: 수량 | E34: 금액 | G34: 복 합 단 가
B35: G | C35: 0 | E35: 0 | G35: 0 | R35: 별도 보관물량(국세청 제외)
B36: K | C36: =$C$29+$K$29 -> #REF! | E36: =$G$29+$O$29 -> #REF! | G36: =E36/C36 -> #REF! | T36: 46017
B37: D | C37: =$C$30+$K$30 -> 412042 | E37: =$G$30+$O$30-K37 -> 5.9561562e+08 | G37: =E37/C37 -> 1445.5216 | T37: 신광
T38: =112719-28000+137 -> 84856
B39: 재 고 현 황 | O39: [단위:리터/원] | T39: 3대
C40: 전일 | F40: 금일 | N40: 복합단가 | O40: 증감 | Q40: 46387 | R40: 신광 56천 | S40: 2대출고
C41: 재고 | F41: 입고 | H41: 출고 | K41: 마 감 재 고 | M41: 재고율
B42: 휘발유
B43: 등 유 | C43: =SUM($E$9) -> #REF! | F43: =$K$29 -> 0 | H43: =$D$23 -> 0 | K43: =$C$43-$H$43+$F$43+$O$43 -> #REF! | M43: =SUM($K$43)/$D$9 -> #REF! | N43: =$G$36 -> #REF!
B44: 경 유 | C44: =SUM($E$10) -> 441096 | F44: =$K$30 -> 0 | H44: =$L$23 -> 29054 | K44: =$C$44-$H$44+$F$44+$O$44 -> 412042 | M44: =SUM($K$44)/D10 -> 0.5150525 | N44: =$G$37 -> 1445.5216
G45: 복합단가의 재고수량과 단가는 보관물량 제외니 참고해주세요!

Sheet 0102
B1: ◈ KK저장소 복합단가 운영표 - 침산저장소
B5: 이 월 재 고 | G5: [단위:리터/원]
B7: 유종 | D7: 탱크용량 | E7: 재고수량 | F7: 재고율 | G7: 단가
C8: G | D8: 0 | E8: 0 | F8: 0 | G8: 0
C9: K | D9: 0 | E9: =SUM(#REF!) -> #REF! | G9: =SUM(#REF!) -> #REF!
C10: D | D10: 800000 | E10: =SUM('1231'!K44:L44) -> 412042 | G10: =SUM('1231'!N44) -> 1445.5216
B13: 출고내역(K) | G13: [단위:리터/원] | J13: 출고내역(LD) | O13: [단위:리터/원]
B14: 유종 | C14: 일반매출(사내이관 포함) | J14: 유종 | K14: 일반매출(사내이관 포함)
C15: 거래처명 | D15: 수량 | E15: 출고단가 | F15: 재고단가 | G15: 단가차액 | H15: 이익 | K15: 거래처명 | L15: 수량 | M15: 출고단가 | N15: 재고단가 | O15: 단가차액 | P15: 이익
B16: 실내 등유 | F16: =IF(D16="","",(SUM($G$9))) | G16: =IF(D16="","",(SUM(E16)-F16)) | H16: =IF(D16="","",(D16*G16)) | J16: 경유 | N16: =IF(L16="","",($G$10)) | O16: =IF(L16="","",(SUM(M16)-N16)) | P16: =IF(L16="","",(L16*O16))
F17: =IF(D17="","",(SUM($G$9))) | G17: =IF(D17="","",(SUM(E17)-F17)) | H17: =IF(D17="","",(D17*G17)) | N17: =IF(L17="","",($G$10)) | O17: =IF(L17="","",(SUM(M17)-N17)) | P17: =IF(L17="","",(L17*O17))
F18: =IF(D18="","",(SUM($G$9))) | G18: =IF(D18="","",(SUM(E18)-F18)) | H18: =IF(D18="","",(D18*G18)) | N18: =IF(L18="","",($G$10)) | O18: =IF(L18="","",(SUM(M18)-N18)) | P18: =IF(L18="","",(L18*O18))
F19: =IF(D19="","",(SUM($G$9))) | G19: =IF(D19="","",(SUM(E19)-F19)) | H19: =IF(D19="","",(D19*G19)) | N19: =IF(L19="","",($G$10)) | O19: =IF(L19="","",(SUM(M19)-N19)) | P19: =IF(L19="","",(L19*O19))
F20: =IF(D20="","",(SUM($G$9))) | G20: =IF(D20="","",(SUM(E20)-F20)) | H20: =IF(D20="","",(D20*G20)) | N20: =IF(L20="","",($G$10)) | O20: =IF(L20="","",(SUM(M20)-N20)) | P20: =IF(L20="","",(L20*O20))
F21: =IF(D21="","",(SUM($G$9))) | G21: =IF(D21="","",(SUM(E21)-F21)) | H21: =IF(D21="","",(D21*G21)) | N21: =IF(L21="","",($G$10)) | O21: =IF(L21="","",(SUM(M21)-N21)) | P21: =IF(L21="","",(L21*O21))
F22: =IF(D22="","",(SUM($G$9))) | G22: =IF(D22="","",(SUM(E22)-F22)) | H22: =IF(D22="","",(D22*G22)) | N22: =IF(L22="","",($G$10)) | O22: =IF(L22="","",(SUM(M22)-N22)) | P22: =IF(L22="","",(L22*O22))
B23: 소 계 | D23: =SUM(D16:D22) -> 0 | H23: =SUM(H16:H22) -> 0 | J23: 소 계 | L23: =SUM(L16:L22) -> 0 | P23: =SUM(P16:P22) -> 0
B26: 마 감 재 고 | G26: [단위:리터/원] | J26: 입 고 내 역 | O26: [단위:리터/원]
B27: 유종 | C27: 수량 | E27: 단가 | G27: 환산금액 | J27: 유종 | K27: 수량 | M27: 사입단가 | O27: 환산금액
B28: G | C28: 0 | E28: 0 | G28: 0 | J28: G | K28: 0 | M28: 0 | O28: 0
B29: K | C29: =$E$9-$D$23 -> #REF! | E29: =$G$9 -> #REF! | G29: =C29*E29 -> #REF! | J29: K | O29: =K29*M29 -> 0
B30: D | C30: =$E$10-$L$23 -> 412042 | E30: =$G$10 -> 1445.5216 | G30: =C30*E30 -> 5.9561562e+08 | J30: D | O30: =K30*M30 -> 0
B33: 복 합 단 가
B34: 유종 | C34: 수량 | E34: 금액 | G34: 복 합 단 가
B35: G | C35: 0 | E35: 0 | G35: 0 | R35: 별도 보관물량(국세청 제외)
B36: K | C36: =$C$29+$K$29 -> #REF! | E36: =$G$29+$O$29 -> #REF! | G36: =E36/C36 -> #REF! | T36: 46017
B37: D | C37: =$C$30+$K$30 -> 412042 | E37: =$G$30+$O$30-K37 -> 5.9494414e+08 | G37: =E37/C37 -> 1443.892 | K37: 671482.37 | L37: <<11월, 12월 경질유인센 | T37: 신광
T38: 56856
B39: 재 고 현 황 | O39: [단위:리터/원] | T39: 2대
C40: 전일 | F40: 금일 | N40: 복합단가 | O40: 증감 | Q40: 12월 31일 | R40: 신광 56천 | S40: 2대출고
C41: 재고 | F41: 입고 | H41: 출고 | K41: 마 감 재 고 | M41: 재고율 | Q41: 01월 02일 | R41: 신광 28천 | S41: 1대출고
B42: 휘발유
B43: 등 유 | C43: =SUM($E$9) -> #REF! | F43: =$K$29 -> 0 | H43: =$D$23 -> 0 | K43: =$C$43-$H$43+$F$43+$O$43 -> #REF! | M43: =SUM($K$43)/$D$9 -> #REF! | N43: =$G$36 -> #REF!
B44: 경 유 | C44: =SUM($E$10) -> 412042 | F44: =$K$30 -> 0 | H44: =$L$23 -> 0 | K44: =$C$44-$H$44+$F$44+$O$44 -> 415560 | M44: =SUM($K$44)/D10 -> 0.51945 | N44: =$G$37 -> 1443.892 | O44: 3518
G45: 복합단가의 재고수량과 단가는 보관물량 제외니 참고해주세요!

Sheet 0105
B1: ◈ KK저장소 복합단가 운영표 - 침산저장소
B5: 이 월 재 고 | G5: [단위:리터/원]
B7: 유종 | D7: 탱크용량 | E7: 재고수량 | F7: 재고율 | G7: 단가
C8: G | D8: 0 | E8: 0 | F8: 0 | G8: 0
C9: K | D9: 0 | E9: =SUM(#REF!) -> #REF! | G9: =SUM(#REF!) -> #REF!
C10: D | D10: 800000 | E10: =SUM('0102'!K44:L44) -> 415560 | G10: =SUM('0102'!N44) -> 1443.892
B13: 출고내역(K) | G13: [단위:리터/원] | J13: 출고내역(LD) | O13: [단위:리터/원]
B14: 유종 | C14: 일반매출(사내이관 포함) | J14: 유종 | K14: 일반매출(사내이관 포함)
C15: 거래처명 | D15: 수량 | E15: 출고단가 | F15: 재고단가 | G15: 단가차액 | H15: 이익 | K15: 거래처명 | L15: 수량 | M15: 출고단가 | N15: 재고단가 | O15: 단가차액 | P15: 이익
B16: 실내 등유 | F16: =IF(D16="","",(SUM($G$9))) | G16: =IF(D16="","",(SUM(E16)-F16)) | H16: =IF(D16="","",(D16*G16)) | J16: 경유 | K16: 세양개발 | L16: 8000 | N16: =IF(L16="","",($G$10)) -> 1443.892 | O16: =IF(L16="","",(SUM(M16)-N16)) -> -1443.892 | P16: =IF(L16="","",(L16*O16)) -> -11551136
F17: =IF(D17="","",(SUM($G$9))) | G17: =IF(D17="","",(SUM(E17)-F17)) | H17: =IF(D17="","",(D17*G17)) | N17: =IF(L17="","",($G$10)) | O17: =IF(L17="","",(SUM(M17)-N17)) | P17: =IF(L17="","",(L17*O17))
F18: =IF(D18="","",(SUM($G$9))) | G18: =IF(D18="","",(SUM(E18)-F18)) | H18: =IF(D18="","",(D18*G18)) | N18: =IF(L18="","",($G$10)) | O18: =IF(L18="","",(SUM(M18)-N18)) | P18: =IF(L18="","",(L18*O18))
F19: =IF(D19="","",(SUM($G$9))) | G19: =IF(D19="","",(SUM(E19)-F19)) | H19: =IF(D19="","",(D19*G19)) | N19: =IF(L19="","",($G$10)) | O19: =IF(L19="","",(SUM(M19)-N19)) | P19: =IF(L19="","",(L19*O19))
F20: =IF(D20="","",(SUM($G$9))) | G20: =IF(D20="","",(SUM(E20)-F20)) | H20: =IF(D20="","",(D20*G20)) | N20: =IF(L20="","",($G$10)) | O20: =IF(L20="","",(SUM(M20)-N20)) | P20: =IF(L20="","",(L20*O20))
F21: =IF(D21="","",(SUM($G$9))) | G21: =IF(D21="","",(SUM(E21)-F21)) | H21: =IF(D21="","",(D21*G21)) | N21: =IF(L21="","",($G$10)) | O21: =IF(L21="","",(SUM(M21)-N21)) | P21: =IF(L21="","",(L21*O21))
F22: =IF(D22="","",(SUM($G$9))) | G22: =IF(D22="","",(SUM(E22)-F22)) | H22: =IF(D22="","",(D22*G22)) | N22: =IF(L22="","",($G$10)) | O22: =IF(L22="","",(SUM(M22)-N22)) | P22: =IF(L22="","",(L22*O22))
B23: 소 계 | D23: =SUM(D16:D22) -> 0 | H23: =SUM(H16:H22) -> 0 | J23: 소 계 | L23: =SUM(L16:L22) -> 8000 | P23: =SUM(P16:P22) -> -11551136
B26: 마 감 재 고 | G26: [단위:리터/원] | J26: 입 고 내 역 | O26: [단위:리터/원]
B27: 유종 | C27: 수량 | E27: 단가 | G27: 환산금액 | J27: 유종 | K27: 수량 | M27: 사입단가 | O27: 환산금액
B28: G | C28: 0 | E28: 0 | G28: 0 | J28: G | K28: 0 | M28: 0 | O28: 0
B29: K | C29: =$E$9-$D$23 -> #REF! | E29: =$G$9 -> #REF! | G29: =C29*E29 -> #REF! | J29: K | O29: =K29*M29 -> 0
B30: D | C30: =$E$10-$L$23 -> 407560 | E30: =$G$10 -> 1443.892 | G30: =C30*E30 -> 5.8847261e+08 | J30: D | O30: =K30*M30 -> 0
B33: 복 합 단 가
B34: 유종 | C34: 수량 | E34: 금액 | G34: 복 합 단 가
B35: G | C35: 0 | E35: 0 | G35: 0 | R35: 별도 보관물량(국세청 제외)
B36: K | C36: =$C$29+$K$29 -> #REF! | E36: =$G$29+$O$29 -> #REF! | G36: =E36/C36 -> #REF! | T36: 46017
B37: D | C37: =$C$30+$K$30 -> 407560 | E37: =$G$30+$O$30-K37 -> 5.8847261e+08 | G37: =E37/C37 -> 1443.892 | T37: 신광
T38: 28856
B39: 재 고 현 황 | O39: [단위:리터/원] | T39: 1대
C40: 전일 | F40: 금일 | N40: 복합단가 | O40: 증감 | Q40: 12월 31일 | R40: 신광 56천 | S40: 2대출고
C41: 재고 | F41: 입고 | H41: 출고 | K41: 마 감 재 고 | M41: 재고율 | Q41: 01월 02일 | R41: 신광 28천 | S41: 1대출고
B42: 휘발유 | Q42: 01월 05일 | R42: 신광 28천 | S42: 1대출고
B43: 등 유 | C43: =SUM($E$9) -> #REF! | F43: =$K$29 -> 0 | H43: =$D$23 -> 0 | K43: =$C$43-$H$43+$F$43+$O$43 -> #REF! | M43: =SUM($K$43)/$D$9 -> #REF! | N43: =$G$36 -> #REF!
B44: 경 유 | C44: =SUM($E$10) -> 415560 | F44: =$K$30 -> 0 | H44: =$L$23 -> 8000 | K44: =$C$44-$H$44+$F$44+$O$44 -> 407560 | M44: =SUM($K$44)/D10 -> 0.50945 | N44: =$G$37 -> 1443.892
G45: 복합단가의 재고수량과 단가는 보관물량 제외니 참고해주세요!

Sheet 0107
B1: ◈ KK저장소 복합단가 운영표 - 침산저장소
B5: 이 월 재 고 | G5: [단위:리터/원]
B7: 유종 | D7: 탱크용량 | E7: 재고수량 | F7: 재고율 | G7: 단가
C8: G | D8: 0 | E8: 0 | F8: 0 | G8: 0
C9: K | D9: 0 | E9: =SUM(#REF!) -> #REF! | G9: =SUM(#REF!) -> #REF!
C10: D | D10: 800000 | E10: =SUM('0105'!K44:L44) -> 407560 | G10: =SUM('0105'!N44) -> 1443.892
B13: 출고내역(K) | G13: [단위:리터/원] | J13: 출고내역(LD) | O13: [단위:리터/원]
B14: 유종 | C14: 일반매출(사내이관 포함) | J14: 유종 | K14: 일반매출(사내이관 포함)
C15: 거래처명 | D15: 수량 | E15: 출고단가 | F15: 재고단가 | G15: 단가차액 | H15: 이익 | K15: 거래처명 | L15: 수량 | M15: 출고단가 | N15: 재고단가 | O15: 단가차액 | P15: 이익
B16: 실내 등유 | F16: =IF(D16="","",(SUM($G$9))) | G16: =IF(D16="","",(SUM(E16)-F16)) | H16: =IF(D16="","",(D16*G16)) | J16: 경유 | N16: =IF(L16="","",($G$10)) | O16: =IF(L16="","",(SUM(M16)-N16)) | P16: =IF(L16="","",(L16*O16))
F17: =IF(D17="","",(SUM($G$9))) | G17: =IF(D17="","",(SUM(E17)-F17)) | H17: =IF(D17="","",(D17*G17)) | N17: =IF(L17="","",($G$10)) | O17: =IF(L17="","",(SUM(M17)-N17)) | P17: =IF(L17="","",(L17*O17))
F18: =IF(D18="","",(SUM($G$9))) | G18: =IF(D18="","",(SUM(E18)-F18)) | H18: =IF(D18="","",(D18*G18)) | N18: =IF(L18="","",($G$10)) | O18: =IF(L18="","",(SUM(M18)-N18)) | P18: =IF(L18="","",(L18*O18))
F19: =IF(D19="","",(SUM($G$9))) | G19: =IF(D19="","",(SUM(E19)-F19)) | H19: =IF(D19="","",(D19*G19)) | N19: =IF(L19="","",($G$10)) | O19: =IF(L19="","",(SUM(M19)-N19)) | P19: =IF(L19="","",(L19*O19))
F20: =IF(D20="","",(SUM($G$9))) | G20: =IF(D20="","",(SUM(E20)-F20)) | H20: =IF(D20="","",(D20*G20)) | N20: =IF(L20="","",($G$10)) | O20: =IF(L20="","",(SUM(M20)-N20)) | P20: =IF(L20="","",(L20*O20))
F21: =IF(D21="","",(SUM($G$9))) | G21: =IF(D21="","",(SUM(E21)-F21)) | H21: =IF(D21="","",(D21*G21)) | N21: =IF(L21="","",($G$10)) | O21: =IF(L21="","",(SUM(M21)-N21)) | P21: =IF(L21="","",(L21*O21))
F22: =IF(D22="","",(SUM($G$9))) | G22: =IF(D22="","",(SUM(E22)-F22)) | H22: =IF(D22="","",(D22*G22)) | N22: =IF(L22="","",($G$10)) | O22: =IF(L22="","",(SUM(M22)-N22)) | P22: =IF(L22="","",(L22*O22))
B23: 소 계 | D23: =SUM(D16:D22) -> 0 | H23: =SUM(H16:H22) -> 0 | J23: 소 계 | L23: =SUM(L16:L22) -> 0 | P23: =SUM(P16:P22) -> 0
B26: 마 감 재 고 | G26: [단위:리터/원] | J26: 입 고 내 역 | O26: [단위:리터/원]
B27: 유종 | C27: 수량 | E27: 단가 | G27: 환산금액 | J27: 유종 | K27: 수량 | M27: 사입단가 | O27: 환산금액
B28: G | C28: 0 | E28: 0 | G28: 0 | J28: G | K28: 0 | M28: 0 | O28: 0
B29: K | C29: =$E$9-$D$23 -> #REF! | E29: =$G$9 -> #REF! | G29: =C29*E29 -> #REF! | J29: K | O29: =K29*M29 -> 0
B30: D | C30: =$E$10-$L$23 -> 407560 | E30: =$G$10 -> 1443.892 | G30: =C30*E30 -> 5.8847261e+08 | J30: D | O30: =K30*M30 -> 0
B33: 복 합 단 가
B34: 유종 | C34: 수량 | E34: 금액 | G34: 복 합 단 가
B35: G | C35: 0 | E35: 0 | G35: 0 | R35: 별도 보관물량(국세청 제외)
B36: K | C36: =$C$29+$K$29 -> #REF! | E36: =$G$29+$O$29 -> #REF! | G36: =E36/C36 -> #REF! | T36: 46017
B37: D | C37: =$C$30+$K$30 -> 407560 | E37: =$G$30+$O$30-K37 -> 5.8847261e+08 | G37: =E37/C37 -> 1443.892 | T37: 신광
T38: 856 | U38: <<증감처리
B39: 재 고 현 황 | O39: [단위:리터/원]
C40: 전일 | F40: 금일 | N40: 복합단가 | O40: 증감 | Q40: 12월 31일 | R40: 신광 56천 | S40: 2대출고
C41: 재고 | F41: 입고 | H41: 출고 | K41: 마 감 재 고 | M41: 재고율 | Q41: 01월 02일 | R41: 신광 28천 | S41: 1대출고
B42: 휘발유 | Q42: 01월 05일 | R42: 신광 28천 | S42: 1대출고
B43: 등 유 | C43: =SUM($E$9) -> #REF! | F43: =$K$29 -> 0 | H43: =$D$23 -> 0 | K43: =$C$43-$H$43+$F$43+$O$43 -> #REF! | M43: =SUM($K$43)/$D$9 -> #REF! | N43: =$G$36 -> #REF! | Q43: 01월 07일 | R43: 신광 28천 | S43: 1대출고
B44: 경 유 | C44: =SUM($E$10) -> 407560 | F44: =$K$30 -> 0 | H44: =$L$23 -> 0 | K44: =$C$44-$H$44+$F$44+$O$44 -> 408416 | M44: =SUM($K$44)/D10 -> 0.51052 | N44: =$G$37 -> 1443.892 | O44: 856
G45: 복합단가의 재고수량과 단가는 보관물량 제외니 참고해주세요!

Sheet 0109
B1: ◈ KK저장소 복합단가 운영표 - 침산저장소
B5: 이 월 재 고 | G5: [단위:리터/원]
B7: 유종 | D7: 탱크용량 | E7: 재고수량 | F7: 재고율 | G7: 단가
C8: G | D8: 0 | E8: 0 | F8: 0 | G8: 0
C9: K | D9: 0 | E9: =SUM(#REF!) -> #REF! | G9: =SUM(#REF!) -> #REF!
C10: D | D10: 800000 | E10: =SUM('0107'!K44:L44) -> 408416 | G10: =SUM('0107'!N44) -> 1443.892
B13: 출고내역(K) | G13: [단위:리터/원] | J13: 출고내역(LD) | O13: [단위:리터/원]
B14: 유종 | C14: 일반매출(사내이관 포함) | J14: 유종 | K14: 일반매출(사내이관 포함)
C15: 거래처명 | D15: 수량 | E15: 출고단가 | F15: 재고단가 | G15: 단가차액 | H15: 이익 | K15: 거래처명 | L15: 수량 | M15: 출고단가 | N15: 재고단가 | O15: 단가차액 | P15: 이익
B16: 실내 등유 | F16: =IF(D16="","",(SUM($G$9))) | G16: =IF(D16="","",(SUM(E16)-F16)) | H16: =IF(D16="","",(D16*G16)) | J16: 경유 | K16: 침산2 | L16: 20000 | N16: =IF(L16="","",($G$10)) -> 1443.892 | O16: =IF(L16="","",(SUM(M16)-N16)) -> -1443.892 | P16: =IF(L16="","",(L16*O16)) -> -28877839
F17: =IF(D17="","",(SUM($G$9))) | G17: =IF(D17="","",(SUM(E17)-F17)) | H17: =IF(D17="","",(D17*G17)) | K17: 세양개발 | L17: 8000 | N17: =IF(L17="","",($G$10)) -> 1443.892 | O17: =IF(L17="","",(SUM(M17)-N17)) -> -1443.892 | P17: =IF(L17="","",(L17*O17)) -> -11551136
F18: =IF(D18="","",(SUM($G$9))) | G18: =IF(D18="","",(SUM(E18)-F18)) | H18: =IF(D18="","",(D18*G18)) | N18: =IF(L18="","",($G$10)) | O18: =IF(L18="","",(SUM(M18)-N18)) | P18: =IF(L18="","",(L18*O18))
F19: =IF(D19="","",(SUM($G$9))) | G19: =IF(D19="","",(SUM(E19)-F19)) | H19: =IF(D19="","",(D19*G19)) | N19: =IF(L19="","",($G$10)) | O19: =IF(L19="","",(SUM(M19)-N19)) | P19: =IF(L19="","",(L19*O19))
F20: =IF(D20="","",(SUM($G$9))) | G20: =IF(D20="","",(SUM(E20)-F20)) | H20: =IF(D20="","",(D20*G20)) | N20: =IF(L20="","",($G$10)) | O20: =IF(L20="","",(SUM(M20)-N20)) | P20: =IF(L20="","",(L20*O20))
F21: =IF(D21="","",(SUM($G$9))) | G21: =IF(D21="","",(SUM(E21)-F21)) | H21: =IF(D21="","",(D21*G21)) | N21: =IF(L21="","",($G$10)) | O21: =IF(L21="","",(SUM(M21)-N21)) | P21: =IF(L21="","",(L21*O21))
F22: =IF(D22="","",(SUM($G$9))) | G22: =IF(D22="","",(SUM(E22)-F22)) | H22: =IF(D22="","",(D22*G22)) | N22: =IF(L22="","",($G$10)) | O22: =IF(L22="","",(SUM(M22)-N22)) | P22: =IF(L22="","",(L22*O22))
B23: 소 계 | D23: =SUM(D16:D22) -> 0 | H23: =SUM(H16:H22) -> 0 | J23: 소 계 | L23: =SUM(L16:L22) -> 28000 | P23: =SUM(P16:P22) -> -40428975
B26: 마 감 재 고 | G26: [단위:리터/원] | J26: 입 고 내 역 | O26: [단위:리터/원]
B27: 유종 | C27: 수량 | E27: 단가 | G27: 환산금액 | J27: 유종 | K27: 수량 | M27: 사입단가 | O27: 환산금액
B28: G | C28: 0 | E28: 0 | G28: 0 | J28: G | K28: 0 | M28: 0 | O28: 0
B29: K | C29: =$E$9-$D$23 -> #REF! | E29: =$G$9 -> #REF! | G29: =C29*E29 -> #REF! | J29: K | O29: =K29*M29 -> 0
B30: D | C30: =$E$10-$L$23 -> 380416 | E30: =$G$10 -> 1443.892 | G30: =C30*E30 -> 5.4927961e+08 | J30: D | O30: =K30*M30 -> 0
B33: 복 합 단 가
B34: 유종 | C34: 수량 | E34: 금액 | G34: 복 합 단 가
B35: G | C35: 0 | E35: 0 | G35: 0 | R35: 별도 보관물량(국세청 제외)
B36: K | C36: =$C$29+$K$29 -> #REF! | E36: =$G$29+$O$29 -> #REF! | G36: =E36/C36 -> #REF!
B37: D | C37: =$C$30+$K$30 -> 380416 | E37: =$G$30+$O$30-K37 -> 5.4927961e+08 | G37: =E37/C37 -> 1443.892
B39: 재 고 현 황 | O39: [단위:리터/원]
C40: 전일 | F40: 금일 | N40: 복합단가 | O40: 증감
C41: 재고 | F41: 입고 | H41: 출고 | K41: 마 감 재 고 | M41: 재고율
B42: 휘발유
B43: 등 유 | C43: =SUM($E$9) -> #REF! | F43: =$K$29 -> 0 | H43: =$D$23 -> 0 | K43: =$C$43-$H$43+$F$43+$O$43 -> #REF! | M43: =SUM($K$43)/$D$9 -> #REF! | N43: =$G$36 -> #REF!
B44: 경 유 | C44: =SUM($E$10) -> 408416 | F44: =$K$30 -> 0 | H44: =$L$23 -> 28000 | K44: =$C$44-$H$44+$F$44+$O$44 -> 380416 | M44: =SUM($K$44)/D10 -> 0.47552 | N44: =$G$37 -> 1443.892
G45: 복합단가의 재고수량과 단가는 보관물량 제외니 참고해주세요!

Sheet 0119
B1: ◈ KK저장소 복합단가 운영표 - 침산저장소
B5: 이 월 재 고 | G5: [단위:리터/원]
B7: 유종 | D7: 탱크용량 | E7: 재고수량 | F7: 재고율 | G7: 단가
C8: G | D8: 0 | E8: 0 | F8: 0 | G8: 0
C9: K | D9: 0 | E9: =SUM(#REF!) -> #REF! | G9: =SUM(#REF!) -> #REF!
C10: D | D10: 800000 | E10: =SUM('0109'!K44:L44) -> 380416 | G10: =SUM('0109'!N44) -> 1443.892
B13: 출고내역(K) | G13: [단위:리터/원] | J13: 출고내역(LD) | O13: [단위:리터/원]
B14: 유종 | C14: 일반매출(사내이관 포함) | J14: 유종 | K14: 일반매출(사내이관 포함)
C15: 거래처명 | D15: 수량 | E15: 출고단가 | F15: 재고단가 | G15: 단가차액 | H15: 이익 | K15: 거래처명 | L15: 수량 | M15: 출고단가 | N15: 재고단가 | O15: 단가차액 | P15: 이익
B16: 실내 등유 | F16: =IF(D16="","",(SUM($G$9))) | G16: =IF(D16="","",(SUM(E16)-F16)) | H16: =IF(D16="","",(D16*G16)) | J16: 경유 | K16: 중앙2 | L16: 28000 | N16: =IF(L16="","",($G$10)) -> 1443.892 | O16: =IF(L16="","",(SUM(M16)-N16)) -> -1443.892 | P16: =IF(L16="","",(L16*O16)) -> -40428975
F17: =IF(D17="","",(SUM($G$9))) | G17: =IF(D17="","",(SUM(E17)-F17)) | H17: =IF(D17="","",(D17*G17)) | K17: 신라 | L17: 32000 | N17: =IF(L17="","",($G$10)) -> 1443.892 | O17: =IF(L17="","",(SUM(M17)-N17)) -> -1443.892 | P17: =IF(L17="","",(L17*O17)) -> -46204543
F18: =IF(D18="","",(SUM($G$9))) | G18: =IF(D18="","",(SUM(E18)-F18)) | H18: =IF(D18="","",(D18*G18)) | N18: =IF(L18="","",($G$10)) | O18: =IF(L18="","",(SUM(M18)-N18)) | P18: =IF(L18="","",(L18*O18))
F19: =IF(D19="","",(SUM($G$9))) | G19: =IF(D19="","",(SUM(E19)-F19)) | H19: =IF(D19="","",(D19*G19)) | N19: =IF(L19="","",($G$10)) | O19: =IF(L19="","",(SUM(M19)-N19)) | P19: =IF(L19="","",(L19*O19))
F20: =IF(D20="","",(SUM($G$9))) | G20: =IF(D20="","",(SUM(E20)-F20)) | H20: =IF(D20="","",(D20*G20)) | N20: =IF(L20="","",($G$10)) | O20: =IF(L20="","",(SUM(M20)-N20)) | P20: =IF(L20="","",(L20*O20))
F21: =IF(D21="","",(SUM($G$9))) | G21: =IF(D21="","",(SUM(E21)-F21)) | H21: =IF(D21="","",(D21*G21)) | N21: =IF(L21="","",($G$10)) | O21: =IF(L21="","",(SUM(M21)-N21)) | P21: =IF(L21="","",(L21*O21))
F22: =IF(D22="","",(SUM($G$9))) | G22: =IF(D22="","",(SUM(E22)-F22)) | H22: =IF(D22="","",(D22*G22)) | N22: =IF(L22="","",($G$10)) | O22: =IF(L22="","",(SUM(M22)-N22)) | P22: =IF(L22="","",(L22*O22))
B23: 소 계 | D23: =SUM(D16:D22) -> 0 | H23: =SUM(H16:H22) -> 0 | J23: 소 계 | L23: =SUM(L16:L22) -> 60000 | P23: =SUM(P16:P22) -> -86633518
B26: 마 감 재 고 | G26: [단위:리터/원] | J26: 입 고 내 역 | O26: [단위:리터/원]
B27: 유종 | C27: 수량 | E27: 단가 | G27: 환산금액 | J27: 유종 | K27: 수량 | M27: 사입단가 | O27: 환산금액
B28: G | C28: 0 | E28: 0 | G28: 0 | J28: G | K28: 0 | M28: 0 | O28: 0
B29: K | C29: =$E$9-$D$23 -> #REF! | E29: =$G$9 -> #REF! | G29: =C29*E29 -> #REF! | J29: K | O29: =K29*M29 -> 0
B30: D | C30: =$E$10-$L$23 -> 320416 | E30: =$G$10 -> 1443.892 | G30: =C30*E30 -> 4.6264609e+08 | J30: D | O30: =K30*M30 -> 0
B33: 복 합 단 가
B34: 유종 | C34: 수량 | E34: 금액 | G34: 복 합 단 가
B35: G | C35: 0 | E35: 0 | G35: 0 | R35: 별도 보관물량(국세청 제외)
B36: K | C36: =$C$29+$K$29 -> #REF! | E36: =$G$29+$O$29 -> #REF! | G36: =E36/C36 -> #REF!
B37: D | C37: =$C$30+$K$30 -> 320416 | E37: =$G$30+$O$30-K37 -> 4.6264609e+08 | G37: =E37/C37 -> 1443.892
B39: 재 고 현 황 | O39: [단위:리터/원]
C40: 전일 | F40: 금일 | N40: 복합단가 | O40: 증감
C41: 재고 | F41: 입고 | H41: 출고 | K41: 마 감 재 고 | M41: 재고율
B42: 휘발유
B43: 등 유 | C43: =SUM($E$9) -> #REF! | F43: =$K$29 -> 0 | H43: =$D$23 -> 0 | K43: =$C$43-$H$43+$F$43+$O$43 -> #REF! | M43: =SUM($K$43)/$D$9 -> #REF! | N43: =$G$36 -> #REF!
B44: 경 유 | C44: =SUM($E$10) -> 380416 | F44: =$K$30 -> 0 | H44: =$L$23 -> 60000 | K44: =$C$44-$H$44+$F$44+$O$44 -> 320416 | M44: =SUM($K$44)/D10 -> 0.40052 | N44: =$G$37 -> 1443.892
G45: 복합단가의 재고수량과 단가는 보관물량 제외니 참고해주세요!

Sheet 0120
B1: ◈ KK저장소 복합단가 운영표 - 침산저장소
B5: 이 월 재 고 | G5: [단위:리터/원]
B7: 유종 | D7: 탱크용량 | E7: 재고수량 | F7: 재고율 | G7: 단가
C8: G | D8: 0 | E8: 0 | F8: 0 | G8: 0
C9: K | D9: 0 | E9: =SUM(#REF!) -> #REF! | G9: =SUM(#REF!) -> #REF!
C10: D | D10: 800000 | E10: =SUM('0119'!K44:L44) -> 320416 | G10: =SUM('0119'!N44) -> 1443.892
B13: 출고내역(K) | G13: [단위:리터/원] | J13: 출고내역(LD) | O13: [단위:리터/원]
B14: 유종 | C14: 일반매출(사내이관 포함) | J14: 유종 | K14: 일반매출(사내이관 포함)
C15: 거래처명 | D15: 수량 | E15: 출고단가 | F15: 재고단가 | G15: 단가차액 | H15: 이익 | K15: 거래처명 | L15: 수량 | M15: 출고단가 | N15: 재고단가 | O15: 단가차액 | P15: 이익
B16: 실내 등유 | F16: =IF(D16="","",(SUM($G$9))) | G16: =IF(D16="","",(SUM(E16)-F16)) | H16: =IF(D16="","",(D16*G16)) | J16: 경유 | K16: 영강 | L16: 28000 | N16: =IF(L16="","",($G$10)) -> 1443.892 | O16: =IF(L16="","",(SUM(M16)-N16)) -> -1443.892 | P16: =IF(L16="","",(L16*O16)) -> -40428975
F17: =IF(D17="","",(SUM($G$9))) | G17: =IF(D17="","",(SUM(E17)-F17)) | H17: =IF(D17="","",(D17*G17)) | K17: 침산 | L17: 28000 | N17: =IF(L17="","",($G$10)) -> 1443.892 | O17: =IF(L17="","",(SUM(M17)-N17)) -> -1443.892 | P17: =IF(L17="","",(L17*O17)) -> -40428975
F18: =IF(D18="","",(SUM($G$9))) | G18: =IF(D18="","",(SUM(E18)-F18)) | H18: =IF(D18="","",(D18*G18)) | N18: =IF(L18="","",($G$10)) | O18: =IF(L18="","",(SUM(M18)-N18)) | P18: =IF(L18="","",(L18*O18))
F19: =IF(D19="","",(SUM($G$9))) | G19: =IF(D19="","",(SUM(E19)-F19)) | H19: =IF(D19="","",(D19*G19)) | N19: =IF(L19="","",($G$10)) | O19: =IF(L19="","",(SUM(M19)-N19)) | P19: =IF(L19="","",(L19*O19))
F20: =IF(D20="","",(SUM($G$9))) | G20: =IF(D20="","",(SUM(E20)-F20)) | H20: =IF(D20="","",(D20*G20)) | N20: =IF(L20="","",($G$10)) | O20: =IF(L20="","",(SUM(M20)-N20)) | P20: =IF(L20="","",(L20*O20))
F21: =IF(D21="","",(SUM($G$9))) | G21: =IF(D21="","",(SUM(E21)-F21)) | H21: =IF(D21="","",(D21*G21)) | N21: =IF(L21="","",($G$10)) | O21: =IF(L21="","",(SUM(M21)-N21)) | P21: =IF(L21="","",(L21*O21))
F22: =IF(D22="","",(SUM($G$9))) | G22: =IF(D22="","",(SUM(E22)-F22)) | H22: =IF(D22="","",(D22*G22)) | N22: =IF(L22="","",($G$10)) | O22: =IF(L22="","",(SUM(M22)-N22)) | P22: =IF(L22="","",(L22*O22))
B23: 소 계 | D23: =SUM(D16:D22) -> 0 | H23: =SUM(H16:H22) -> 0 | J23: 소 계 | L23: =SUM(L16:L22) -> 56000 | P23: =SUM(P16:P22) -> -80857951
B26: 마 감 재 고 | G26: [단위:리터/원] | J26: 입 고 내 역 | O26: [단위:리터/원]
B27: 유종 | C27: 수량 | E27: 단가 | G27: 환산금액 | J27: 유종 | K27: 수량 | M27: 사입단가 | O27: 환산금액
B28: G | C28: 0 | E28: 0 | G28: 0 | J28: G | K28: 0 | M28: 0 | O28: 0
B29: K | C29: =$E$9-$D$23 -> #REF! | E29: =$G$9 -> #REF! | G29: =C29*E29 -> #REF! | J29: K | O29: =K29*M29 -> 0
B30: D | C30: =$E$10-$L$23 -> 264416 | E30: =$G$10 -> 1443.892 | G30: =C30*E30 -> 3.8178814e+08 | J30: D | O30: =K30*M30 -> 0
B33: 복 합 단 가
B34: 유종 | C34: 수량 | E34: 금액 | G34: 복 합 단 가
B35: G | C35: 0 | E35: 0 | G35: 0 | R35: 별도 보관물량(국세청 제외)
B36: K | C36: =$C$29+$K$29 -> #REF! | E36: =$G$29+$O$29 -> #REF! | G36: =E36/C36 -> #REF!
B37: D | C37: =$C$30+$K$30 -> 264416 | E37: =$G$30+$O$30-K37 -> 3.8178814e+08 | G37: =E37/C37 -> 1443.892
B39: 재 고 현 황 | O39: [단위:리터/원]
C40: 전일 | F40: 금일 | N40: 복합단가 | O40: 증감
C41: 재고 | F41: 입고 | H41: 출고 | K41: 마 감 재 고 | M41: 재고율
B42: 휘발유
B43: 등 유 | C43: =SUM($E$9) -> #REF! | F43: =$K$29 -> 0 | H43: =$D$23 -> 0 | K43: =$C$43-$H$43+$F$43+$O$43 -> #REF! | M43: =SUM($K$43)/$D$9 -> #REF! | N43: =$G$36 -> #REF!
B44: 경 유 | C44: =SUM($E$10) -> 320416 | F44: =$K$30 -> 0 | H44: =$L$23 -> 56000 | K44: =$C$44-$H$44+$F$44+$O$44 -> 264416 | M44: =SUM($K$44)/D10 -> 0.33052 | N44: =$G$37 -> 1443.892
G45: 복합단가의 재고수량과 단가는 보관물량 제외니 참고해주세요!

Sheet 0122
B1: ◈ KK저장소 복합단가 운영표 - 침산저장소
B5: 이 월 재 고 | G5: [단위:리터/원]
B7: 유종 | D7: 탱크용량 | E7: 재고수량 | F7: 재고율 | G7: 단가
C8: G | D8: 0 | E8: 0 | F8: 0 | G8: 0
C9: K | D9: 0 | E9: =SUM(#REF!) -> #REF! | G9: =SUM(#REF!) -> #REF!
C10: D | D10: 800000 | E10: =SUM('0120'!K44:L44) -> 264416 | G10: =SUM('0120'!N44) -> 1443.892
B13: 출고내역(K) | G13: [단위:리터/원] | J13: 출고내역(LD) | O13: [단위:리터/원]
B14: 유종 | C14: 일반매출(사내이관 포함) | J14: 유종 | K14: 일반매출(사내이관 포함)
C15: 거래처명 | D15: 수량 | E15: 출고단가 | F15: 재고단가 | G15: 단가차액 | H15: 이익 | K15: 거래처명 | L15: 수량 | M15: 출고단가 | N15: 재고단가 | O15: 단가차액 | P15: 이익
B16: 실내 등유 | F16: =IF(D16="","",(SUM($G$9))) | G16: =IF(D16="","",(SUM(E16)-F16)) | H16: =IF(D16="","",(D16*G16)) | J16: 경유 | K16: 세양개발 | L16: 8000 | N16: =IF(L16="","",($G$10)) -> 1443.892 | O16: =IF(L16="","",(SUM(M16)-N16)) -> -1443.892 | P16: =IF(L16="","",(L16*O16)) -> -11551136
F17: =IF(D17="","",(SUM($G$9))) | G17: =IF(D17="","",(SUM(E17)-F17)) | H17: =IF(D17="","",(D17*G17)) | N17: =IF(L17="","",($G$10)) | O17: =IF(L17="","",(SUM(M17)-N17)) | P17: =IF(L17="","",(L17*O17))
F18: =IF(D18="","",(SUM($G$9))) | G18: =IF(D18="","",(SUM(E18)-F18)) | H18: =IF(D18="","",(D18*G18)) | N18: =IF(L18="","",($G$10)) | O18: =IF(L18="","",(SUM(M18)-N18)) | P18: =IF(L18="","",(L18*O18))
F19: =IF(D19="","",(SUM($G$9))) | G19: =IF(D19="","",(SUM(E19)-F19)) | H19: =IF(D19="","",(D19*G19)) | N19: =IF(L19="","",($G$10)) | O19: =IF(L19="","",(SUM(M19)-N19)) | P19: =IF(L19="","",(L19*O19))
F20: =IF(D20="","",(SUM($G$9))) | G20: =IF(D20="","",(SUM(E20)-F20)) | H20: =IF(D20="","",(D20*G20)) | N20: =IF(L20="","",($G$10)) | O20: =IF(L20="","",(SUM(M20)-N20)) | P20: =IF(L20="","",(L20*O20))
F21: =IF(D21="","",(SUM($G$9))) | G21: =IF(D21="","",(SUM(E21)-F21)) | H21: =IF(D21="","",(D21*G21)) | N21: =IF(L21="","",($G$10)) | O21: =IF(L21="","",(SUM(M21)-N21)) | P21: =IF(L21="","",(L21*O21))
F22: =IF(D22="","",(SUM($G$9))) | G22: =IF(D22="","",(SUM(E22)-F22)) | H22: =IF(D22="","",(D22*G22)) | N22: =IF(L22="","",($G$10)) | O22: =IF(L22="","",(SUM(M22)-N22)) | P22: =IF(L22="","",(L22*O22))
B23: 소 계 | D23: =SUM(D16:D22) -> 0 | H23: =SUM(H16:H22) -> 0 | J23: 소 계 | L23: =SUM(L16:L22) -> 8000 | P23: =SUM(P16:P22) -> -11551136
B26: 마 감 재 고 | G26: [단위:리터/원] | J26: 입 고 내 역 | O26: [단위:리터/원]
B27: 유종 | C27: 수량 | E27: 단가 | G27: 환산금액 | J27: 유종 | K27: 수량 | M27: 사입단가 | O27: 환산금액
B28: G | C28: 0 | E28: 0 | G28: 0 | J28: G | K28: 0 | M28: 0 | O28: 0
B29: K | C29: =$E$9-$D$23 -> #REF! | E29: =$G$9 -> #REF! | G29: =C29*E29 -> #REF! | J29: K | O29: =K29*M29 -> 0
B30: D | C30: =$E$10-$L$23 -> 256416 | E30: =$G$10 -> 1443.892 | G30: =C30*E30 -> 3.70237e+08 | J30: D | O30: =K30*M30 -> 0
B33: 복 합 단 가
B34: 유종 | C34: 수량 | E34: 금액 | G34: 복 합 단 가
B35: G | C35: 0 | E35: 0 | G35: 0 | R35: 별도 보관물량(국세청 제외)
B36: K | C36: =$C$29+$K$29 -> #REF! | E36: =$G$29+$O$29 -> #REF! | G36: =E36/C36 -> #REF!
B37: D | C37: =$C$30+$K$30 -> 256416 | E37: =$G$30+$O$30-K37 -> 3.70237e+08 | G37: =E37/C37 -> 1443.892
B39: 재 고 현 황 | O39: [단위:리터/원]
C40: 전일 | F40: 금일 | N40: 복합단가 | O40: 증감
C41: 재고 | F41: 입고 | H41: 출고 | K41: 마 감 재 고 | M41: 재고율
B42: 휘발유
B43: 등 유 | C43: =SUM($E$9) -> #REF! | F43: =$K$29 -> 0 | H43: =$D$23 -> 0 | K43: =$C$43-$H$43+$F$43+$O$43 -> #REF! | M43: =SUM($K$43)/$D$9 -> #REF! | N43: =$G$36 -> #REF!
B44: 경 유 | C44: =SUM($E$10) -> 264416 | F44: =$K$30 -> 0 | H44: =$L$23 -> 8000 | K44: =$C$44-$H$44+$F$44+$O$44 -> 256416 | M44: =SUM($K$44)/D10 -> 0.32052 | N44: =$G$37 -> 1443.892
G45: 복합단가의 재고수량과 단가는 보관물량 제외니 참고해주세요!

Sheet 0127
B1: ◈ KK저장소 복합단가 운영표 - 침산저장소
B5: 이 월 재 고 | G5: [단위:리터/원]
B7: 유종 | D7: 탱크용량 | E7: 재고수량 | F7: 재고율 | G7: 단가
C8: G | D8: 0 | E8: 0 | F8: 0 | G8: 0
C9: K | D9: 0 | E9: =SUM(#REF!) -> #REF! | G9: =SUM(#REF!) -> #REF!
C10: D | D10: 800000 | E10: =SUM('0122'!K44:L44) -> 256416 | G10: =SUM('0122'!N44) -> 1443.892
B13: 출고내역(K) | G13: [단위:리터/원] | J13: 출고내역(LD) | O13: [단위:리터/원]
B14: 유종 | C14: 일반매출(사내이관 포함) | J14: 유종 | K14: 일반매출(사내이관 포함)
C15: 거래처명 | D15: 수량 | E15: 출고단가 | F15: 재고단가 | G15: 단가차액 | H15: 이익 | K15: 거래처명 | L15: 수량 | M15: 출고단가 | N15: 재고단가 | O15: 단가차액 | P15: 이익
B16: 실내 등유 | F16: =IF(D16="","",(SUM($G$9))) | G16: =IF(D16="","",(SUM(E16)-F16)) | H16: =IF(D16="","",(D16*G16)) | J16: 경유 | N16: =IF(L16="","",($G$10)) | O16: =IF(L16="","",(SUM(M16)-N16)) | P16: =IF(L16="","",(L16*O16))
F17: =IF(D17="","",(SUM($G$9))) | G17: =IF(D17="","",(SUM(E17)-F17)) | H17: =IF(D17="","",(D17*G17)) | N17: =IF(L17="","",($G$10)) | O17: =IF(L17="","",(SUM(M17)-N17)) | P17: =IF(L17="","",(L17*O17))
F18: =IF(D18="","",(SUM($G$9))) | G18: =IF(D18="","",(SUM(E18)-F18)) | H18: =IF(D18="","",(D18*G18)) | N18: =IF(L18="","",($G$10)) | O18: =IF(L18="","",(SUM(M18)-N18)) | P18: =IF(L18="","",(L18*O18))
F19: =IF(D19="","",(SUM($G$9))) | G19: =IF(D19="","",(SUM(E19)-F19)) | H19: =IF(D19="","",(D19*G19)) | N19: =IF(L19="","",($G$10)) | O19: =IF(L19="","",(SUM(M19)-N19)) | P19: =IF(L19="","",(L19*O19))
F20: =IF(D20="","",(SUM($G$9))) | G20: =IF(D20="","",(SUM(E20)-F20)) | H20: =IF(D20="","",(D20*G20)) | N20: =IF(L20="","",($G$10)) | O20: =IF(L20="","",(SUM(M20)-N20)) | P20: =IF(L20="","",(L20*O20))
F21: =IF(D21="","",(SUM($G$9))) | G21: =IF(D21="","",(SUM(E21)-F21)) | H21: =IF(D21="","",(D21*G21)) | N21: =IF(L21="","",($G$10)) | O21: =IF(L21="","",(SUM(M21)-N21)) | P21: =IF(L21="","",(L21*O21))
F22: =IF(D22="","",(SUM($G$9))) | G22: =IF(D22="","",(SUM(E22)-F22)) | H22: =IF(D22="","",(D22*G22)) | N22: =IF(L22="","",($G$10)) | O22: =IF(L22="","",(SUM(M22)-N22)) | P22: =IF(L22="","",(L22*O22))
B23: 소 계 | D23: =SUM(D16:D22) -> 0 | H23: =SUM(H16:H22) -> 0 | J23: 소 계 | L23: =SUM(L16:L22) -> 0 | P23: =SUM(P16:P22) -> 0
B26: 마 감 재 고 | G26: [단위:리터/원] | J26: 입 고 내 역 | O26: [단위:리터/원]
B27: 유종 | C27: 수량 | E27: 단가 | G27: 환산금액 | J27: 유종 | K27: 수량 | M27: 사입단가 | O27: 환산금액
B28: G | C28: 0 | E28: 0 | G28: 0 | J28: G | K28: 0 | M28: 0 | O28: 0
B29: K | C29: =$E$9-$D$23 -> #REF! | E29: =$G$9 -> #REF! | G29: =C29*E29 -> #REF! | J29: K | O29: =K29*M29 -> 0
B30: D | C30: =$E$10-$L$23 -> 256416 | E30: =$G$10 -> 1443.892 | G30: =C30*E30 -> 3.70237e+08 | J30: D | O30: =K30*M30 -> 0
B33: 복 합 단 가
B34: 유종 | C34: 수량 | E34: 금액 | G34: 복 합 단 가
B35: G | C35: 0 | E35: 0 | G35: 0 | R35: 별도 보관물량(국세청 제외)
B36: K | C36: =$C$29+$K$29 -> #REF! | E36: =$G$29+$O$29 -> #REF! | G36: =E36/C36 -> #REF! | R36: 46049
B37: D | C37: =$C$30+$K$30 -> 256416 | E37: =$G$30+$O$30-K37 -> 3.70237e+08 | G37: =E37/C37 -> 1443.892 | R37: 신광 | S37: 용두
R38: =28185+28171 -> 56356 | S38: 32195
B39: 재 고 현 황 | O39: [단위:리터/원] | R39: 2대 | S39: 1대
C40: 전일 | F40: 금일 | N40: 복합단가 | O40: 증감
C41: 재고 | F41: 입고 | H41: 출고 | K41: 마 감 재 고 | M41: 재고율
B42: 휘발유
B43: 등 유 | C43: =SUM($E$9) -> #REF! | F43: =$K$29 -> 0 | H43: =$D$23 -> 0 | K43: =$C$43-$H$43+$F$43+$O$43 -> #REF! | M43: =SUM($K$43)/$D$9 -> #REF! | N43: =$G$36 -> #REF!
B44: 경 유 | C44: =SUM($E$10) -> 256416 | F44: =$K$30 -> 0 | H44: =$L$23 -> 0 | K44: =$C$44-$H$44+$F$44+$O$44 -> 256416 | M44: =SUM($K$44)/D10 -> 0.32052 | N44: =$G$37 -> 1443.892
G45: 복합단가의 재고수량과 단가는 보관물량 제외니 참고해주세요!

Sheet 0128
B1: ◈ KK저장소 복합단가 운영표 - 침산저장소
B5: 이 월 재 고 | G5: [단위:리터/원]
B7: 유종 | D7: 탱크용량 | E7: 재고수량 | F7: 재고율 | G7: 단가
C8: G | D8: 0 | E8: 0 | F8: 0 | G8: 0
C9: K | D9: 0 | E9: =SUM(#REF!) -> #REF! | G9: =SUM(#REF!) -> #REF!
C10: D | D10: 800000 | E10: =SUM('0127'!K44:L44) -> 256416 | G10: =SUM('0127'!N44) -> 1443.892
B13: 출고내역(K) | G13: [단위:리터/원] | J13: 출고내역(LD) | O13: [단위:리터/원]
B14: 유종 | C14: 일반매출(사내이관 포함) | J14: 유종 | K14: 일반매출(사내이관 포함)
C15: 거래처명 | D15: 수량 | E15: 출고단가 | F15: 재고단가 | G15: 단가차액 | H15: 이익 | K15: 거래처명 | L15: 수량 | M15: 출고단가 | N15: 재고단가 | O15: 단가차액 | P15: 이익
B16: 실내 등유 | F16: =IF(D16="","",(SUM($G$9))) | G16: =IF(D16="","",(SUM(E16)-F16)) | H16: =IF(D16="","",(D16*G16)) | J16: 경유 | N16: =IF(L16="","",($G$10)) | O16: =IF(L16="","",(SUM(M16)-N16)) | P16: =IF(L16="","",(L16*O16))
F17: =IF(D17="","",(SUM($G$9))) | G17: =IF(D17="","",(SUM(E17)-F17)) | H17: =IF(D17="","",(D17*G17)) | N17: =IF(L17="","",($G$10)) | O17: =IF(L17="","",(SUM(M17)-N17)) | P17: =IF(L17="","",(L17*O17))
F18: =IF(D18="","",(SUM($G$9))) | G18: =IF(D18="","",(SUM(E18)-F18)) | H18: =IF(D18="","",(D18*G18)) | N18: =IF(L18="","",($G$10)) | O18: =IF(L18="","",(SUM(M18)-N18)) | P18: =IF(L18="","",(L18*O18))
F19: =IF(D19="","",(SUM($G$9))) | G19: =IF(D19="","",(SUM(E19)-F19)) | H19: =IF(D19="","",(D19*G19)) | N19: =IF(L19="","",($G$10)) | O19: =IF(L19="","",(SUM(M19)-N19)) | P19: =IF(L19="","",(L19*O19))
F20: =IF(D20="","",(SUM($G$9))) | G20: =IF(D20="","",(SUM(E20)-F20)) | H20: =IF(D20="","",(D20*G20)) | N20: =IF(L20="","",($G$10)) | O20: =IF(L20="","",(SUM(M20)-N20)) | P20: =IF(L20="","",(L20*O20))
