Workbook

Sheet 1201
B1: ◈ KK저장소 복합단가 운영표 - 단지저장소
B5: 이 월 재 고 | G5: [단위:리터/원]
B7: 유종 | D7: 탱크용량 | E7: 재고수량 | F7: 재고율 | G7: 단가
C8: G | D8: 0 | E8: 0 | F8: 0 | G8: 0
C9: K | D9: 200000 | E9: 55700 | F9: 0.2785 | G9: 1058.7304
C10: D | D10: 500000 | E10: 66705 | F10: 0.13341 | G10: 1490.0255
B13: 출고내역(K) | G13: [단위:리터/원] | J13: 출고내역(LD) | O13: [단위:리터/원]
B14: 유종 | C14: 일반매출(사내이관 포함) | J14: 유종 | K14: 일반매출(사내이관 포함)
C15: 거래처명 | D15: 수량 | E15: 출고단가 | F15: 재고단가 | G15: 단가차액 | H15: 이익 | K15: 거래처명 | L15: 수량 | M15: 출고단가 | N15: 재고단가 | O15: 단가차액 | P15: 이익
B16: 실내 등유 | D16: 5000 | F16: 1058.7304 | G16: -1058.7304 | H16: -5293652.1 | J16: 경유 | L16: 3000 | N16: 1490.0255 | O16: -1490.0255 | P16: -4470076.6
B23: 소 계 | D23: 5000 | H23: -5293652.1 | J23: 소 계 | L23: 3000 | P23: -4470076.6
B26: 마 감 재 고 | G26: [단위:리터/원] | J26: 입 고 내 역 | O26: [단위:리터/원]
B27: 유종 | C27: 수량 | E27: 단가 | G27: 환산금액 | J27: 유종 | K27: 수량 | M27: 사입단가 | O27: 환산금액
B28: G | C28: 0 | E28: 0 | G28: 0 | J28: G | K28: 0 | O28: 0
B29: K | C29: 50700 | E29: 1058.7304 | G29: 53677632 | J29: K | O29: 0
B30: D | C30: 63705 | E30: 1490.0255 | G30: 94922077 | J30: D | O30: 0
B33: 복 합 단 가
B34: 유종 | C34: 수량 | E34: 금액 | G34: 복 합 단 가
B35: G | C35: 0 | E35: 0 | G35: 0
B36: K | C36: 50700 | E36: 53677632 | G36: 1058.7304
B37: D | C37: 63705 | E37: 94922077 | G37: 1490.0255
B39: 재 고 현 황 | O39: [단위:리터/원]
C40: 전일 | F40: 금일 | N40: 복합단가 | O40: 증감
C41: 재고 | F41: 입고 | H41: 출고 | K41: 마 감 재 고 | M41: 재고율
B42: 휘발유 | P42: .
B43: 등 유 | C43: 55700 | F43: 0 | H43: 5000 | K43: 50764 | M43: 0.25382 | N43: 1058.7304 | O43: 64
B44: 경 유 | C44: 66705 | F44: 0 | H44: 3000 | K44: 62574 | M44: 0.125148 | N44: 1490.0255 | O44: -1131
G45: 복합단가의 재고수량과 단가는 보관물량 제외니 참고해주세요!

Sheet 1202
B1: ◈ KK저장소 복합단가 운영표 - 단지저장소
B5: 이 월 재 고 | G5: [단위:리터/원]
B7: 유종 | D7: 탱크용량 | E7: 재고수량 | F7: 재고율 | G7: 단가
C8: G | D8: 0 | E8: 0 | F8: 0 | G8: 0
C9: K | D9: 200000 | E9: =SUM('1201'!K43:L43) -> 50764 | F9: =E9/D9 -> 0.25382 | G9: =SUM('1201'!N43) -> 1058.7304
C10: D | D10: 500000 | E10: =SUM('1201'!K44:L44) -> 62574 | F10: =E10/D10 -> 0.125148 | G10: =SUM('1201'!N44) -> 1490.0255
B13: 출고내역(K) | G13: [단위:리터/원] | J13: 출고내역(LD) | O13: [단위:리터/원]
B14: 유종 | C14: 일반매출(사내이관 포함) | J14: 유종 | K14: 일반매출(사내이관 포함)
C15: 거래처명 | D15: 수량 | E15: 출고단가 | F15: 재고단가 | G15: 단가차액 | H15: 이익 | K15: 거래처명 | L15: 수량 | M15: 출고단가 | N15: 재고단가 | O15: 단가차액 | P15: 이익
B16: 실내 등유 | F16: =IF(D16="","",(SUM($G$9))) | G16: =IF(D16="","",(SUM(E16)-F16)) | H16: =IF(D16="","",(D16*G16)) | J16: 경유 | L16: 3000 | N16: =IF(L16="","",($G$10)) -> 1490.0255 | O16: =IF(L16="","",(SUM(M16)-N16)) -> -1490.0255 | P16: =IF(L16="","",(L16*O16)) -> -4470076.6
F17: =IF(D17="","",(SUM($G$9))) | G17: =IF(D17="","",(SUM(E17)-F17)) | H17: =IF(D17="","",(D17*G17)) | L17: 6000 | N17: =IF(L17="","",($G$10)) -> 1490.0255 | O17: =IF(L17="","",(SUM(M17)-N17)) -> -1490.0255 | P17: =IF(L17="","",(L17*O17)) -> -8940153.2
F18: =IF(D18="","",(SUM($G$9))) | G18: =IF(D18="","",(SUM(E18)-F18)) | H18: =IF(D18="","",(D18*G18)) | N18: =IF(L18="","",($G$10)) | O18: =IF(L18="","",(SUM(M18)-N18)) | P18: =IF(L18="","",(L18*O18))
F19: =IF(D19="","",(SUM($G$9))) | G19: =IF(D19="","",(SUM(E19)-F19)) | H19: =IF(D19="","",(D19*G19)) | N19: =IF(L19="","",($G$10)) | O19: =IF(L19="","",(SUM(M19)-N19)) | P19: =IF(L19="","",(L19*O19))
F20: =IF(D20="","",(SUM($G$9))) | G20: =IF(D20="","",(SUM(E20)-F20)) | H20: =IF(D20="","",(D20*G20)) | N20: =IF(L20="","",($G$10)) | O20: =IF(L20="","",(SUM(M20)-N20)) | P20: =IF(L20="","",(L20*O20))
F21: =IF(D21="","",(SUM($G$9))) | G21: =IF(D21="","",(SUM(E21)-F21)) | H21: =IF(D21="","",(D21*G21)) | N21: =IF(L21="","",($G$10)) | O21: =IF(L21="","",(SUM(M21)-N21)) | P21: =IF(L21="","",(L21*O21))
F22: =IF(D22="","",(SUM($G$9))) | G22: =IF(D22="","",(SUM(E22)-F22)) | H22: =IF(D22="","",(D22*G22)) | N22: =IF(L22="","",($G$10)) | O22: =IF(L22="","",(SUM(M22)-N22)) | P22: =IF(L22="","",(L22*O22))
B23: 소 계 | D23: =SUM(D16:D22) -> 0 | H23: =SUM(H16:H22) -> 0 | J23: 소 계 | L23: =SUM(L16:L22) -> 9000 | P23: =SUM(P16:P22) -> -13410230
B26: 마 감 재 고 | G26: [단위:리터/원] | J26: 입 고 내 역 | O26: [단위:리터/원]
B27: 유종 | C27: 수량 | E27: 단가 | G27: 환산금액 | J27: 유종 | K27: 수량 | M27: 사입단가 | O27: 환산금액
B28: G | C28: 0 | E28: 0 | G28: 0 | J28: G | K28: 0 | O28: 0
B29: K | C29: =$E$9-$D$23 -> 50764 | E29: =$G$9 -> 1058.7304 | G29: =C29*E29 -> 53745391 | J29: K | O29: =K29*M29 -> 0
B30: D | C30: =$E$10-$L$23 -> 53574 | E30: =$G$10 -> 1490.0255 | G30: =C30*E30 -> 79826628 | J30: D | O30: =K30*M30 -> 0
B33: 복 합 단 가
B34: 유종 | C34: 수량 | E34: 금액 | G34: 복 합 단 가
B35: G | C35: 0 | E35: 0 | G35: 0
B36: K | C36: =$C$29+$K$29 -> 50764 | E36: =$G$29+$O$29-K36 -> 53745391 | G36: =E36/C36 -> 1058.7304
B37: D | C37: =$C$30+$K$30 -> 53574 | E37: =$G$30+$O$30 -> 79826628 | G37: =E37/C37 -> 1490.0255
B39: 재 고 현 황 | O39: [단위:리터/원]
C40: 전일 | F40: 금일 | N40: 복합단가 | O40: 증감
C41: 재고 | F41: 입고 | H41: 출고 | K41: 마 감 재 고 | M41: 재고율
B42: 휘발유 | P42: .
B43: 등 유 | C43: =SUM($E$9) -> 50764 | F43: =$K$29 -> 0 | H43: =$D$23 -> 0 | K43: =$C$43-$H$43+$F$43+$O$43 -> 50764 | M43: =SUM($K$43)/$D$9 -> 0.25382 | N43: =$G$36 -> 1058.7304
B44: 경 유 | C44: =SUM($E$10) -> 62574 | F44: =$K$30 -> 0 | H44: =$L$23 -> 9000 | K44: =$C$44-$H$44+$F$44+$O$44 -> 53574 | M44: =SUM($K$44)/D10 -> 0.107148 | N44: =$G$37 -> 1490.0255
G45: 복합단가의 재고수량과 단가는 보관물량 제외니 참고해주세요!

Sheet 1203
B1: ◈ KK저장소 복합단가 운영표 - 단지저장소
B5: 이 월 재 고 | G5: [단위:리터/원]
B7: 유종 | D7: 탱크용량 | E7: 재고수량 | F7: 재고율 | G7: 단가
C8: G | D8: 0 | E8: 0 | F8: 0 | G8: 0
C9: K | D9: 200000 | E9: =SUM('1202'!K43:L43) -> 50764 | F9: =E9/D9 -> 0.25382 | G9: =SUM('1202'!N43) -> 1058.7304
C10: D | D10: 500000 | E10: =SUM('1202'!K44:L44) -> 53574 | F10: =E10/D10 -> 0.107148 | G10: =SUM('1202'!N44) -> 1490.0255
B13: 출고내역(K) | G13: [단위:리터/원] | J13: 출고내역(LD) | O13: [단위:리터/원]
B14: 유종 | C14: 일반매출(사내이관 포함) | J14: 유종 | K14: 일반매출(사내이관 포함)
C15: 거래처명 | D15: 수량 | E15: 출고단가 | F15: 재고단가 | G15: 단가차액 | H15: 이익 | K15: 거래처명 | L15: 수량 | M15: 출고단가 | N15: 재고단가 | O15: 단가차액 | P15: 이익
B16: 실내 등유 | D16: 5700 | F16: =IF(D16="","",(SUM($G$9))) -> 1058.7304 | G16: =IF(D16="","",(SUM(E16)-F16)) -> -1058.7304 | H16: =IF(D16="","",(D16*G16)) -> -6034763.4 | J16: 경유 | L16: 1000 | N16: =IF(L16="","",($G$10)) -> 1490.0255 | O16: =IF(L16="","",(SUM(M16)-N16)) -> -1490.0255 | P16: =IF(L16="","",(L16*O16)) -> -1490025.5
D17: 1700 | F17: =IF(D17="","",(SUM($G$9))) -> 1058.7304 | G17: =IF(D17="","",(SUM(E17)-F17)) -> -1058.7304 | H17: =IF(D17="","",(D17*G17)) -> -1799841.7 | L17: 3000 | N17: =IF(L17="","",($G$10)) -> 1490.0255 | O17: =IF(L17="","",(SUM(M17)-N17)) -> -1490.0255 | P17: =IF(L17="","",(L17*O17)) -> -4470076.6
D18: 1000 | F18: =IF(D18="","",(SUM($G$9))) -> 1058.7304 | G18: =IF(D18="","",(SUM(E18)-F18)) -> -1058.7304 | H18: =IF(D18="","",(D18*G18)) -> -1058730.4 | N18: =IF(L18="","",($G$10)) | O18: =IF(L18="","",(SUM(M18)-N18)) | P18: =IF(L18="","",(L18*O18))
F19: =IF(D19="","",(SUM($G$9))) | G19: =IF(D19="","",(SUM(E19)-F19)) | H19: =IF(D19="","",(D19*G19)) | N19: =IF(L19="","",($G$10)) | O19: =IF(L19="","",(SUM(M19)-N19)) | P19: =IF(L19="","",(L19*O19))
F20: =IF(D20="","",(SUM($G$9))) | G20: =IF(D20="","",(SUM(E20)-F20)) | H20: =IF(D20="","",(D20*G20)) | N20: =IF(L20="","",($G$10)) | O20: =IF(L20="","",(SUM(M20)-N20)) | P20: =IF(L20="","",(L20*O20))
F21: =IF(D21="","",(SUM($G$9))) | G21: =IF(D21="","",(SUM(E21)-F21)) | H21: =IF(D21="","",(D21*G21)) | N21: =IF(L21="","",($G$10)) | O21: =IF(L21="","",(SUM(M21)-N21)) | P21: =IF(L21="","",(L21*O21))
F22: =IF(D22="","",(SUM($G$9))) | G22: =IF(D22="","",(SUM(E22)-F22)) | H22: =IF(D22="","",(D22*G22)) | N22: =IF(L22="","",($G$10)) | O22: =IF(L22="","",(SUM(M22)-N22)) | P22: =IF(L22="","",(L22*O22))
B23: 소 계 | D23: =SUM(D16:D22) -> 8400 | H23: =SUM(H16:H22) -> -8893335.5 | J23: 소 계 | L23: =SUM(L16:L22) -> 4000 | P23: =SUM(P16:P22) -> -5960102.2
B26: 마 감 재 고 | G26: [단위:리터/원] | J26: 입 고 내 역 | O26: [단위:리터/원]
B27: 유종 | C27: 수량 | E27: 단가 | G27: 환산금액 | J27: 유종 | K27: 수량 | M27: 사입단가 | O27: 환산금액
B28: G | C28: 0 | E28: 0 | G28: 0 | J28: G | K28: 0 | O28: 0
B29: K | C29: =$E$9-$D$23 -> 42364 | E29: =$G$9 -> 1058.7304 | G29: =C29*E29 -> 44852055 | J29: K | O29: =K29*M29 -> 0
B30: D | C30: =$E$10-$L$23 -> 49574 | E30: =$G$10 -> 1490.0255 | G30: =C30*E30 -> 73866526 | J30: D | O30: =K30*M30 -> 0
B33: 복 합 단 가
B34: 유종 | C34: 수량 | E34: 금액 | G34: 복 합 단 가
B35: G | C35: 0 | E35: 0 | G35: 0
B36: K | C36: =$C$29+$K$29 -> 42364 | E36: =$G$29+$O$29-K36 -> 44852055 | G36: =E36/C36 -> 1058.7304
B37: D | C37: =$C$30+$K$30 -> 49574 | E37: =$G$30+$O$30 -> 73866526 | G37: =E37/C37 -> 1490.0255
B39: 재 고 현 황 | O39: [단위:리터/원]
C40: 전일 | F40: 금일 | N40: 복합단가 | O40: 증감
C41: 재고 | F41: 입고 | H41: 출고 | K41: 마 감 재 고 | M41: 재고율
B42: 휘발유 | P42: .
B43: 등 유 | C43: =SUM($E$9) -> 50764 | F43: =$K$29 -> 0 | H43: =$D$23 -> 8400 | K43: =$C$43-$H$43+$F$43+$O$43 -> 42364 | M43: =SUM($K$43)/$D$9 -> 0.21182 | N43: =$G$36 -> 1058.7304
B44: 경 유 | C44: =SUM($E$10) -> 53574 | F44: =$K$30 -> 0 | H44: =$L$23 -> 4000 | K44: =$C$44-$H$44+$F$44+$O$44 -> 49574 | M44: =SUM($K$44)/D10 -> 0.099148 | N44: =$G$37 -> 1490.0255
G45: 복합단가의 재고수량과 단가는 보관물량 제외니 참고해주세요!

Sheet 1204
B1: ◈ KK저장소 복합단가 운영표 - 단지저장소
B5: 이 월 재 고 | G5: [단위:리터/원]
B7: 유종 | D7: 탱크용량 | E7: 재고수량 | F7: 재고율 | G7: 단가
C8: G | D8: 0 | E8: 0 | F8: 0 | G8: 0
C9: K | D9: 200000 | E9: =SUM('1203'!K43:L43) -> 42364 | F9: =E9/D9 -> 0.21182 | G9: =SUM('1203'!N43) -> 1058.7304
C10: D | D10: 500000 | E10: =SUM('1203'!K44:L44) -> 49574 | F10: =E10/D10 -> 0.099148 | G10: =SUM('1203'!N44) -> 1490.0255
B13: 출고내역(K) | G13: [단위:리터/원] | J13: 출고내역(LD) | O13: [단위:리터/원]
B14: 유종 | C14: 일반매출(사내이관 포함) | J14: 유종 | K14: 일반매출(사내이관 포함)
C15: 거래처명 | D15: 수량 | E15: 출고단가 | F15: 재고단가 | G15: 단가차액 | H15: 이익 | K15: 거래처명 | L15: 수량 | M15: 출고단가 | N15: 재고단가 | O15: 단가차액 | P15: 이익
B16: 실내 등유 | D16: 8000 | F16: =IF(D16="","",(SUM($G$9))) -> 1058.7304 | G16: =IF(D16="","",(SUM(E16)-F16)) -> -1058.7304 | H16: =IF(D16="","",(D16*G16)) -> -8469843.3 | J16: 경유 | L16: 1000 | N16: =IF(L16="","",($G$10)) -> 1490.0255 | O16: =IF(L16="","",(SUM(M16)-N16)) -> -1490.0255 | P16: =IF(L16="","",(L16*O16)) -> -1490025.5
D17: 2000 | F17: =IF(D17="","",(SUM($G$9))) -> 1058.7304 | G17: =IF(D17="","",(SUM(E17)-F17)) -> -1058.7304 | H17: =IF(D17="","",(D17*G17)) -> -2117460.8 | L17: 3000 | N17: =IF(L17="","",($G$10)) -> 1490.0255 | O17: =IF(L17="","",(SUM(M17)-N17)) -> -1490.0255 | P17: =IF(L17="","",(L17*O17)) -> -4470076.6
D18: 1500 | F18: =IF(D18="","",(SUM($G$9))) -> 1058.7304 | G18: =IF(D18="","",(SUM(E18)-F18)) -> -1058.7304 | H18: =IF(D18="","",(D18*G18)) -> -1588095.6 | L18: 3000 | N18: =IF(L18="","",($G$10)) -> 1490.0255 | O18: =IF(L18="","",(SUM(M18)-N18)) -> -1490.0255 | P18: =IF(L18="","",(L18*O18)) -> -4470076.6
D19: 20000 | F19: =IF(D19="","",(SUM($G$9))) -> 1058.7304 | G19: =IF(D19="","",(SUM(E19)-F19)) -> -1058.7304 | H19: =IF(D19="","",(D19*G19)) -> -21174608 | N19: =IF(L19="","",($G$10)) | O19: =IF(L19="","",(SUM(M19)-N19)) | P19: =IF(L19="","",(L19*O19))
D20: 1000 | F20: =IF(D20="","",(SUM($G$9))) -> 1058.7304 | G20: =IF(D20="","",(SUM(E20)-F20)) -> -1058.7304 | H20: =IF(D20="","",(D20*G20)) -> -1058730.4 | N20: =IF(L20="","",($G$10)) | O20: =IF(L20="","",(SUM(M20)-N20)) | P20: =IF(L20="","",(L20*O20))
F21: =IF(D21="","",(SUM($G$9))) | G21: =IF(D21="","",(SUM(E21)-F21)) | H21: =IF(D21="","",(D21*G21)) | N21: =IF(L21="","",($G$10)) | O21: =IF(L21="","",(SUM(M21)-N21)) | P21: =IF(L21="","",(L21*O21))
F22: =IF(D22="","",(SUM($G$9))) | G22: =IF(D22="","",(SUM(E22)-F22)) | H22: =IF(D22="","",(D22*G22)) | N22: =IF(L22="","",($G$10)) | O22: =IF(L22="","",(SUM(M22)-N22)) | P22: =IF(L22="","",(L22*O22))
B23: 소 계 | D23: =SUM(D16:D22) -> 32500 | H23: =SUM(H16:H22) -> -34408739 | J23: 소 계 | L23: =SUM(L16:L22) -> 7000 | P23: =SUM(P16:P22) -> -10430179
B26: 마 감 재 고 | G26: [단위:리터/원] | J26: 입 고 내 역 | O26: [단위:리터/원]
B27: 유종 | C27: 수량 | E27: 단가 | G27: 환산금액 | J27: 유종 | K27: 수량 | M27: 사입단가 | O27: 환산금액
B28: G | C28: 0 | E28: 0 | G28: 0 | J28: G | K28: 0 | O28: 0
B29: K | C29: =$E$9-$D$23 -> 9864 | E29: =$G$9 -> 1058.7304 | G29: =C29*E29 -> 10443317 | J29: K | K29: 20000 | M29: 1064.5 | O29: =K29*M29 -> 21290000
B30: D | C30: =$E$10-$L$23 -> 42574 | E30: =$G$10 -> 1490.0255 | G30: =C30*E30 -> 63436347 | J30: D | O30: =K30*M30 -> 0
B33: 복 합 단 가
B34: 유종 | C34: 수량 | E34: 금액 | G34: 복 합 단 가
B35: G | C35: 0 | E35: 0 | G35: 0
B36: K | C36: =$C$29+$K$29 -> 29864 | E36: =$G$29+$O$29-K36 -> 31733317 | G36: =E36/C36 -> 1062.5943
B37: D | C37: =$C$30+$K$30 -> 42574 | E37: =$G$30+$O$30 -> 63436347 | G37: =E37/C37 -> 1490.0255
B39: 재 고 현 황 | O39: [단위:리터/원]
C40: 전일 | F40: 금일 | N40: 복합단가 | O40: 증감
C41: 재고 | F41: 입고 | H41: 출고 | K41: 마 감 재 고 | M41: 재고율
B42: 휘발유 | P42: .
B43: 등 유 | C43: =SUM($E$9) -> 42364 | F43: =$K$29 -> 20000 | H43: =$D$23 -> 32500 | K43: =$C$43-$H$43+$F$43+$O$43 -> 29864 | M43: =SUM($K$43)/$D$9 -> 0.14932 | N43: =$G$36 -> 1062.5943
B44: 경 유 | C44: =SUM($E$10) -> 49574 | F44: =$K$30 -> 0 | H44: =$L$23 -> 7000 | K44: =$C$44-$H$44+$F$44+$O$44 -> 42574 | M44: =SUM($K$44)/D10 -> 0.085148 | N44: =$G$37 -> 1490.0255
G45: 복합단가의 재고수량과 단가는 보관물량 제외니 참고해주세요!

Sheet 1205
B1: ◈ KK저장소 복합단가 운영표 - 단지저장소
B5: 이 월 재 고 | G5: [단위:리터/원]
B7: 유종 | D7: 탱크용량 | E7: 재고수량 | F7: 재고율 | G7: 단가
C8: G | D8: 0 | E8: 0 | F8: 0 | G8: 0
C9: K | D9: 200000 | E9: =SUM('1204'!K43:L43) -> 29864 | F9: =E9/D9 -> 0.14932 | G9: =SUM('1204'!N43) -> 1062.5943
C10: D | D10: 500000 | E10: =SUM('1204'!K44:L44) -> 42574 | F10: =E10/D10 -> 0.085148 | G10: =SUM('1204'!N44) -> 1490.0255
B13: 출고내역(K) | G13: [단위:리터/원] | J13: 출고내역(LD) | O13: [단위:리터/원]
B14: 유종 | C14: 일반매출(사내이관 포함) | J14: 유종 | K14: 일반매출(사내이관 포함)
C15: 거래처명 | D15: 수량 | E15: 출고단가 | F15: 재고단가 | G15: 단가차액 | H15: 이익 | K15: 거래처명 | L15: 수량 | M15: 출고단가 | N15: 재고단가 | O15: 단가차액 | P15: 이익
B16: 실내 등유 | D16: 5150 | F16: =IF(D16="","",(SUM($G$9))) -> 1062.5943 | G16: =IF(D16="","",(SUM(E16)-F16)) -> -1062.5943 | H16: =IF(D16="","",(D16*G16)) -> -5472360.8 | J16: 경유 | L16: 3000 | N16: =IF(L16="","",($G$10)) -> 1490.0255 | O16: =IF(L16="","",(SUM(M16)-N16)) -> -1490.0255 | P16: =IF(L16="","",(L16*O16)) -> -4470076.6
D17: 1500 | F17: =IF(D17="","",(SUM($G$9))) -> 1062.5943 | G17: =IF(D17="","",(SUM(E17)-F17)) -> -1062.5943 | H17: =IF(D17="","",(D17*G17)) -> -1593891.5 | L17: 3000 | N17: =IF(L17="","",($G$10)) -> 1490.0255 | O17: =IF(L17="","",(SUM(M17)-N17)) -> -1490.0255 | P17: =IF(L17="","",(L17*O17)) -> -4470076.6
D18: 1000 | F18: =IF(D18="","",(SUM($G$9))) -> 1062.5943 | G18: =IF(D18="","",(SUM(E18)-F18)) -> -1062.5943 | H18: =IF(D18="","",(D18*G18)) -> -1062594.3 | L18: 900 | N18: =IF(L18="","",($G$10)) -> 1490.0255 | O18: =IF(L18="","",(SUM(M18)-N18)) -> -1490.0255 | P18: =IF(L18="","",(L18*O18)) -> -1341023
F19: =IF(D19="","",(SUM($G$9))) | G19: =IF(D19="","",(SUM(E19)-F19)) | H19: =IF(D19="","",(D19*G19)) | L19: 3000 | N19: =IF(L19="","",($G$10)) -> 1490.0255 | O19: =IF(L19="","",(SUM(M19)-N19)) -> -1490.0255 | P19: =IF(L19="","",(L19*O19)) -> -4470076.6
F20: =IF(D20="","",(SUM($G$9))) | G20: =IF(D20="","",(SUM(E20)-F20)) | H20: =IF(D20="","",(D20*G20)) | L20: 5000 | N20: =IF(L20="","",($G$10)) -> 1490.0255 | O20: =IF(L20="","",(SUM(M20)-N20)) -> -1490.0255 | P20: =IF(L20="","",(L20*O20)) -> -7450127.7
F21: =IF(D21="","",(SUM($G$9))) | G21: =IF(D21="","",(SUM(E21)-F21)) | H21: =IF(D21="","",(D21*G21)) | N21: =IF(L21="","",($G$10)) | O21: =IF(L21="","",(SUM(M21)-N21)) | P21: =IF(L21="","",(L21*O21))
F22: =IF(D22="","",(SUM($G$9))) | G22: =IF(D22="","",(SUM(E22)-F22)) | H22: =IF(D22="","",(D22*G22)) | N22: =IF(L22="","",($G$10)) | O22: =IF(L22="","",(SUM(M22)-N22)) | P22: =IF(L22="","",(L22*O22))
B23: 소 계 | D23: =SUM(D16:D22) -> 7650 | H23: =SUM(H16:H22) -> -8128846.6 | J23: 소 계 | L23: =SUM(L16:L22) -> 14900 | P23: =SUM(P16:P22) -> -22201381
B26: 마 감 재 고 | G26: [단위:리터/원] | J26: 입 고 내 역 | O26: [단위:리터/원]
B27: 유종 | C27: 수량 | E27: 단가 | G27: 환산금액 | J27: 유종 | K27: 수량 | M27: 사입단가 | O27: 환산금액
B28: G | C28: 0 | E28: 0 | G28: 0 | J28: G | K28: 0 | O28: 0
B29: K | C29: =$E$9-$D$23 -> 22214 | E29: =$G$9 -> 1062.5943 | G29: =C29*E29 -> 23604470 | J29: K | O29: =K29*M29 -> 0
B30: D | C30: =$E$10-$L$23 -> 27674 | E30: =$G$10 -> 1490.0255 | G30: =C30*E30 -> 41234967 | J30: D | O30: =K30*M30 -> 0
B33: 복 합 단 가
B34: 유종 | C34: 수량 | E34: 금액 | G34: 복 합 단 가
B35: G | C35: 0 | E35: 0 | G35: 0
B36: K | C36: =$C$29+$K$29 -> 22214 | E36: =$G$29+$O$29-K36 -> 23604470 | G36: =E36/C36 -> 1062.5943
B37: D | C37: =$C$30+$K$30 -> 27674 | E37: =$G$30+$O$30 -> 41234967 | G37: =E37/C37 -> 1490.0255
B39: 재 고 현 황 | O39: [단위:리터/원]
C40: 전일 | F40: 금일 | N40: 복합단가 | O40: 증감
C41: 재고 | F41: 입고 | H41: 출고 | K41: 마 감 재 고 | M41: 재고율
B42: 휘발유 | P42: .
B43: 등 유 | C43: =SUM($E$9) -> 29864 | F43: =$K$29 -> 0 | H43: =$D$23 -> 7650 | K43: =$C$43-$H$43+$F$43+$O$43 -> 22214 | M43: =SUM($K$43)/$D$9 -> 0.11107 | N43: =$G$36 -> 1062.5943
B44: 경 유 | C44: =SUM($E$10) -> 42574 | F44: =$K$30 -> 0 | H44: =$L$23 -> 14900 | K44: =$C$44-$H$44+$F$44+$O$44 -> 27674 | M44: =SUM($K$44)/D10 -> 0.055348 | N44: =$G$37 -> 1490.0255
G45: 복합단가의 재고수량과 단가는 보관물량 제외니 참고해주세요!

Sheet 1208
B1: ◈ KK저장소 복합단가 운영표 - 단지저장소
B5: 이 월 재 고 | G5: [단위:리터/원]
B7: 유종 | D7: 탱크용량 | E7: 재고수량 | F7: 재고율 | G7: 단가
C8: G | D8: 0 | E8: 0 | F8: 0 | G8: 0
C9: K | D9: 200000 | E9: =SUM('1205'!K43:L43) -> 22214 | F9: =E9/D9 -> 0.11107 | G9: =SUM('1205'!N43) -> 1062.5943
C10: D | D10: 500000 | E10: =SUM('1205'!K44:L44) -> 27674 | F10: =E10/D10 -> 0.055348 | G10: =SUM('1205'!N44) -> 1490.0255
B13: 출고내역(K) | G13: [단위:리터/원] | J13: 출고내역(LD) | O13: [단위:리터/원]
B14: 유종 | C14: 일반매출(사내이관 포함) | J14: 유종 | K14: 일반매출(사내이관 포함)
C15: 거래처명 | D15: 수량 | E15: 출고단가 | F15: 재고단가 | G15: 단가차액 | H15: 이익 | K15: 거래처명 | L15: 수량 | M15: 출고단가 | N15: 재고단가 | O15: 단가차액 | P15: 이익
B16: 실내 등유 | D16: 2800 | F16: =IF(D16="","",(SUM($G$9))) -> 1062.5943 | G16: =IF(D16="","",(SUM(E16)-F16)) -> -1062.5943 | H16: =IF(D16="","",(D16*G16)) -> -2975264.1 | J16: 경유 | N16: =IF(L16="","",($G$10)) | O16: =IF(L16="","",(SUM(M16)-N16)) | P16: =IF(L16="","",(L16*O16))
D17: 1000 | F17: =IF(D17="","",(SUM($G$9))) -> 1062.5943 | G17: =IF(D17="","",(SUM(E17)-F17)) -> -1062.5943 | H17: =IF(D17="","",(D17*G17)) -> -1062594.3 | N17: =IF(L17="","",($G$10)) | O17: =IF(L17="","",(SUM(M17)-N17)) | P17: =IF(L17="","",(L17*O17))
D18: 1900 | F18: =IF(D18="","",(SUM($G$9))) -> 1062.5943 | G18: =IF(D18="","",(SUM(E18)-F18)) -> -1062.5943 | H18: =IF(D18="","",(D18*G18)) -> -2018929.2 | N18: =IF(L18="","",($G$10)) | O18: =IF(L18="","",(SUM(M18)-N18)) | P18: =IF(L18="","",(L18*O18))
F19: =IF(D19="","",(SUM($G$9))) | G19: =IF(D19="","",(SUM(E19)-F19)) | H19: =IF(D19="","",(D19*G19)) | N19: =IF(L19="","",($G$10)) | O19: =IF(L19="","",(SUM(M19)-N19)) | P19: =IF(L19="","",(L19*O19))
F20: =IF(D20="","",(SUM($G$9))) | G20: =IF(D20="","",(SUM(E20)-F20)) | H20: =IF(D20="","",(D20*G20)) | N20: =IF(L20="","",($G$10)) | O20: =IF(L20="","",(SUM(M20)-N20)) | P20: =IF(L20="","",(L20*O20))
F21: =IF(D21="","",(SUM($G$9))) | G21: =IF(D21="","",(SUM(E21)-F21)) | H21: =IF(D21="","",(D21*G21)) | N21: =IF(L21="","",($G$10)) | O21: =IF(L21="","",(SUM(M21)-N21)) | P21: =IF(L21="","",(L21*O21))
F22: =IF(D22="","",(SUM($G$9))) | G22: =IF(D22="","",(SUM(E22)-F22)) | H22: =IF(D22="","",(D22*G22)) | N22: =IF(L22="","",($G$10)) | O22: =IF(L22="","",(SUM(M22)-N22)) | P22: =IF(L22="","",(L22*O22))
B23: 소 계 | D23: =SUM(D16:D22) -> 5700 | H23: =SUM(H16:H22) -> -6056787.6 | J23: 소 계 | L23: =SUM(L16:L22) -> 0 | P23: =SUM(P16:P22) -> 0
B26: 마 감 재 고 | G26: [단위:리터/원] | J26: 입 고 내 역 | O26: [단위:리터/원]
B27: 유종 | C27: 수량 | E27: 단가 | G27: 환산금액 | J27: 유종 | K27: 수량 | M27: 사입단가 | O27: 환산금액
B28: G | C28: 0 | E28: 0 | G28: 0 | J28: G | K28: 0 | O28: 0
B29: K | C29: =$E$9-$D$23 -> 16514 | E29: =$G$9 -> 1062.5943 | G29: =C29*E29 -> 17547683 | J29: K | O29: =K29*M29 -> 0
B30: D | C30: =$E$10-$L$23 -> 27674 | E30: =$G$10 -> 1490.0255 | G30: =C30*E30 -> 41234967 | J30: D | O30: =K30*M30 -> 0
B33: 복 합 단 가
B34: 유종 | C34: 수량 | E34: 금액 | G34: 복 합 단 가
B35: G | C35: 0 | E35: 0 | G35: 0
B36: K | C36: =$C$29+$K$29 -> 16514 | E36: =$G$29+$O$29-K36 -> 17547683 | G36: =E36/C36 -> 1062.5943
B37: D | C37: =$C$30+$K$30 -> 27674 | E37: =$G$30+$O$30 -> 41234967 | G37: =E37/C37 -> 1490.0255
B39: 재 고 현 황 | O39: [단위:리터/원]
C40: 전일 | F40: 금일 | N40: 복합단가 | O40: 증감
C41: 재고 | F41: 입고 | H41: 출고 | K41: 마 감 재 고 | M41: 재고율
B42: 휘발유 | P42: .
B43: 등 유 | C43: =SUM($E$9) -> 22214 | F43: =$K$29 -> 0 | H43: =$D$23 -> 5700 | K43: =$C$43-$H$43+$F$43+$O$43 -> 16514 | M43: =SUM($K$43)/$D$9 -> 0.08257 | N43: =$G$36 -> 1062.5943
B44: 경 유 | C44: =SUM($E$10) -> 27674 | F44: =$K$30 -> 0 | H44: =$L$23 -> 0 | K44: =$C$44-$H$44+$F$44+$O$44 -> 27674 | M44: =SUM($K$44)/D10 -> 0.055348 | N44: =$G$37 -> 1490.0255
G45: 복합단가의 재고수량과 단가는 보관물량 제외니 참고해주세요!

Sheet 1209
B1: ◈ KK저장소 복합단가 운영표 - 단지저장소
B5: 이 월 재 고 | G5: [단위:리터/원]
B7: 유종 | D7: 탱크용량 | E7: 재고수량 | F7: 재고율 | G7: 단가
C8: G | D8: 0 | E8: 0 | F8: 0 | G8: 0
C9: K | D9: 200000 | E9: =SUM('1208'!K43:L43) -> 16514 | F9: =E9/D9 -> 0.08257 | G9: =SUM('1208'!N43) -> 1062.5943
C10: D | D10: 500000 | E10: =SUM('1208'!K44:L44) -> 27674 | F10: =E10/D10 -> 0.055348 | G10: =SUM('1208'!N44) -> 1490.0255
B13: 출고내역(K) | G13: [단위:리터/원] | J13: 출고내역(LD) | O13: [단위:리터/원]
B14: 유종 | C14: 일반매출(사내이관 포함) | J14: 유종 | K14: 일반매출(사내이관 포함)
C15: 거래처명 | D15: 수량 | E15: 출고단가 | F15: 재고단가 | G15: 단가차액 | H15: 이익 | K15: 거래처명 | L15: 수량 | M15: 출고단가 | N15: 재고단가 | O15: 단가차액 | P15: 이익
B16: 실내 등유 | D16: 2000 | F16: =IF(D16="","",(SUM($G$9))) -> 1062.5943 | G16: =IF(D16="","",(SUM(E16)-F16)) -> -1062.5943 | H16: =IF(D16="","",(D16*G16)) -> -2125188.6 | J16: 경유 | L16: 3000 | N16: =IF(L16="","",($G$10)) -> 1490.0255 | O16: =IF(L16="","",(SUM(M16)-N16)) -> -1490.0255 | P16: =IF(L16="","",(L16*O16)) -> -4470076.6
D17: 1500 | F17: =IF(D17="","",(SUM($G$9))) -> 1062.5943 | G17: =IF(D17="","",(SUM(E17)-F17)) -> -1062.5943 | H17: =IF(D17="","",(D17*G17)) -> -1593891.5 | L17: 3000 | N17: =IF(L17="","",($G$10)) -> 1490.0255 | O17: =IF(L17="","",(SUM(M17)-N17)) -> -1490.0255 | P17: =IF(L17="","",(L17*O17)) -> -4470076.6
F18: =IF(D18="","",(SUM($G$9))) | G18: =IF(D18="","",(SUM(E18)-F18)) | H18: =IF(D18="","",(D18*G18)) | L18: 500 | N18: =IF(L18="","",($G$10)) -> 1490.0255 | O18: =IF(L18="","",(SUM(M18)-N18)) -> -1490.0255 | P18: =IF(L18="","",(L18*O18)) -> -745012.77
F19: =IF(D19="","",(SUM($G$9))) | G19: =IF(D19="","",(SUM(E19)-F19)) | H19: =IF(D19="","",(D19*G19)) | N19: =IF(L19="","",($G$10)) | O19: =IF(L19="","",(SUM(M19)-N19)) | P19: =IF(L19="","",(L19*O19))
F20: =IF(D20="","",(SUM($G$9))) | G20: =IF(D20="","",(SUM(E20)-F20)) | H20: =IF(D20="","",(D20*G20)) | N20: =IF(L20="","",($G$10)) | O20: =IF(L20="","",(SUM(M20)-N20)) | P20: =IF(L20="","",(L20*O20))
F21: =IF(D21="","",(SUM($G$9))) | G21: =IF(D21="","",(SUM(E21)-F21)) | H21: =IF(D21="","",(D21*G21)) | N21: =IF(L21="","",($G$10)) | O21: =IF(L21="","",(SUM(M21)-N21)) | P21: =IF(L21="","",(L21*O21))
F22: =IF(D22="","",(SUM($G$9))) | G22: =IF(D22="","",(SUM(E22)-F22)) | H22: =IF(D22="","",(D22*G22)) | N22: =IF(L22="","",($G$10)) | O22: =IF(L22="","",(SUM(M22)-N22)) | P22: =IF(L22="","",(L22*O22))
B23: 소 계 | D23: =SUM(D16:D22) -> 3500 | H23: =SUM(H16:H22) -> -3719080.1 | J23: 소 계 | L23: =SUM(L16:L22) -> 6500 | P23: =SUM(P16:P22) -> -9685166
B26: 마 감 재 고 | G26: [단위:리터/원] | J26: 입 고 내 역 | O26: [단위:리터/원]
B27: 유종 | C27: 수량 | E27: 단가 | G27: 환산금액 | J27: 유종 | K27: 수량 | M27: 사입단가 | O27: 환산금액
B28: G | C28: 0 | E28: 0 | G28: 0 | J28: G | K28: 0 | O28: 0
B29: K | C29: =$E$9-$D$23 -> 13014 | E29: =$G$9 -> 1062.5943 | G29: =C29*E29 -> 13828603 | J29: K | O29: =K29*M29 -> 0
B30: D | C30: =$E$10-$L$23 -> 21174 | E30: =$G$10 -> 1490.0255 | G30: =C30*E30 -> 31549801 | J30: D | K30: 32000 | M30: 1455.1 | O30: =K30*M30 -> 46563200
B33: 복 합 단 가
B34: 유종 | C34: 수량 | E34: 금액 | G34: 복 합 단 가
B35: G | C35: 0 | E35: 0 | G35: 0
B36: K | C36: =$C$29+$K$29 -> 13014 | E36: =$G$29+$O$29-K36 -> 13828603 | G36: =E36/C36 -> 1062.5943
B37: D | C37: =$C$30+$K$30 -> 53174 | E37: =$G$30+$O$30 -> 78113001 | G37: =E37/C37 -> 1469.0074
B39: 재 고 현 황 | O39: [단위:리터/원]
C40: 전일 | F40: 금일 | N40: 복합단가 | O40: 증감
C41: 재고 | F41: 입고 | H41: 출고 | K41: 마 감 재 고 | M41: 재고율
B42: 휘발유 | P42: .
B43: 등 유 | C43: =SUM($E$9) -> 16514 | F43: =$K$29 -> 0 | H43: =$D$23 -> 3500 | K43: =$C$43-$H$43+$F$43+$O$43 -> 13014 | M43: =SUM($K$43)/$D$9 -> 0.06507 | N43: =$G$36 -> 1062.5943
B44: 경 유 | C44: =SUM($E$10) -> 27674 | F44: =$K$30 -> 32000 | H44: =$L$23 -> 6500 | K44: =$C$44-$H$44+$F$44+$O$44 -> 53174 | M44: =SUM($K$44)/D10 -> 0.106348 | N44: =$G$37 -> 1469.0074
G45: 복합단가의 재고수량과 단가는 보관물량 제외니 참고해주세요!

Sheet 1210
B1: ◈ KK저장소 복합단가 운영표 - 단지저장소
B5: 이 월 재 고 | G5: [단위:리터/원]
B7: 유종 | D7: 탱크용량 | E7: 재고수량 | F7: 재고율 | G7: 단가
C8: G | D8: 0 | E8: 0 | F8: 0 | G8: 0
C9: K | D9: 200000 | E9: =SUM('1209'!K43:L43) -> 13014 | F9: =E9/D9 -> 0.06507 | G9: =SUM('1209'!N43) -> 1062.5943
C10: D | D10: 500000 | E10: =SUM('1209'!K44:L44) -> 53174 | F10: =E10/D10 -> 0.106348 | G10: =SUM('1209'!N44) -> 1469.0074
B13: 출고내역(K) | G13: [단위:리터/원] | J13: 출고내역(LD) | O13: [단위:리터/원]
B14: 유종 | C14: 일반매출(사내이관 포함) | J14: 유종 | K14: 일반매출(사내이관 포함)
C15: 거래처명 | D15: 수량 | E15: 출고단가 | F15: 재고단가 | G15: 단가차액 | H15: 이익 | K15: 거래처명 | L15: 수량 | M15: 출고단가 | N15: 재고단가 | O15: 단가차액 | P15: 이익
B16: 실내 등유 | D16: 1300 | F16: =IF(D16="","",(SUM($G$9))) -> 1062.5943 | G16: =IF(D16="","",(SUM(E16)-F16)) -> -1062.5943 | H16: =IF(D16="","",(D16*G16)) -> -1381372.6 | J16: 경유 | L16: 4000 | N16: =IF(L16="","",($G$10)) -> 1469.0074 | O16: =IF(L16="","",(SUM(M16)-N16)) -> -1469.0074 | P16: =IF(L16="","",(L16*O16)) -> -5876029.7
D17: 1000 | F17: =IF(D17="","",(SUM($G$9))) -> 1062.5943 | G17: =IF(D17="","",(SUM(E17)-F17)) -> -1062.5943 | H17: =IF(D17="","",(D17*G17)) -> -1062594.3 | N17: =IF(L17="","",($G$10)) | O17: =IF(L17="","",(SUM(M17)-N17)) | P17: =IF(L17="","",(L17*O17))
F18: =IF(D18="","",(SUM($G$9))) | G18: =IF(D18="","",(SUM(E18)-F18)) | H18: =IF(D18="","",(D18*G18)) | N18: =IF(L18="","",($G$10)) | O18: =IF(L18="","",(SUM(M18)-N18)) | P18: =IF(L18="","",(L18*O18))
F19: =IF(D19="","",(SUM($G$9))) | G19: =IF(D19="","",(SUM(E19)-F19)) | H19: =IF(D19="","",(D19*G19)) | N19: =IF(L19="","",($G$10)) | O19: =IF(L19="","",(SUM(M19)-N19)) | P19: =IF(L19="","",(L19*O19))
F20: =IF(D20="","",(SUM($G$9))) | G20: =IF(D20="","",(SUM(E20)-F20)) | H20: =IF(D20="","",(D20*G20)) | N20: =IF(L20="","",($G$10)) | O20: =IF(L20="","",(SUM(M20)-N20)) | P20: =IF(L20="","",(L20*O20))
F21: =IF(D21="","",(SUM($G$9))) | G21: =IF(D21="","",(SUM(E21)-F21)) | H21: =IF(D21="","",(D21*G21)) | N21: =IF(L21="","",($G$10)) | O21: =IF(L21="","",(SUM(M21)-N21)) | P21: =IF(L21="","",(L21*O21))
F22: =IF(D22="","",(SUM($G$9))) | G22: =IF(D22="","",(SUM(E22)-F22)) | H22: =IF(D22="","",(D22*G22)) | N22: =IF(L22="","",($G$10)) | O22: =IF(L22="","",(SUM(M22)-N22)) | P22: =IF(L22="","",(L22*O22))
B23: 소 계 | D23: =SUM(D16:D22) -> 2300 | H23: =SUM(H16:H22) -> -2443966.9 | J23: 소 계 | L23: =SUM(L16:L22) -> 4000 | P23: =SUM(P16:P22) -> -5876029.7
B26: 마 감 재 고 | G26: [단위:리터/원] | J26: 입 고 내 역 | O26: [단위:리터/원]
B27: 유종 | C27: 수량 | E27: 단가 | G27: 환산금액 | J27: 유종 | K27: 수량 | M27: 사입단가 | O27: 환산금액
B28: G | C28: 0 | E28: 0 | G28: 0 | J28: G | K28: 0 | O28: 0
B29: K | C29: =$E$9-$D$23 -> 10714 | E29: =$G$9 -> 1062.5943 | G29: =C29*E29 -> 11384636 | J29: K | K29: 32000 | M29: 1023.1 | O29: =K29*M29 -> 32739200
B30: D | C30: =$E$10-$L$23 -> 49174 | E30: =$G$10 -> 1469.0074 | G30: =C30*E30 -> 72236971 | J30: D | O30: =K30*M30 -> 0
B33: 복 합 단 가
B34: 유종 | C34: 수량 | E34: 금액 | G34: 복 합 단 가
B35: G | C35: 0 | E35: 0 | G35: 0
B36: K | C36: =$C$29+$K$29 -> 42714 | E36: =$G$29+$O$29-K36 -> 44123836 | G36: =E36/C36 -> 1033.0064
B37: D | C37: =$C$30+$K$30 -> 49174 | E37: =$G$30+$O$30 -> 72236971 | G37: =E37/C37 -> 1469.0074
B39: 재 고 현 황 | O39: [단위:리터/원]
C40: 전일 | F40: 금일 | N40: 복합단가 | O40: 증감
C41: 재고 | F41: 입고 | H41: 출고 | K41: 마 감 재 고 | M41: 재고율
B42: 휘발유 | P42: .
B43: 등 유 | C43: =SUM($E$9) -> 13014 | F43: =$K$29 -> 32000 | H43: =$D$23 -> 2300 | K43: =$C$43-$H$43+$F$43+$O$43 -> 42714 | M43: =SUM($K$43)/$D$9 -> 0.21357 | N43: =$G$36 -> 1033.0064
B44: 경 유 | C44: =SUM($E$10) -> 53174 | F44: =$K$30 -> 0 | H44: =$L$23 -> 4000 | K44: =$C$44-$H$44+$F$44+$O$44 -> 49174 | M44: =SUM($K$44)/D10 -> 0.098348 | N44: =$G$37 -> 1469.0074
G45: 복합단가의 재고수량과 단가는 보관물량 제외니 참고해주세요!

Sheet 1211
B1: ◈ KK저장소 복합단가 운영표 - 단지저장소
B5: 이 월 재 고 | G5: [단위:리터/원]
B7: 유종 | D7: 탱크용량 | E7: 재고수량 | F7: 재고율 | G7: 단가
C8: G | D8: 0 | E8: 0 | F8: 0 | G8: 0
C9: K | D9: 200000 | E9: =SUM('1210'!K43:L43) -> 42714 | F9: =E9/D9 -> 0.21357 | G9: =SUM('1210'!N43) -> 1033.0064
C10: D | D10: 500000 | E10: =SUM('1210'!K44:L44) -> 49174 | F10: =E10/D10 -> 0.098348 | G10: =SUM('1210'!N44) -> 1469.0074
B13: 출고내역(K) | G13: [단위:리터/원] | J13: 출고내역(LD) | O13: [단위:리터/원]
B14: 유종 | C14: 일반매출(사내이관 포함) | J14: 유종 | K14: 일반매출(사내이관 포함)
C15: 거래처명 | D15: 수량 | E15: 출고단가 | F15: 재고단가 | G15: 단가차액 | H15: 이익 | K15: 거래처명 | L15: 수량 | M15: 출고단가 | N15: 재고단가 | O15: 단가차액 | P15: 이익
B16: 실내 등유 | D16: 4600 | F16: =IF(D16="","",(SUM($G$9))) -> 1033.0064 | G16: =IF(D16="","",(SUM(E16)-F16)) -> -1033.0064 | H16: =IF(D16="","",(D16*G16)) -> -4751829.5 | J16: 경유 | L16: 3000 | N16: =IF(L16="","",($G$10)) -> 1469.0074 | O16: =IF(L16="","",(SUM(M16)-N16)) -> -1469.0074 | P16: =IF(L16="","",(L16*O16)) -> -4407022.3
D17: 1000 | F17: =IF(D17="","",(SUM($G$9))) -> 1033.0064 | G17: =IF(D17="","",(SUM(E17)-F17)) -> -1033.0064 | H17: =IF(D17="","",(D17*G17)) -> -1033006.4 | L17: 3000 | N17: =IF(L17="","",($G$10)) -> 1469.0074 | O17: =IF(L17="","",(SUM(M17)-N17)) -> -1469.0074 | P17: =IF(L17="","",(L17*O17)) -> -4407022.3
F18: =IF(D18="","",(SUM($G$9))) | G18: =IF(D18="","",(SUM(E18)-F18)) | H18: =IF(D18="","",(D18*G18)) | N18: =IF(L18="","",($G$10)) | O18: =IF(L18="","",(SUM(M18)-N18)) | P18: =IF(L18="","",(L18*O18))
F19: =IF(D19="","",(SUM($G$9))) | G19: =IF(D19="","",(SUM(E19)-F19)) | H19: =IF(D19="","",(D19*G19)) | N19: =IF(L19="","",($G$10)) | O19: =IF(L19="","",(SUM(M19)-N19)) | P19: =IF(L19="","",(L19*O19))
F20: =IF(D20="","",(SUM($G$9))) | G20: =IF(D20="","",(SUM(E20)-F20)) | H20: =IF(D20="","",(D20*G20)) | N20: =IF(L20="","",($G$10)) | O20: =IF(L20="","",(SUM(M20)-N20)) | P20: =IF(L20="","",(L20*O20))
F21: =IF(D21="","",(SUM($G$9))) | G21: =IF(D21="","",(SUM(E21)-F21)) | H21: =IF(D21="","",(D21*G21)) | N21: =IF(L21="","",($G$10)) | O21: =IF(L21="","",(SUM(M21)-N21)) | P21: =IF(L21="","",(L21*O21))
F22: =IF(D22="","",(SUM($G$9))) | G22: =IF(D22="","",(SUM(E22)-F22)) | H22: =IF(D22="","",(D22*G22)) | N22: =IF(L22="","",($G$10)) | O22: =IF(L22="","",(SUM(M22)-N22)) | P22: =IF(L22="","",(L22*O22))
B23: 소 계 | D23: =SUM(D16:D22) -> 5600 | H23: =SUM(H16:H22) -> -5784835.9 | J23: 소 계 | L23: =SUM(L16:L22) -> 6000 | P23: =SUM(P16:P22) -> -8814044.5
B26: 마 감 재 고 | G26: [단위:리터/원] | J26: 입 고 내 역 | O26: [단위:리터/원]
B27: 유종 | C27: 수량 | E27: 단가 | G27: 환산금액 | J27: 유종 | K27: 수량 | M27: 사입단가 | O27: 환산금액
B28: G | C28: 0 | E28: 0 | G28: 0 | J28: G | K28: 0 | O28: 0
B29: K | C29: =$E$9-$D$23 -> 37114 | E29: =$G$9 -> 1033.0064 | G29: =C29*E29 -> 38339000 | J29: K | O29: =K29*M29 -> 0
B30: D | C30: =$E$10-$L$23 -> 43174 | E30: =$G$10 -> 1469.0074 | G30: =C30*E30 -> 63422927 | J30: D | K30: 32000 | M30: 1455.1 | O30: =K30*M30 -> 46563200
B33: 복 합 단 가
B34: 유종 | C34: 수량 | E34: 금액 | G34: 복 합 단 가
B35: G | C35: 0 | E35: 0 | G35: 0
B36: K | C36: =$C$29+$K$29 -> 37114 | E36: =$G$29+$O$29-K36 -> 38339000 | G36: =E36/C36 -> 1033.0064
B37: D | C37: =$C$30+$K$30 -> 75174 | E37: =$G$30+$O$30 -> 1.0998613e+08 | G37: =E37/C37 -> 1463.0873
B39: 재 고 현 황 | O39: [단위:리터/원]
C40: 전일 | F40: 금일 | N40: 복합단가 | O40: 증감
C41: 재고 | F41: 입고 | H41: 출고 | K41: 마 감 재 고 | M41: 재고율
B42: 휘발유 | P42: .
B43: 등 유 | C43: =SUM($E$9) -> 42714 | F43: =$K$29 -> 0 | H43: =$D$23 -> 5600 | K43: =$C$43-$H$43+$F$43+$O$43 -> 37114 | M43: =SUM($K$43)/$D$9 -> 0.18557 | N43: =$G$36 -> 1033.0064
B44: 경 유 | C44: =SUM($E$10) -> 49174 | F44: =$K$30 -> 32000 | H44: =$L$23 -> 6000 | K44: =$C$44-$H$44+$F$44+$O$44 -> 75174 | M44: =SUM($K$44)/D10 -> 0.150348 | N44: =$G$37 -> 1463.0873
G45: 복합단가의 재고수량과 단가는 보관물량 제외니 참고해주세요!

Sheet 1212
B1: ◈ KK저장소 복합단가 운영표 - 단지저장소
B5: 이 월 재 고 | G5: [단위:리터/원]
B7: 유종 | D7: 탱크용량 | E7: 재고수량 | F7: 재고율 | G7: 단가
C8: G | D8: 0 | E8: 0 | F8: 0 | G8: 0
C9: K | D9: 200000 | E9: =SUM('1211'!K43:L43) -> 37114 | F9: =E9/D9 -> 0.18557 | G9: =SUM('1211'!N43) -> 1033.0064
C10: D | D10: 500000 | E10: =SUM('1211'!K44:L44) -> 75174 | F10: =E10/D10 -> 0.150348 | G10: =SUM('1211'!N44) -> 1463.0873
B13: 출고내역(K) | G13: [단위:리터/원] | J13: 출고내역(LD) | O13: [단위:리터/원]
B14: 유종 | C14: 일반매출(사내이관 포함) | J14: 유종 | K14: 일반매출(사내이관 포함)
C15: 거래처명 | D15: 수량 | E15: 출고단가 | F15: 재고단가 | G15: 단가차액 | H15: 이익 | K15: 거래처명 | L15: 수량 | M15: 출고단가 | N15: 재고단가 | O15: 단가차액 | P15: 이익
B16: 실내 등유 | D16: 2300 | F16: =IF(D16="","",(SUM($G$9))) -> 1033.0064 | G16: =IF(D16="","",(SUM(E16)-F16)) -> -1033.0064 | H16: =IF(D16="","",(D16*G16)) -> -2375914.7 | J16: 경유 | L16: 6000 | N16: =IF(L16="","",($G$10)) -> 1463.0873 | O16: =IF(L16="","",(SUM(M16)-N16)) -> -1463.0873 | P16: =IF(L16="","",(L16*O16)) -> -8778523.9
D17: 1700 | F17: =IF(D17="","",(SUM($G$9))) -> 1033.0064 | G17: =IF(D17="","",(SUM(E17)-F17)) -> -1033.0064 | H17: =IF(D17="","",(D17*G17)) -> -1756110.9 | L17: 2000 | N17: =IF(L17="","",($G$10)) -> 1463.0873 | O17: =IF(L17="","",(SUM(M17)-N17)) -> -1463.0873 | P17: =IF(L17="","",(L17*O17)) -> -2926174.6
F18: =IF(D18="","",(SUM($G$9))) | G18: =IF(D18="","",(SUM(E18)-F18)) | H18: =IF(D18="","",(D18*G18)) | L18: 800 | N18: =IF(L18="","",($G$10)) -> 1463.0873 | O18: =IF(L18="","",(SUM(M18)-N18)) -> -1463.0873 | P18: =IF(L18="","",(L18*O18)) -> -1170469.9
F19: =IF(D19="","",(SUM($G$9))) | G19: =IF(D19="","",(SUM(E19)-F19)) | H19: =IF(D19="","",(D19*G19)) | N19: =IF(L19="","",($G$10)) | O19: =IF(L19="","",(SUM(M19)-N19)) | P19: =IF(L19="","",(L19*O19))
F20: =IF(D20="","",(SUM($G$9))) | G20: =IF(D20="","",(SUM(E20)-F20)) | H20: =IF(D20="","",(D20*G20)) | N20: =IF(L20="","",($G$10)) | O20: =IF(L20="","",(SUM(M20)-N20)) | P20: =IF(L20="","",(L20*O20))
F21: =IF(D21="","",(SUM($G$9))) | G21: =IF(D21="","",(SUM(E21)-F21)) | H21: =IF(D21="","",(D21*G21)) | N21: =IF(L21="","",($G$10)) | O21: =IF(L21="","",(SUM(M21)-N21)) | P21: =IF(L21="","",(L21*O21))
F22: =IF(D22="","",(SUM($G$9))) | G22: =IF(D22="","",(SUM(E22)-F22)) | H22: =IF(D22="","",(D22*G22)) | N22: =IF(L22="","",($G$10)) | O22: =IF(L22="","",(SUM(M22)-N22)) | P22: =IF(L22="","",(L22*O22))
B23: 소 계 | D23: =SUM(D16:D22) -> 4000 | H23: =SUM(H16:H22) -> -4132025.6 | J23: 소 계 | L23: =SUM(L16:L22) -> 8800 | P23: =SUM(P16:P22) -> -12875168
B26: 마 감 재 고 | G26: [단위:리터/원] | J26: 입 고 내 역 | O26: [단위:리터/원]
B27: 유종 | C27: 수량 | E27: 단가 | G27: 환산금액 | J27: 유종 | K27: 수량 | M27: 사입단가 | O27: 환산금액
B28: G | C28: 0 | E28: 0 | G28: 0 | J28: G | K28: 0 | O28: 0
B29: K | C29: =$E$9-$D$23 -> 33114 | E29: =$G$9 -> 1033.0064 | G29: =C29*E29 -> 34206974 | J29: K | K29: 32000 | M29: 999.5 | O29: =K29*M29 -> 31984000
B30: D | C30: =$E$10-$L$23 -> 66374 | E30: =$G$10 -> 1463.0873 | G30: =C30*E30 -> 97110958 | J30: D | K30: 32000 | M30: 1488.3224 | O30: =K30*M30 -> 47626315
B33: 복 합 단 가
B34: 유종 | C34: 수량 | E34: 금액 | G34: 복 합 단 가
B35: G | C35: 0 | E35: 0 | G35: 0
B36: K | C36: =$C$29+$K$29 -> 65114 | E36: =$G$29+$O$29-K36 -> 66190974 | G36: =E36/C36 -> 1016.5398
B37: D | C37: =$C$30+$K$30 -> 98374 | E37: =$G$30+$O$30 -> 1.4473727e+08 | G37: =E37/C37 -> 1471.296
B39: 재 고 현 황 | O39: [단위:리터/원]
C40: 전일 | F40: 금일 | N40: 복합단가 | O40: 증감
C41: 재고 | F41: 입고 | H41: 출고 | K41: 마 감 재 고 | M41: 재고율
B42: 휘발유 | P42: .
B43: 등 유 | C43: =SUM($E$9) -> 37114 | F43: =$K$29 -> 32000 | H43: =$D$23 -> 4000 | K43: =$C$43-$H$43+$F$43+$O$43 -> 65114 | M43: =SUM($K$43)/$D$9 -> 0.32557 | N43: =$G$36 -> 1016.5398
B44: 경 유 | C44: =SUM($E$10) -> 75174 | F44: =$K$30 -> 32000 | H44: =$L$23 -> 8800 | K44: =$C$44-$H$44+$F$44+$O$44 -> 98374 | M44: =SUM($K$44)/D10 -> 0.196748 | N44: =$G$37 -> 1471.296
G45: 복합단가의 재고수량과 단가는 보관물량 제외니 참고해주세요!

Sheet 1213
B1: ◈ KK저장소 복합단가 운영표 - 단지저장소
B5: 이 월 재 고 | G5: [단위:리터/원]
B7: 유종 | D7: 탱크용량 | E7: 재고수량 | F7: 재고율 | G7: 단가
C8: G | D8: 0 | E8: 0 | F8: 0 | G8: 0
C9: K | D9: 200000 | E9: =SUM('1212'!K43:L43) -> 65114 | F9: =E9/D9 -> 0.32557 | G9: =SUM('1212'!N43) -> 1016.5398
C10: D | D10: 500000 | E10: =SUM('1212'!K44:L44) -> 98374 | F10: =E10/D10 -> 0.196748 | G10: =SUM('1212'!N44) -> 1471.296
B13: 출고내역(K) | G13: [단위:리터/원] | J13: 출고내역(LD) | O13: [단위:리터/원]
B14: 유종 | C14: 일반매출(사내이관 포함) | J14: 유종 | K14: 일반매출(사내이관 포함)
C15: 거래처명 | D15: 수량 | E15: 출고단가 | F15: 재고단가 | G15: 단가차액 | H15: 이익 | K15: 거래처명 | L15: 수량 | M15: 출고단가 | N15: 재고단가 | O15: 단가차액 | P15: 이익
B16: 실내 등유 | D16: 2000 | F16: =IF(D16="","",(SUM($G$9))) -> 1016.5398 | G16: =IF(D16="","",(SUM(E16)-F16)) -> -1016.5398 | H16: =IF(D16="","",(D16*G16)) -> -2033079.6 | J16: 경유 | L16: 1000 | N16: =IF(L16="","",($G$10)) -> 1471.296 | O16: =IF(L16="","",(SUM(M16)-N16)) -> -1471.296 | P16: =IF(L16="","",(L16*O16)) -> -1471296
F17: =IF(D17="","",(SUM($G$9))) | G17: =IF(D17="","",(SUM(E17)-F17)) | H17: =IF(D17="","",(D17*G17)) | N17: =IF(L17="","",($G$10)) | O17: =IF(L17="","",(SUM(M17)-N17)) | P17: =IF(L17="","",(L17*O17))
F18: =IF(D18="","",(SUM($G$9))) | G18: =IF(D18="","",(SUM(E18)-F18)) | H18: =IF(D18="","",(D18*G18)) | N18: =IF(L18="","",($G$10)) | O18: =IF(L18="","",(SUM(M18)-N18)) | P18: =IF(L18="","",(L18*O18))
F19: =IF(D19="","",(SUM($G$9))) | G19: =IF(D19="","",(SUM(E19)-F19)) | H19: =IF(D19="","",(D19*G19)) | N19: =IF(L19="","",($G$10)) | O19: =IF(L19="","",(SUM(M19)-N19)) | P19: =IF(L19="","",(L19*O19))
F20: =IF(D20="","",(SUM($G$9))) | G20: =IF(D20="","",(SUM(E20)-F20)) | H20: =IF(D20="","",(D20*G20)) | N20: =IF(L20="","",($G$10)) | O20: =IF(L20="","",(SUM(M20)-N20)) | P20: =IF(L20="","",(L20*O20))
F21: =IF(D21="","",(SUM($G$9))) | G21: =IF(D21="","",(SUM(E21)-F21)) | H21: =IF(D21="","",(D21*G21)) | N21: =IF(L21="","",($G$10)) | O21: =IF(L21="","",(SUM(M21)-N21)) | P21: =IF(L21="","",(L21*O21))
F22: =IF(D22="","",(SUM($G$9))) | G22: =IF(D22="","",(SUM(E22)-F22)) | H22: =IF(D22="","",(D22*G22)) | N22: =IF(L22="","",($G$10)) | O22: =IF(L22="","",(SUM(M22)-N22)) | P22: =IF(L22="","",(L22*O22))
B23: 소 계 | D23: =SUM(D16:D22) -> 2000 | H23: =SUM(H16:H22) -> -2033079.6 | J23: 소 계 | L23: =SUM(L16:L22) -> 1000 | P23: =SUM(P16:P22) -> -1471296
B26: 마 감 재 고 | G26: [단위:리터/원] | J26: 입 고 내 역 | O26: [단위:리터/원]
B27: 유종 | C27: 수량 | E27: 단가 | G27: 환산금액 | J27: 유종 | K27: 수량 | M27: 사입단가 | O27: 환산금액
B28: G | C28: 0 | E28: 0 | G28: 0 | J28: G | K28: 0 | O28: 0
B29: K | C29: =$E$9-$D$23 -> 63114 | E29: =$G$9 -> 1016.5398 | G29: =C29*E29 -> 64157894 | J29: K | O29: =K29*M29 -> 0
B30: D | C30: =$E$10-$L$23 -> 97374 | E30: =$G$10 -> 1471.296 | G30: =C30*E30 -> 1.4326598e+08 | J30: D | O30: =K30*M30 -> 0
B33: 복 합 단 가
B34: 유종 | C34: 수량 | E34: 금액 | G34: 복 합 단 가
B35: G | C35: 0 | E35: 0 | G35: 0
B36: K | C36: =$C$29+$K$29 -> 63114 | E36: =$G$29+$O$29-K36 -> 64157894 | G36: =E36/C36 -> 1016.5398
B37: D | C37: =$C$30+$K$30 -> 97374 | E37: =$G$30+$O$30 -> 1.4326598e+08 | G37: =E37/C37 -> 1471.296
B39: 재 고 현 황 | O39: [단위:리터/원]
C40: 전일 | F40: 금일 | N40: 복합단가 | O40: 증감
C41: 재고 | F41: 입고 | H41: 출고 | K41: 마 감 재 고 | M41: 재고율
B42: 휘발유 | P42: .
B43: 등 유 | C43: =SUM($E$9) -> 65114 | F43: =$K$29 -> 0 | H43: =$D$23 -> 2000 | K43: =$C$43-$H$43+$F$43+$O$43 -> 63114 | M43: =SUM($K$43)/$D$9 -> 0.31557 | N43: =$G$36 -> 1016.5398
B44: 경 유 | C44: =SUM($E$10) -> 98374 | F44: =$K$30 -> 0 | H44: =$L$23 -> 1000 | K44: =$C$44-$H$44+$F$44+$O$44 -> 97374 | M44: =SUM($K$44)/D10 -> 0.194748 | N44: =$G$37 -> 1471.296
G45: 복합단가의 재고수량과 단가는 보관물량 제외니 참고해주세요!

Sheet 1215
B1: ◈ KK저장소 복합단가 운영표 - 단지저장소
B5: 이 월 재 고 | G5: [단위:리터/원]
B7: 유종 | D7: 탱크용량 | E7: 재고수량 | F7: 재고율 | G7: 단가
C8: G | D8: 0 | E8: 0 | F8: 0 | G8: 0
C9: K | D9: 200000 | E9: =SUM('1213'!K43:L43) -> 63114 | F9: =E9/D9 -> 0.31557 | G9: =SUM('1213'!N43) -> 1016.5398
C10: D | D10: 500000 | E10: =SUM('1213'!K44:L44) -> 97374 | F10: =E10/D10 -> 0.194748 | G10: =SUM('1213'!N44) -> 1471.296
B13: 출고내역(K) | G13: [단위:리터/원] | J13: 출고내역(LD) | O13: [단위:리터/원]
B14: 유종 | C14: 일반매출(사내이관 포함) | J14: 유종 | K14: 일반매출(사내이관 포함)
C15: 거래처명 | D15: 수량 | E15: 출고단가 | F15: 재고단가 | G15: 단가차액 | H15: 이익 | K15: 거래처명 | L15: 수량 | M15: 출고단가 | N15: 재고단가 | O15: 단가차액 | P15: 이익
B16: 실내 등유 | D16: 1900 | F16: =IF(D16="","",(SUM($G$9))) -> 1016.5398 | G16: =IF(D16="","",(SUM(E16)-F16)) -> -1016.5398 | H16: =IF(D16="","",(D16*G16)) -> -1931425.7 | J16: 경유 | L16: 3000 | N16: =IF(L16="","",($G$10)) -> 1471.296 | O16: =IF(L16="","",(SUM(M16)-N16)) -> -1471.296 | P16: =IF(L16="","",(L16*O16)) -> -4413888
D17: 1500 | F17: =IF(D17="","",(SUM($G$9))) -> 1016.5398 | G17: =IF(D17="","",(SUM(E17)-F17)) -> -1016.5398 | H17: =IF(D17="","",(D17*G17)) -> -1524809.7 | L17: 1000 | N17: =IF(L17="","",($G$10)) -> 1471.296 | O17: =IF(L17="","",(SUM(M17)-N17)) -> -1471.296 | P17: =IF(L17="","",(L17*O17)) -> -1471296
F18: =IF(D18="","",(SUM($G$9))) | G18: =IF(D18="","",(SUM(E18)-F18)) | H18: =IF(D18="","",(D18*G18)) | N18: =IF(L18="","",($G$10)) | O18: =IF(L18="","",(SUM(M18)-N18)) | P18: =IF(L18="","",(L18*O18))
F19: =IF(D19="","",(SUM($G$9))) | G19: =IF(D19="","",(SUM(E19)-F19)) | H19: =IF(D19="","",(D19*G19)) | N19: =IF(L19="","",($G$10)) | O19: =IF(L19="","",(SUM(M19)-N19)) | P19: =IF(L19="","",(L19*O19))
F20: =IF(D20="","",(SUM($G$9))) | G20: =IF(D20="","",(SUM(E20)-F20)) | H20: =IF(D20="","",(D20*G20)) | N20: =IF(L20="","",($G$10)) | O20: =IF(L20="","",(SUM(M20)-N20)) | P20: =IF(L20="","",(L20*O20))
F21: =IF(D21="","",(SUM($G$9))) | G21: =IF(D21="","",(SUM(E21)-F21)) | H21: =IF(D21="","",(D21*G21)) | N21: =IF(L21="","",($G$10)) | O21: =IF(L21="","",(SUM(M21)-N21)) | P21: =IF(L21="","",(L21*O21))
F22: =IF(D22="","",(SUM($G$9))) | G22: =IF(D22="","",(SUM(E22)-F22)) | H22: =IF(D22="","",(D22*G22)) | N22: =IF(L22="","",($G$10)) | O22: =IF(L22="","",(SUM(M22)-N22)) | P22: =IF(L22="","",(L22*O22))
B23: 소 계 | D23: =SUM(D16:D22) -> 3400 | H23: =SUM(H16:H22) -> -3456235.4 | J23: 소 계 | L23: =SUM(L16:L22) -> 4000 | P23: =SUM(P16:P22) -> -5885184
B26: 마 감 재 고 | G26: [단위:리터/원] | J26: 입 고 내 역 | O26: [단위:리터/원]
B27: 유종 | C27: 수량 | E27: 단가 | G27: 환산금액 | J27: 유종 | K27: 수량 | M27: 사입단가 | O27: 환산금액
B28: G | C28: 0 | E28: 0 | G28: 0 | J28: G | K28: 0 | O28: 0
B29: K | C29: =$E$9-$D$23 -> 59714 | E29: =$G$9 -> 1016.5398 | G29: =C29*E29 -> 60701659 | J29: K | K29: 32000 | M29: 999.5 | O29: =K29*M29 -> 31984000
B30: D | C30: =$E$10-$L$23 -> 93374 | E30: =$G$10 -> 1471.296 | G30: =C30*E30 -> 1.3738079e+08 | J30: D | O30: =K30*M30 -> 0
B33: 복 합 단 가
B34: 유종 | C34: 수량 | E34: 금액 | G34: 복 합 단 가
B35: G | C35: 0 | E35: 0 | G35: 0
B36: K | C36: =$C$29+$K$29 -> 91714 | E36: =$G$29+$O$29-K36 -> 92685659 | G36: =E36/C36 -> 1010.5944
B37: D | C37: =$C$30+$K$30 -> 93374 | E37: =$G$30+$O$30 -> 1.3738079e+08 | G37: =E37/C37 -> 1471.296
B39: 재 고 현 황 | O39: [단위:리터/원]
C40: 전일 | F40: 금일 | N40: 복합단가 | O40: 증감
C41: 재고 | F41: 입고 | H41: 출고 | K41: 마 감 재 고 | M41: 재고율
B42: 휘발유 | P42: .
B43: 등 유 | C43: =SUM($E$9) -> 63114 | F43: =$K$29 -> 32000 | H43: =$D$23 -> 3400 | K43: =$C$43-$H$43+$F$43+$O$43 -> 91714 | M43: =SUM($K$43)/$D$9 -> 0.45857 | N43: =$G$36 -> 1010.5944
B44: 경 유 | C44: =SUM($E$10) -> 97374 | F44: =$K$30 -> 0 | H44: =$L$23 -> 4000 | K44: =$C$44-$H$44+$F$44+$O$44 -> 93374 | M44: =SUM($K$44)/D10 -> 0.186748 | N44: =$G$37 -> 1471.296
G45: 복합단가의 재고수량과 단가는 보관물량 제외니 참고해주세요!

Sheet 1216
B1: ◈ KK저장소 복합단가 운영표 - 단지저장소
B5: 이 월 재 고 | G5: [단위:리터/원]
B7: 유종 | D7: 탱크용량 | E7: 재고수량 | F7: 재고율 | G7: 단가
C8: G | D8: 0 | E8: 0 | F8: 0 | G8: 0
C9: K | D9: 200000 | E9: =SUM('1215'!K43:L43) -> 91714 | F9: =E9/D9 -> 0.45857 | G9: =SUM('1215'!N43) -> 1010.5944
C10: D | D10: 500000 | E10: =SUM('1215'!K44:L44) -> 93374 | F10: =E10/D10 -> 0.186748 | G10: =SUM('1215'!N44) -> 1471.296
B13: 출고내역(K) | G13: [단위:리터/원] | J13: 출고내역(LD) | O13: [단위:리터/원]
B14: 유종 | C14: 일반매출(사내이관 포함) | J14: 유종 | K14: 일반매출(사내이관 포함)
C15: 거래처명 | D15: 수량 | E15: 출고단가 | F15: 재고단가 | G15: 단가차액 | H15: 이익 | K15: 거래처명 | L15: 수량 | M15: 출고단가 | N15: 재고단가 | O15: 단가차액 | P15: 이익
B16: 실내 등유 | D16: 2800 | F16: =IF(D16="","",(SUM($G$9))) -> 1010.5944 | G16: =IF(D16="","",(SUM(E16)-F16)) -> -1010.5944 | H16: =IF(D16="","",(D16*G16)) -> -2829664.4 | J16: 경유 | L16: 3000 | N16: =IF(L16="","",($G$10)) -> 1471.296 | O16: =IF(L16="","",(SUM(M16)-N16)) -> -1471.296 | P16: =IF(L16="","",(L16*O16)) -> -4413888
F17: =IF(D17="","",(SUM($G$9))) | G17: =IF(D17="","",(SUM(E17)-F17)) | H17: =IF(D17="","",(D17*G17)) | L17: 520 | N17: =IF(L17="","",($G$10)) -> 1471.296 | O17: =IF(L17="","",(SUM(M17)-N17)) -> -1471.296 | P17: =IF(L17="","",(L17*O17)) -> -765073.92
F18: =IF(D18="","",(SUM($G$9))) | G18: =IF(D18="","",(SUM(E18)-F18)) | H18: =IF(D18="","",(D18*G18)) | N18: =IF(L18="","",($G$10)) | O18: =IF(L18="","",(SUM(M18)-N18)) | P18: =IF(L18="","",(L18*O18))
F19: =IF(D19="","",(SUM($G$9))) | G19: =IF(D19="","",(SUM(E19)-F19)) | H19: =IF(D19="","",(D19*G19)) | N19: =IF(L19="","",($G$10)) | O19: =IF(L19="","",(SUM(M19)-N19)) | P19: =IF(L19="","",(L19*O19))
F20: =IF(D20="","",(SUM($G$9))) | G20: =IF(D20="","",(SUM(E20)-F20)) | H20: =IF(D20="","",(D20*G20)) | N20: =IF(L20="","",($G$10)) | O20: =IF(L20="","",(SUM(M20)-N20)) | P20: =IF(L20="","",(L20*O20))
F21: =IF(D21="","",(SUM($G$9))) | G21: =IF(D21="","",(SUM(E21)-F21)) | H21: =IF(D21="","",(D21*G21)) | N21: =IF(L21="","",($G$10)) | O21: =IF(L21="","",(SUM(M21)-N21)) | P21: =IF(L21="","",(L21*O21))
F22: =IF(D22="","",(SUM($G$9))) | G22: =IF(D22="","",(SUM(E22)-F22)) | H22: =IF(D22="","",(D22*G22)) | N22: =IF(L22="","",($G$10)) | O22: =IF(L22="","",(SUM(M22)-N22)) | P22: =IF(L22="","",(L22*O22))
B23: 소 계 | D23: =SUM(D16:D22) -> 2800 | H23: =SUM(H16:H22) -> -2829664.4 | J23: 소 계 | L23: =SUM(L16:L22) -> 3520 | P23: =SUM(P16:P22) -> -5178961.9
B26: 마 감 재 고 | G26: [단위:리터/원] | J26: 입 고 내 역 | O26: [단위:리터/원]
B27: 유종 | C27: 수량 | E27: 단가 | G27: 환산금액 | J27: 유종 | K27: 수량 | M27: 사입단가 | O27: 환산금액
B28: G | C28: 0 | E28: 0 | G28: 0 | J28: G | K28: 0 | O28: 0
B29: K | C29: =$E$9-$D$23 -> 88914 | E29: =$G$9 -> 1010.5944 | G29: =C29*E29 -> 89855995 | J29: K | O29: =K29*M29 -> 0
B30: D | C30: =$E$10-$L$23 -> 89854 | E30: =$G$10 -> 1471.296 | G30: =C30*E30 -> 1.3220183e+08 | J30: D | O30: =K30*M30 -> 0
B33: 복 합 단 가
B34: 유종 | C34: 수량 | E34: 금액 | G34: 복 합 단 가
B35: G | C35: 0 | E35: 0 | G35: 0
B36: K | C36: =$C$29+$K$29 -> 88914 | E36: =$G$29+$O$29-K36 -> 89855995 | G36: =E36/C36 -> 1010.5944
B37: D | C37: =$C$30+$K$30 -> 89854 | E37: =$G$30+$O$30 -> 1.3220183e+08 | G37: =E37/C37 -> 1471.296
B39: 재 고 현 황 | O39: [단위:리터/원]
C40: 전일 | F40: 금일 | N40: 복합단가 | O40: 증감
C41: 재고 | F41: 입고 | H41: 출고 | K41: 마 감 재 고 | M41: 재고율
B42: 휘발유 | P42: .
B43: 등 유 | C43: =SUM($E$9) -> 91714 | F43: =$K$29 -> 0 | H43: =$D$23 -> 2800 | K43: =$C$43-$H$43+$F$43+$O$43 -> 88914 | M43: =SUM($K$43)/$D$9 -> 0.44457 | N43: =$G$36 -> 1010.5944
B44: 경 유 | C44: =SUM($E$10) -> 93374 | F44: =$K$30 -> 0 | H44: =$L$23 -> 3520 | K44: =$C$44-$H$44+$F$44+$O$44 -> 89854 | M44: =SUM($K$44)/D10 -> 0.179708 | N44: =$G$37 -> 1471.296
G45: 복합단가의 재고수량과 단가는 보관물량 제외니 참고해주세요!

Sheet 1217
B1: ◈ KK저장소 복합단가 운영표 - 단지저장소
B5: 이 월 재 고 | G5: [단위:리터/원]
B7: 유종 | D7: 탱크용량 | E7: 재고수량 | F7: 재고율 | G7: 단가
C8: G | D8: 0 | E8: 0 | F8: 0 | G8: 0
C9: K | D9: 200000 | E9: =SUM('1216'!K43:L43) -> 88914 | F9: =E9/D9 -> 0.44457 | G9: =SUM('1216'!N43) -> 1010.5944
C10: D | D10: 500000 | E10: =SUM('1216'!K44:L44) -> 89854 | F10: =E10/D10 -> 0.179708 | G10: =SUM('1216'!N44) -> 1471.296
B13: 출고내역(K) | G13: [단위:리터/원] | J13: 출고내역(LD) | O13: [단위:리터/원]
B14: 유종 | C14: 일반매출(사내이관 포함) | J14: 유종 | K14: 일반매출(사내이관 포함)
C15: 거래처명 | D15: 수량 | E15: 출고단가 | F15: 재고단가 | G15: 단가차액 | H15: 이익 | K15: 거래처명 | L15: 수량 | M15: 출고단가 | N15: 재고단가 | O15: 단가차액 | P15: 이익
B16: 실내 등유 | D16: 1800 | F16: =IF(D16="","",(SUM($G$9))) -> 1010.5944 | G16: =IF(D16="","",(SUM(E16)-F16)) -> -1010.5944 | H16: =IF(D16="","",(D16*G16)) -> -1819070 | J16: 경유 | L16: 3000 | N16: =IF(L16="","",($G$10)) -> 1471.296 | O16: =IF(L16="","",(SUM(M16)-N16)) -> -1471.296 | P16: =IF(L16="","",(L16*O16)) -> -4413888
D17: 1500 | F17: =IF(D17="","",(SUM($G$9))) -> 1010.5944 | G17: =IF(D17="","",(SUM(E17)-F17)) -> -1010.5944 | H17: =IF(D17="","",(D17*G17)) -> -1515891.7 | N17: =IF(L17="","",($G$10)) | O17: =IF(L17="","",(SUM(M17)-N17)) | P17: =IF(L17="","",(L17*O17))
F18: =IF(D18="","",(SUM($G$9))) | G18: =IF(D18="","",(SUM(E18)-F18)) | H18: =IF(D18="","",(D18*G18)) | N18: =IF(L18="","",($G$10)) | O18: =IF(L18="","",(SUM(M18)-N18)) | P18: =IF(L18="","",(L18*O18))
F19: =IF(D19="","",(SUM($G$9))) | G19: =IF(D19="","",(SUM(E19)-F19)) | H19: =IF(D19="","",(D19*G19)) | N19: =IF(L19="","",($G$10)) | O19: =IF(L19="","",(SUM(M19)-N19)) | P19: =IF(L19="","",(L19*O19))
F20: =IF(D20="","",(SUM($G$9))) | G20: =IF(D20="","",(SUM(E20)-F20)) | H20: =IF(D20="","",(D20*G20)) | N20: =IF(L20="","",($G$10)) | O20: =IF(L20="","",(SUM(M20)-N20)) | P20: =IF(L20="","",(L20*O20))
F21: =IF(D21="","",(SUM($G$9))) | G21: =IF(D21="","",(SUM(E21)-F21)) | H21: =IF(D21="","",(D21*G21)) | N21: =IF(L21="","",($G$10)) | O21: =IF(L21="","",(SUM(M21)-N21)) | P21: =IF(L21="","",(L21*O21))
F22: =IF(D22="","",(SUM($G$9))) | G22: =IF(D22="","",(SUM(E22)-F22)) | H22: =IF(D22="","",(D22*G22)) | N22: =IF(L22="","",($G$10)) | O22: =IF(L22="","",(SUM(M22)-N22)) | P22: =IF(L22="","",(L22*O22))
B23: 소 계 | D23: =SUM(D16:D22) -> 3300 | H23: =SUM(H16:H22) -> -3334961.7 | J23: 소 계 | L23: =SUM(L16:L22) -> 3000 | P23: =SUM(P16:P22) -> -4413888
B26: 마 감 재 고 | G26: [단위:리터/원] | J26: 입 고 내 역 | O26: [단위:리터/원]
B27: 유종 | C27: 수량 | E27: 단가 | G27: 환산금액 | J27: 유종 | K27: 수량 | M27: 사입단가 | O27: 환산금액
B28: G | C28: 0 | E28: 0 | G28: 0 | J28: G | K28: 0 | O28: 0
B29: K | C29: =$E$9-$D$23 -> 85614 | E29: =$G$9 -> 1010.5944 | G29: =C29*E29 -> 86521033 | J29: K | O29: =K29*M29 -> 0
B30: D | C30: =$E$10-$L$23 -> 86854 | E30: =$G$10 -> 1471.296 | G30: =C30*E30 -> 1.2778794e+08 | J30: D | O30: =K30*M30 -> 0
B33: 복 합 단 가
B34: 유종 | C34: 수량 | E34: 금액 | G34: 복 합 단 가
B35: G | C35: 0 | E35: 0 | G35: 0
B36: K | C36: =$C$29+$K$29 -> 85614 | E36: =$G$29+$O$29-K36 -> 86521033 | G36: =E36/C36 -> 1010.5944
B37: D | C37: =$C$30+$K$30 -> 86854 | E37: =$G$30+$O$30 -> 1.2778794e+08 | G37: =E37/C37 -> 1471.296
B39: 재 고 현 황 | O39: [단위:리터/원]
C40: 전일 | F40: 금일 | N40: 복합단가 | O40: 증감
C41: 재고 | F41: 입고 | H41: 출고 | K41: 마 감 재 고 | M41: 재고율
B42: 휘발유 | P42: .
B43: 등 유 | C43: =SUM($E$9) -> 88914 | F43: =$K$29 -> 0 | H43: =$D$23 -> 3300 | K43: =$C$43-$H$43+$F$43+$O$43 -> 85614 | M43: =SUM($K$43)/$D$9 -> 0.42807 | N43: =$G$36 -> 1010.5944
B44: 경 유 | C44: =SUM($E$10) -> 89854 | F44: =$K$30 -> 0 | H44: =$L$23 -> 3000 | K44: =$C$44-$H$44+$F$44+$O$44 -> 86854 | M44: =SUM($K$44)/D10 -> 0.173708 | N44: =$G$37 -> 1471.296
G45: 복합단가의 재고수량과 단가는 보관물량 제외니 참고해주세요!

Sheet 1218
B1: ◈ KK저장소 복합단가 운영표 - 단지저장소
B5: 이 월 재 고 | G5: [단위:리터/원]
B7: 유종 | D7: 탱크용량 | E7: 재고수량 | F7: 재고율 | G7: 단가
C8: G | D8: 0 | E8: 0 | F8: 0 | G8: 0
C9: K | D9: 200000 | E9: =SUM('1217'!K43:L43) -> 85614 | F9: =E9/D9 -> 0.42807 | G9: =SUM('1217'!N43) -> 1010.5944
C10: D | D10: 500000 | E10: =SUM('1217'!K44:L44) -> 86854 | F10: =E10/D10 -> 0.173708 | G10: =SUM('1217'!N44) -> 1471.296
B13: 출고내역(K) | G13: [단위:리터/원] | J13: 출고내역(LD) | O13: [단위:리터/원]
B14: 유종 | C14: 일반매출(사내이관 포함) | J14: 유종 | K14: 일반매출(사내이관 포함)
C15: 거래처명 | D15: 수량 | E15: 출고단가 | F15: 재고단가 | G15: 단가차액 | H15: 이익 | K15: 거래처명 | L15: 수량 | M15: 출고단가 | N15: 재고단가 | O15: 단가차액 | P15: 이익
B16: 실내 등유 | C16: 영포석유 | D16: 4500 | F16: =IF(D16="","",(SUM($G$9))) -> 1010.5944 | G16: =IF(D16="","",(SUM(E16)-F16)) -> -1010.5944 | H16: =IF(D16="","",(D16*G16)) -> -4547675 | J16: 경유 | K16: 문덕 | L16: 3000 | N16: =IF(L16="","",($G$10)) -> 1471.296 | O16: =IF(L16="","",(SUM(M16)-N16)) -> -1471.296 | P16: =IF(L16="","",(L16*O16)) -> -4413888
C17: 강변 | D17: 1300 | F17: =IF(D17="","",(SUM($G$9))) -> 1010.5944 | G17: =IF(D17="","",(SUM(E17)-F17)) -> -1010.5944 | H17: =IF(D17="","",(D17*G17)) -> -1313772.8 | K17: 세계 | L17: 3000 | N17: =IF(L17="","",($G$10)) -> 1471.296 | O17: =IF(L17="","",(SUM(M17)-N17)) -> -1471.296 | P17: =IF(L17="","",(L17*O17)) -> -4413888
C18: 장일석유 | D18: 1900 | F18: =IF(D18="","",(SUM($G$9))) -> 1010.5944 | G18: =IF(D18="","",(SUM(E18)-F18)) -> -1010.5944 | H18: =IF(D18="","",(D18*G18)) -> -1920129.4 | N18: =IF(L18="","",($G$10)) | O18: =IF(L18="","",(SUM(M18)-N18)) | P18: =IF(L18="","",(L18*O18))
C19: 동해안 | D19: 1000 | F19: =IF(D19="","",(SUM($G$9))) -> 1010.5944 | G19: =IF(D19="","",(SUM(E19)-F19)) -> -1010.5944 | H19: =IF(D19="","",(D19*G19)) -> -1010594.4 | N19: =IF(L19="","",($G$10)) | O19: =IF(L19="","",(SUM(M19)-N19)) | P19: =IF(L19="","",(L19*O19))
F20: =IF(D20="","",(SUM($G$9))) | G20: =IF(D20="","",(SUM(E20)-F20)) | H20: =IF(D20="","",(D20*G20)) | N20: =IF(L20="","",($G$10)) | O20: =IF(L20="","",(SUM(M20)-N20)) | P20: =IF(L20="","",(L20*O20))
F21: =IF(D21="","",(SUM($G$9))) | G21: =IF(D21="","",(SUM(E21)-F21)) | H21: =IF(D21="","",(D21*G21)) | N21: =IF(L21="","",($G$10)) | O21: =IF(L21="","",(SUM(M21)-N21)) | P21: =IF(L21="","",(L21*O21))
F22: =IF(D22="","",(SUM($G$9))) | G22: =IF(D22="","",(SUM(E22)-F22)) | H22: =IF(D22="","",(D22*G22)) | N22: =IF(L22="","",($G$10)) | O22: =IF(L22="","",(SUM(M22)-N22)) | P22: =IF(L22="","",(L22*O22))
B23: 소 계 | D23: =SUM(D16:D22) -> 8700 | H23: =SUM(H16:H22) -> -8792171.7 | J23: 소 계 | L23: =SUM(L16:L22) -> 6000 | P23: =SUM(P16:P22) -> -8827776.1
B26: 마 감 재 고 | G26: [단위:리터/원] | J26: 입 고 내 역 | O26: [단위:리터/원]
B27: 유종 | C27: 수량 | E27: 단가 | G27: 환산금액 | J27: 유종 | K27: 수량 | M27: 사입단가 | O27: 환산금액
B28: G | C28: 0 | E28: 0 | G28: 0 | J28: G | K28: 0 | O28: 0
B29: K | C29: =$E$9-$D$23 -> 76914 | E29: =$G$9 -> 1010.5944 | G29: =C29*E29 -> 77728861 | J29: K | O29: =K29*M29 -> 0
B30: D | C30: =$E$10-$L$23 -> 80854 | E30: =$G$10 -> 1471.296 | G30: =C30*E30 -> 1.1896017e+08 | J30: D | O30: =K30*M30 -> 0
B33: 복 합 단 가
B34: 유종 | C34: 수량 | E34: 금액 | G34: 복 합 단 가
B35: G | C35: 0 | E35: 0 | G35: 0
B36: K | C36: =$C$29+$K$29 -> 76914 | E36: =$G$29+$O$29-K36 -> 77728861 | G36: =E36/C36 -> 1010.5944
B37: D | C37: =$C$30+$K$30 -> 80854 | E37: =$G$30+$O$30 -> 1.1896017e+08 | G37: =E37/C37 -> 1471.296
B39: 재 고 현 황 | O39: [단위:리터/원]
C40: 전일 | F40: 금일 | N40: 복합단가 | O40: 증감
C41: 재고 | F41: 입고 | H41: 출고 | K41: 마 감 재 고 | M41: 재고율
B42: 휘발유 | P42: .
B43: 등 유 | C43: =SUM($E$9) -> 85614 | F43: =$K$29 -> 0 | H43: =$D$23 -> 8700 | K43: =$C$43-$H$43+$F$43+$O$43 -> 76914 | M43: =SUM($K$43)/$D$9 -> 0.38457 | N43: =$G$36 -> 1010.5944
B44: 경 유 | C44: =SUM($E$10) -> 86854 | F44: =$K$30 -> 0 | H44: =$L$23 -> 6000 | K44: =$C$44-$H$44+$F$44+$O$44 -> 80854 | M44: =SUM($K$44)/D10 -> 0.161708 | N44: =$G$37 -> 1471.296
G45: 복합단가의 재고수량과 단가는 보관물량 제외니 참고해주세요!

Sheet 1219
B1: ◈ KK저장소 복합단가 운영표 - 단지저장소
B5: 이 월 재 고 | G5: [단위:리터/원]
B7: 유종 | D7: 탱크용량 | E7: 재고수량 | F7: 재고율 | G7: 단가
C8: G | D8: 0 | E8: 0 | F8: 0 | G8: 0
C9: K | D9: 200000 | E9: =SUM('1218'!K43:L43) -> 76914 | F9: =E9/D9 -> 0.38457 | G9: =SUM('1218'!N43) -> 1010.5944
C10: D | D10: 500000 | E10: =SUM('1218'!K44:L44) -> 80854 | F10: =E10/D10 -> 0.161708 | G10: =SUM('1218'!N44) -> 1471.296
B13: 출고내역(K) | G13: [단위:리터/원] | J13: 출고내역(LD) | O13: [단위:리터/원]
B14: 유종 | C14: 일반매출(사내이관 포함) | J14: 유종 | K14: 일반매출(사내이관 포함)
C15: 거래처명 | D15: 수량 | E15: 출고단가 | F15: 재고단가 | G15: 단가차액 | H15: 이익 | K15: 거래처명 | L15: 수량 | M15: 출고단가 | N15: 재고단가 | O15: 단가차액 | P15: 이익
B16: 실내 등유 | C16: 영포석유 | D16: 1470 | F16: =IF(D16="","",(SUM($G$9))) -> 1010.5944 | G16: =IF(D16="","",(SUM(E16)-F16)) -> -1010.5944 | H16: =IF(D16="","",(D16*G16)) -> -1485573.8 | J16: 경유 | K16: 문덕 | L16: 6000 | N16: =IF(L16="","",($G$10)) -> 1471.296 | O16: =IF(L16="","",(SUM(M16)-N16)) -> -1471.296 | P16: =IF(L16="","",(L16*O16)) -> -8827776.1
F17: =IF(D17="","",(SUM($G$9))) | G17: =IF(D17="","",(SUM(E17)-F17)) | H17: =IF(D17="","",(D17*G17)) | K17: 세계 | L17: 3000 | N17: =IF(L17="","",($G$10)) -> 1471.296 | O17: =IF(L17="","",(SUM(M17)-N17)) -> -1471.296 | P17: =IF(L17="","",(L17*O17)) -> -4413888
F18: =IF(D18="","",(SUM($G$9))) | G18: =IF(D18="","",(SUM(E18)-F18)) | H18: =IF(D18="","",(D18*G18)) | N18: =IF(L18="","",($G$10)) | O18: =IF(L18="","",(SUM(M18)-N18)) | P18: =IF(L18="","",(L18*O18))
F19: =IF(D19="","",(SUM($G$9))) | G19: =IF(D19="","",(SUM(E19)-F19)) | H19: =IF(D19="","",(D19*G19)) | N19: =IF(L19="","",($G$10)) | O19: =IF(L19="","",(SUM(M19)-N19)) | P19: =IF(L19="","",(L19*O19))
F20: =IF(D20="","",(SUM($G$9))) | G20: =IF(D20="","",(SUM(E20)-F20)) | H20: =IF(D20="","",(D20*G20)) | N20: =IF(L20="","",($G$10)) | O20: =IF(L20="","",(SUM(M20)-N20)) | P20: =IF(L20="","",(L20*O20))
F21: =IF(D21="","",(SUM($G$9))) | G21: =IF(D21="","",(SUM(E21)-F21)) | H21: =IF(D21="","",(D21*G21)) | N21: =IF(L21="","",($G$10)) | O21: =IF(L21="","",(SUM(M21)-N21)) | P21: =IF(L21="","",(L21*O21))
F22: =IF(D22="","",(SUM($G$9))) | G22: =IF(D22="","",(SUM(E22)-F22)) | H22: =IF(D22="","",(D22*G22)) | N22: =IF(L22="","",($G$10)) | O22: =IF(L22="","",(SUM(M22)-N22)) | P22: =IF(L22="","",(L22*O22))
B23: 소 계 | D23: =SUM(D16:D22) -> 1470 | H23: =SUM(H16:H22) -> -1485573.8 | J23: 소 계 | L23: =SUM(L16:L22) -> 9000 | P23: =SUM(P16:P22) -> -13241664
B26: 마 감 재 고 | G26: [단위:리터/원] | J26: 입 고 내 역 | O26: [단위:리터/원]
B27: 유종 | C27: 수량 | E27: 단가 | G27: 환산금액 | J27: 유종 | K27: 수량 | M27: 사입단가 | O27: 환산금액
B28: G | C28: 0 | E28: 0 | G28: 0 | J28: G | K28: 0 | O28: 0
B29: K | C29: =$E$9-$D$23 -> 75444 | E29: =$G$9 -> 1010.5944 | G29: =C29*E29 -> 76243287 | J29: K | O29: =K29*M29 -> 0
B30: D | C30: =$E$10-$L$23 -> 71854 | E30: =$G$10 -> 1471.296 | G30: =C30*E30 -> 1.057185e+08 | J30: D | O30: =K30*M30 -> 0
B33: 복 합 단 가
B34: 유종 | C34: 수량 | E34: 금액 | G34: 복 합 단 가
B35: G | C35: 0 | E35: 0 | G35: 0
B36: K | C36: =$C$29+$K$29 -> 75444 | E36: =$G$29+$O$29-K36 -> 76243287 | G36: =E36/C36 -> 1010.5944
B37: D | C37: =$C$30+$K$30 -> 71854 | E37: =$G$30+$O$30 -> 1.057185e+08 | G37: =E37/C37 -> 1471.296
B39: 재 고 현 황 | O39: [단위:리터/원]
C40: 전일 | F40: 금일 | N40: 복합단가 | O40: 증감
C41: 재고 | F41: 입고 | H41: 출고 | K41: 마 감 재 고 | M41: 재고율
B42: 휘발유 | P42: .
B43: 등 유 | C43: =SUM($E$9) -> 76914 | F43: =$K$29 -> 0 | H43: =$D$23 -> 1470 | K43: =$C$43-$H$43+$F$43+$O$43 -> 75444 | M43: =SUM($K$43)/$D$9 -> 0.37722 | N43: =$G$36 -> 1010.5944
B44: 경 유 | C44: =SUM($E$10) -> 80854 | F44: =$K$30 -> 0 | H44: =$L$23 -> 9000 | K44: =$C$44-$H$44+$F$44+$O$44 -> 71854 | M44: =SUM($K$44)/D10 -> 0.143708 | N44: =$G$37 -> 1471.296
G45: 복합단가의 재고수량과 단가는 보관물량 제외니 참고해주세요!

Sheet 1220
B1: ◈ KK저장소 복합단가 운영표 - 단지저장소
B5: 이 월 재 고 | G5: [단위:리터/원]
B7: 유종 | D7: 탱크용량 | E7: 재고수량 | F7: 재고율 | G7: 단가
C8: G | D8: 0 | E8: 0 | F8: 0 | G8: 0
C9: K | D9: 200000 | E9: =SUM('1219'!K43:L43) -> 75444 | F9: =E9/D9 -> 0.37722 | G9: =SUM('1219'!N43) -> 1010.5944
C10: D | D10: 500000 | E10: =SUM('1219'!K44:L44) -> 71854 | F10: =E10/D10 -> 0.143708 | G10: =SUM('1219'!N44) -> 1471.296
B13: 출고내역(K) | G13: [단위:리터/원] | J13: 출고내역(LD) | O13: [단위:리터/원]
B14: 유종 | C14: 일반매출(사내이관 포함) | J14: 유종 | K14: 일반매출(사내이관 포함)
C15: 거래처명 | D15: 수량 | E15: 출고단가 | F15: 재고단가 | G15: 단가차액 | H15: 이익 | K15: 거래처명 | L15: 수량 | M15: 출고단가 | N15: 재고단가 | O15: 단가차액 | P15: 이익
B16: 실내 등유 | C16: 영포석유 | D16: 2000 | F16: =IF(D16="","",(SUM($G$9))) -> 1010.5944 | G16: =IF(D16="","",(SUM(E16)-F16)) -> -1010.5944 | H16: =IF(D16="","",(D16*G16)) -> -2021188.9 | J16: 경유 | K16: 영포석유 | L16: 500 | N16: =IF(L16="","",($G$10)) -> 1471.296 | O16: =IF(L16="","",(SUM(M16)-N16)) -> -1471.296 | P16: =IF(L16="","",(L16*O16)) -> -735648
C17: 보문 | D17: 2000 | F17: =IF(D17="","",(SUM($G$9))) -> 1010.5944 | G17: =IF(D17="","",(SUM(E17)-F17)) -> -1010.5944 | H17: =IF(D17="","",(D17*G17)) -> -2021188.9 | N17: =IF(L17="","",($G$10)) | O17: =IF(L17="","",(SUM(M17)-N17)) | P17: =IF(L17="","",(L17*O17))
F18: =IF(D18="","",(SUM($G$9))) | G18: =IF(D18="","",(SUM(E18)-F18)) | H18: =IF(D18="","",(D18*G18)) | N18: =IF(L18="","",($G$10)) | O18: =IF(L18="","",(SUM(M18)-N18)) | P18: =IF(L18="","",(L18*O18))
F19: =IF(D19="","",(SUM($G$9))) | G19: =IF(D19="","",(SUM(E19)-F19)) | H19: =IF(D19="","",(D19*G19)) | N19: =IF(L19="","",($G$10)) | O19: =IF(L19="","",(SUM(M19)-N19)) | P19: =IF(L19="","",(L19*O19))
F20: =IF(D20="","",(SUM($G$9))) | G20: =IF(D20="","",(SUM(E20)-F20)) | H20: =IF(D20="","",(D20*G20)) | N20: =IF(L20="","",($G$10)) | O20: =IF(L20="","",(SUM(M20)-N20)) | P20: =IF(L20="","",(L20*O20))
F21: =IF(D21="","",(SUM($G$9))) | G21: =IF(D21="","",(SUM(E21)-F21)) | H21: =IF(D21="","",(D21*G21)) | N21: =IF(L21="","",($G$10)) | O21: =IF(L21="","",(SUM(M21)-N21)) | P21: =IF(L21="","",(L21*O21))
